Workbook

Sheet Sheet1
A1: First Author | B1: Date | C1: Gender (Male) | E1: Gender (Female) | G1: Mean Age (Primary) | I1: Mean Age (Secondary) | K1: Mean Age (Total) | M1: Ethnicity (Black) | O1: Ethnicity (White) | Q1: Ethnicity (Asian) | S1: Ethnicity (Other) | U1: Accident and Emergency / Urgent Care | W1: Inpatient Psychiatric Service | Y1: Outpatient Psychiatric Service | AA1: GP /non-Urgent Physical Care | AC1: setting | AD1: Country | AF1: Continant | AG1: Retrospective | AI1: Prospective | AK1: FEP Only | AM1: First Episode Cohort | AO1: Chronic Psychosis Cohort | AQ1: Mixed Cohort | AS1: DUP (all psychosis) | AU1: DUP (primary) | AW1: DUP (secondary) | AY1: Total Sample Size | BA1: Total Secondary Causes | BC1: Was the study looking at multiple causes? | BE1: Endogenous | BG1: Exogenous | BI1: Autoimmune Disorders | BK1: Cytogenic / Congenital | BM1: Toxic / Substance-Induced | BO1: Iatrogenic | BQ1: Cerebrovascular | BS1: Space-Occupying | BU1: Metabolic | BW1: Dietary | BY1: Sepsis / Infectious | CA1: Degenerative | CC1: Demyelinating | CE1: Seizure | CG1: Sleep Disorders | CI1: Head Injury | CK1: Endocrine | CM1: Other | CO1: Unknown | CQ1: MRI (freq) | CS1: CT (freq) | CU1: SPECT/PET (freq) | CW1: EEG (freq) | CY1: CSF (freq) | DA1: Blood (freq) | DC1: Urine (freq) | DE1: Psychiatric Assessment (freq) | DG1: Psychiatric Assessment Standardised Tool (y/n) | DI1: Physical Exam (including neurological, vital signs) (freq) | DK1: Cognitive Assessment (freq) | DM1: Cognitive Assessment-standardised tool | DO1: Other (add detail) | DQ1: NS | DS1: Diagnosis | DU1: Diagnostic Tool | DW1: Classification System | DY1: Item 1 | EA1: Item 2 | EC1: Item 3 | EE1: Item 4 | EG1: Item 5 | EI1: Item 6 | EK1: Item 7 | EM1: Item 8 | EO1: Item 9 | EQ1: Item 10 | ES1: Overall Score | EU1: First Author | EV1: Date | EW1: Gender (Male) | EX1: Gender (Female) | EY1: Mean Age (Primary) | EZ1: Mean Age (Secondary) | FA1: Mean Age (Total) | FB1: Ethnicity (Black) | FC1: Ethnicity (White) | FD1: Ethnicity (Asian) | FE1: Ethnicity (Other) | FF1: Accident and Emergency / Urgent Care | FG1: Inpatient Psychiatric Service | FH1: Outpatient Psychiatric Service | FI1: GP /non-Urgent Physical Care | FJ1: Geographic Location | FK1: Retrospective | FL1: Prospective | FM1: First Episode Cohort | FN1: Chronic Psychosis Cohort | FO1: Mixed Cohort | FP1: Total Sample Size | FQ1: Total Secondary Causes | FR1: Was the study looking at multiple causes? | FS1: Endogenous | FT1: Exogenous | FU1: Autoimmune Disorders | FV1: Cytogenic / Congenital | FW1: Toxic / Substance-Induced | FX1: Iatrogenic | FY1: Cerebrovascular | FZ1: Space-Occupying | GA1: Metabolic | GB1: Dietary | GC1: Sepsis / Infectious | GD1: Degenerative | GE1: Demyelinating | GF1: Seizure | GG1: Sleep Disorder | GH1: Head Injury | GI1: Endocrine | GJ1: Other | GK1: Unknown | GL1: MRI (freq) | GM1: CT (freq) | GN1: SPECT/PET (freq) | GO1: EEG (freq) | GP1: CSF (freq) | GQ1: Blood (freq) | GR1: Urine (freq) | GS1: Psychiatric Assessment (freq) | GT1: Psychiatric Assessment Standardised Tool (y/n) | GU1: Physical Exam (including neurological, vital signs) (freq) | GV1: Cognitive Assessment (freq) | GW1: Cognitive Assessment-standardised tool | GX1: Other (add detail) | GY1: NS | GZ1: Item 1 | HA1: Item 2 | HB1: Item 3 | HC1: Item 4 | HD1: Item 5 | HE1: Item 6 | HF1: Item 7 | HG1: Item 8 | HH1: Item 9 | HI1: Item 10 | HJ1: Overall Score | HK1: Comments - endogenous causesnot reported at most granual level | HL1: includes endogenous NOS as "other"/"unknown"
C2: Rater 1 | D2: Rater 2 | E2: Rater 1 | F2: Rater 2 | G2: Rater 1 | H2: Rater 2 | I2: Rater 1 | J2: Rater 2 | K2: Rater 1 | L2: Rater 2 | M2: Rater 1 | N2: Rater 2 | O2: Rater 1 | P2: Rater 2 | Q2: Rater 1 | R2: Rater 2 | S2: Rater 1 | T2: Rater 2 | U2: Rater 1 | V2: Rater 2 | W2: Rater 1 | X2: Rater 2 | Y2: Rater 1 | Z2: Rater 2 | AA2: Rater 1 | AB2: Rater 2 | AD2: Rater 1 | AE2: Rater 2 | AG2: Rater 1 | AH2: Rater 2 | AI2: Rater 1 | AJ2: Rater 2 | AK2: Rater 1 | AL2: Rater 2 | AM2: Rater 1 | AN2: Rater 2 | AO2: Rater 1 | AP2: Rater 2 | AQ2: Rater 1 | AR2: Rater 2 | AS2: Rater 1 | AT2: Rater 2 | AU2: Rater 1 | AV2: Rater 2 | AW2: Rater 1 | AX2: Rater 2 | AY2: Rater 1 | AZ2: Rater 2 | BA2: Rater 1 | BB2: Rater 2 | BC2: Rater 1 | BD2: Rater 2 | BE2: Rater 1 | BF2: Rater 2 | BG2: Rater 1 | BH2: Rater 2 | BI2: Rater 1 | BJ2: Rater 2 | BK2: Rater 1 | BL2: Rater 2 | BM2: Rater 1 | BN2: Rater 2 | BO2: Rater 1 | BP2: Rater 2 | BQ2: Rater 1 | BR2: Rater 2 | BS2: Rater 1 | BT2: Rater 2 | BU2: Rater 1 | BV2: Rater 2 | BW2: Rater 1 | BX2: Rater 2 | BY2: Rater 1 | BZ2: Rater 2 | CA2: Rater 1 | CB2: Rater 2 | CC2: Rater 1 | CD2: Rater 2 | CE2: Rater 1 | CF2: Rater 2 | CG2: Rater 1 | CH2: Rater 2 | CI2: Rater 1 | CJ2: Rater 2 | CK2: Rater 1 | CL2: Rater 2 | CM2: Rater 1 | CN2: Rater 2 | CO2: Rater 1 | CP2: Rater 2 | CQ2: Rater 1 | CR2: Rater 2 | CS2: Rater 1 | CT2: Rater 2 | CU2: Rater 1 | CV2: Rater 2 | CW2: Rater 1 | CX2: Rater 2 | CY2: Rater 1 | CZ2: Rater 2 | DA2: Rater 1 | DB2: Rater 2 | DC2: Rater 1 | DD2: Rater 2 | DE2: Rater 1 | DF2: Rater 2 | DG2: Rater 1 | DH2: Rater 2 | DI2: Rater 1 | DJ2: Rater 2 | DK2: Rater 1 | DL2: Rater 2 | DM2: Rater 1 | DN2: Rater 2 | DO2: Rater 1 | DP2: Rater 2 | DQ2: Rater 1 | DR2: Rater 2 | DS2: Rater 1 | DT2: Rater 2 | DU2: Rater 1 | DV2: Rater 2 | DW2: Rater 1 | DX2: Rater 2 | DY2: Rater 1 | DZ2: Rater 2 | EA2: Rater 1 | EB2: Rater 2 | EC2: Rater 1 | ED2: Rater 2 | EE2: Rater 1 | EF2: Rater 2 | EG2: Rater 1 | EH2: Rater 2 | EI2: Rater 1 | EJ2: Rater 2 | EK2: Rater 1 | EL2: Rater 2 | EM2: Rater 1 | EN2: Rater 2 | EO2: Rater 1 | EP2: Rater 2 | EQ2: Rater 1 | ER2: Rater 2 | ES2: Rater 1 | ET2: Rater 2
A3: Adams | B3: 1996 | C3: 68 | D3: 68 | E3: 43 | F3: 43 | G3: NS | H3: NS | I3: NS | J3: NS | K3: NS | L3: NS | M3: NS | N3: NS | O3: NS | P3: NS | Q3: NS | R3: NS | S3: NS | T3: NS | U3: 0 | V3: 0 | W3: 111 | X3: 111 | Y3: 0 | Z3: 0 | AA3: 0 | AB3: 0 | AC3: inpat_psych | AD3: Canada | AE3: Canada | AG3: no | AH3: no | AI3: yes | AJ3: yes | AK3: yes | AL3: yes | AM3: 111 | AN3: 111 | AO3: 0 | AP3: 0 | AQ3: 0 | AR3: 0 | AS3: NS | AT3: NS | AU3: NS | AV3: NS | AW3: NS | AX3: NS | AY3: 111 | AZ3: 111 | BA3: 0 | BB3: 0 | BC3: multiple | BD3: multiple | BE3: =SUM(BI3,BK3,BQ3,BS3,BU3,BW3,BY3,CA3,CC3,CE3,CG3,CI3,CK3,CM3,CO3) -> 0 | BF3: =SUM(BJ3,BL3,BR3,BT3,BV3,BX3,BZ3,CB3,CD3,CF3,CH3,CJ3,CL3,CN3,CP3) -> 0 | BG3: =SUM(BM3,BO3) -> 0 | BH3: =SUM(BN3,BP3) -> 0 | BI3: NA | BJ3: NA | BK3: NA | BL3: NA | BM3: NA | BN3: NA | BO3: NA | BP3: NA | BQ3: 0 | BR3: 0 | BS3: 0 | BT3: 0 | BU3: 0 | BV3: 0 | BW3: 0 | BX3: 0 | BY3: NA | BZ3: NA | CA3: 0 | CB3: 0 | CC3: 0 | CD3: 0 | CE3: NA | CF3: NA | CG3: NA | CH3: NA | CI3: 0 | CJ3: 0 | CK3: 0 | CL3: 0 | CM3: 0 | CN3: 0 | CO3: 0 | CP3: 0 | CQ3: NS | CR3: NS | CS3: some | CT3: some | CU3: some | CV3: some | CW3: some | CX3: some | CY3: NS | CZ3: NS | DA3: all | DB3: all | DC3: NS | DD3: NS | DE3: all | DF3: all | DG3: NS | DH3: NS | DI3: NS | DJ3: NS | DK3: NS | DL3: NS | DM3: NS | DN3: NS | DO3: NS | DP3: NS | DQ3: NS | DR3: NS | DS3: disorder | DT3: disorder | DU3: NS | DV3: NS | DW3: NS | DX3: NS | DY3: 1 | DZ3: 1 | EA3: 1 | EB3: 1 | EC3: 1 | ED3: 1 | EE3: 1 | EF3: 1 | EG3: 1 | EH3: 1 | EI3: 1 | EJ3: 1 | EK3: 1 | EL3: 1 | EM3: 1 | EN3: 1 | EO3: 1 | EP3: 1 | EQ3: 1 | ER3: 1 | ES3: 10 | ET3: 10 | EW3: =IF(C3=D3,"Y","N") -> Y | EX3: =IF(E3=F3,"Y","N") -> Y | EY3: =IF(G3=H3,"Y","N") -> Y | EZ3: =IF(I3=J3,"Y","N") -> Y | FA3: =IF(K3=L3,"Y","N") -> Y | FB3: =IF(M3=N3,"Y","N") -> Y | FC3: =IF(O3=P3,"Y","N") -> Y | FD3: =IF(Q3=R3,"Y","N") -> Y | FE3: =IF(S3=T3,"Y","N") -> Y | FF3: =IF(U3=V3,"Y","N") -> Y | FG3: =IF(W3=X3,"Y","N") -> Y | FH3: =IF(Y3=Z3,"Y","N") -> Y | FI3: =IF(AA3=AB3,"Y","N") -> Y | FJ3: =IF(AD3=AE3,"Y","N") -> Y | FK3: =IF(AG3=AH3,"Y","N") -> Y | FL3: =IF(AI3=AJ3,"Y","N") -> Y | FM3: =IF(AM3=AN3,"Y","N") -> Y | FN3: =IF(AO3=AP3,"Y","N") -> Y | FO3: =IF(AQ3=AR3,"Y","N") -> Y | FP3: =IF(AY3=AZ3,"Y","N") -> Y | FQ3: =IF(BA3=BB3,"Y","N") -> Y | FR3: =IF(BC3=BD3,"Y","N") -> Y | FS3: =IF(BE3=BF3,"Y","N") -> Y | FT3: =IF(BG3=BH3,"Y","N") -> Y | FU3: =IF(BI3=BJ3,"Y","N") -> Y | FV3: =IF(BK3=BL3,"Y","N") -> Y | FW3: =IF(BM3=BN3,"Y","N") -> Y | FX3: =IF(BO3=BP3,"Y","N") -> Y | FY3: =IF(BQ3=BR3,"Y","N") -> Y | FZ3: =IF(BS3=BT3,"Y","N") -> Y | GA3: =IF(BU3=BV3,"Y","N") -> Y | GB3: =IF(BW3=BX3,"Y","N") -> Y | GC3: =IF(BY3=BZ3,"Y","N") -> Y | GD3: =IF(CA3=CB3,"Y","N") -> Y | GE3: =IF(CC3=CD3,"Y","N") -> Y | GF3: =IF(CE3=CF3,"Y","N") -> Y | GG3: =IF(CG3=CH3, "Y", "N") -> Y | GH3: =IF(CI3=CJ3, "Y", "N") -> Y | GI3: =IF(CK3=CL3,"Y","N") -> Y | GJ3: =IF(CM3=CN3,"Y","N") -> Y | GK3: =IF(CO3=CP3,"Y","N") -> Y | GL3: =IF(CQ3=CR3,"Y","N") -> Y | GM3: =IF(CS3=CT3,"Y","N") -> Y | GN3: =IF(CU3=CV3,"Y","N") -> Y | GO3: =IF(CW3=CX3,"Y","N") -> Y | GP3: =IF(CY3=CZ3,"Y","N") -> Y | GQ3: =IF(DA3=DB3,"Y","N") -> Y | GR3: =IF(DC3=DD3,"Y","N") -> Y | GS3: =IF(DE3=DF3,"Y","N") -> Y | GT3: =IF(DG3=DH3,"Y","N") -> Y | GU3: =IF(DI3=DJ3,"Y","N") -> Y | GV3: =IF(DK3=DL3,"Y","N") -> Y | GW3: =IF(DM3=DN3,"Y","N") -> Y | GX3: =IF(DO3=DP3,"Y","N") -> Y | GY3: =IF(DQ3=DR3,"Y","N") -> Y | GZ3: =IF(DY3=DZ3,"Y","N") -> Y | HA3: =IF(EA3=EB3,"Y","N") -> Y | HB3: =IF(EC3=ED3,"Y","N") -> Y | HC3: =IF(EE3=EF3,"Y","N") -> Y | HD3: =IF(EG3=EH3,"Y","N") -> Y | HE3: =IF(EI3=EJ3,"Y","N") -> Y | HF3: =IF(EK3=EL3,"Y","N") -> Y | HG3: =IF(EM3=EN3,"Y","N") -> Y | HH3: =IF(EO3=EP3,"Y","N") -> Y | HI3: =IF(EQ3=ER3,"Y","N") -> Y | HJ3: =IF(ES3=ET3,"Y","N") -> Y
A4: Caton | B4: 2005 | C4: 278 | D4: 278 | E4: 108 | F4: 108 | G4: 27.1 | H4: 27.1 | I4: 30.1 | J4: 30.1 | K4: 28.5 | L4: 28.5 | M4: 168 | N4: 168 | O4: 56 | P4: 56 | Q4: 0 | R4: 0 | S4: 0 | T4: 0 | U4: 386 | V4: 386 | W4: 0 | X4: 0 | Y4: 0 | Z4: 0 | AA4: 0 | AB4: 0 | AC4: gen_hospital | AD4: USA | AE4: USA | AF4: n_am | AG4: no | AH4: no | AI4: yes | AJ4: yes | AK4: yes | AL4: yes | AM4: NS | AN4: NS | AO4: NS | AP4: NS | AQ4: NS | AR4: NS | AS4: NS | AT4: NS | AU4: NS | AV4: NS | AW4: NS | AX4: NS | AY4: 386 | AZ4: 386 | BA4: 169 | BB4: 169 | BC4: single | BD4: single | BE4: =SUM(BI4,BK4,BQ4,BS4,BU4,BW4,BY4,CA4,CC4,CE4,CG4,CI4,CK4,CM4,CO4) -> 0 | BF4: =SUM(BJ4,BL4,BR4,BT4,BV4,BX4,BZ4,CB4,CD4,CF4,CH4,CJ4,CL4,CN4,CP4) -> 0 | BG4: =SUM(BM4,BO4) -> 169 | BH4: =SUM(BN4,BP4) -> 169 | BI4: NA | BJ4: NA | BK4: NA | BL4: NA | BM4: 169 | BN4: 169 | BO4: NA | BP4: NA | BQ4: NA | BR4: NA | BS4: NA | BT4: NA | BU4: NA | BV4: NA | BW4: NA | BX4: NA | BY4: NA | BZ4: NA | CA4: NA | CB4: NA | CC4: NA | CD4: NA | CE4: NA | CF4: NA | CG4: NA | CH4: NA | CI4: NA | CJ4: NA | CK4: NA | CL4: NA | CM4: NA | CN4: NA | CO4: NA | CP4: NA | CQ4: NS | CR4: NS | CS4: NS | CT4: NS | CU4: NS | CV4: NS | CW4: NS | CX4: NS | CY4: NS | CZ4: NS | DA4: NS | DB4: NS | DC4: all | DD4: all | DE4: all | DF4: all | DG4: yes | DH4: yes | DI4: NS | DJ4: NS | DK4: NS | DL4: NS | DM4: NS | DN4: NS | DO4: NS | DP4: NS | DQ4: NS | DR4: NS | DS4: disorder | DT4: disorder | DU4: PRISM | DV4: PRISM | DW4: DSM-IV | DX4: DSM-IV | DY4: 1 | DZ4: 1 | EA4: 0 | EB4: 0 | EC4: 1 | ED4: 1 | EE4: 1 | EF4: 1 | EG4: 1 | EH4: 1 | EI4: 1 | EJ4: 1 | EK4: 1 | EL4: 1 | EM4: 1 | EN4: 1 | EO4: 1 | EP4: 1 | EQ4: 1 | ER4: 1 | ES4: =SUM(DY4,EA4,EC4,EE4,EG4,EI4,EK4,EM4,EO4,EQ4) -> 9 | ET4: =SUM(DZ4,EB4,ED4,EF4,EH4,EJ4,EL4,EN4,EP4,ER4) -> 9 | EU4: Caton | EV4: 2005 | EW4: =IF(C4=D4,"Y","N") -> Y | EX4: =IF(E4=F4,"Y","N") -> Y | EY4: =IF(G4=H4,"Y","N") -> Y | EZ4: =IF(I4=J4,"Y","N") -> Y | FA4: =IF(K4=L4,"Y","N") -> Y | FB4: =IF(M4=N4,"Y","N") -> Y | FC4: =IF(O4=P4,"Y","N") -> Y | FD4: =IF(Q4=R4,"Y","N") -> Y | FE4: =IF(S4=T4,"Y","N") -> Y | FF4: =IF(U4=V4,"Y","N") -> Y | FG4: =IF(W4=X4,"Y","N") -> Y | FH4: =IF(Y4=Z4,"Y","N") -> Y | FI4: =IF(AA4=AB4,"Y","N") -> Y | FJ4: =IF(AD4=AE4,"Y","N") -> Y | FK4: =IF(AG4=AH4,"Y","N") -> Y | FL4: =IF(AI4=AJ4,"Y","N") -> Y | FM4: =IF(AM4=AN4,"Y","N") -> Y | FN4: =IF(AO4=AP4,"Y","N") -> Y | FO4: =IF(AQ4=AR4,"Y","N") -> Y | FP4: =IF(AY4=AZ4,"Y","N") -> Y | FQ4: =IF(BA4=BB4,"Y","N") -> Y | FR4: =IF(BC4=BD4,"Y","N") -> Y | FS4: =IF(BE4=BF4,"Y","N") -> Y | FT4: =IF(BG4=BH4,"Y","N") -> Y | FU4: =IF(BI4=BJ4,"Y","N") -> Y | FV4: =IF(BK4=BL4,"Y","N") -> Y | FW4: =IF(BM4=BN4,"Y","N") -> Y | FX4: =IF(BO4=BP4,"Y","N") -> Y | FY4: =IF(BQ4=BR4,"Y","N") -> Y | FZ4: =IF(BS4=BT4,"Y","N") -> Y | GA4: =IF(BU4=BV4,"Y","N") -> Y | GB4: =IF(BW4=BX4,"Y","N") -> Y | GC4: =IF(BY4=BZ4,"Y","N") -> Y | GD4: =IF(CA4=CB4,"Y","N") -> Y | GE4: =IF(CC4=CD4,"Y","N") -> Y | GF4: =IF(CE4=CF4,"Y","N") -> Y | GG4: =IF(CG4=CH4, "Y", "N") -> Y | GH4: =IF(CI4=CJ4, "Y", "N") -> Y | GI4: =IF(CK4=CL4,"Y","N") -> Y | GJ4: =IF(CM4=CN4,"Y","N") -> Y | GK4: =IF(CO4=CP4,"Y","N") -> Y | GL4: =IF(CQ4=CR4,"Y","N") -> Y | GM4: =IF(CS4=CT4,"Y","N") -> Y | GN4: =IF(CU4=CV4,"Y","N") -> Y | GO4: =IF(CW4=CX4,"Y","N") -> Y | GP4: =IF(CY4=CZ4,"Y","N") -> Y | GQ4: =IF(DA4=DB4,"Y","N") -> Y | GR4: =IF(DC4=DD4,"Y","N") -> Y | GS4: =IF(DE4=DF4,"Y","N") -> Y | GT4: =IF(DG4=DH4,"Y","N") -> Y | GU4: =IF(DI4=DJ4,"Y","N") -> Y | GV4: =IF(DK4=DL4,"Y","N") -> Y | GW4: =IF(DM4=DN4,"Y","N") -> Y | GX4: =IF(DO4=DP4,"Y","N") -> Y | GY4: =IF(DQ4=DR4,"Y","N") -> Y | GZ4: =IF(DY4=DZ4,"Y","N") -> Y | HA4: =IF(EA4=EB4,"Y","N") -> Y | HB4: =IF(EC4=ED4,"Y","N") -> Y | HC4: =IF(EE4=EF4,"Y","N") -> Y | HD4: =IF(EG4=EH4,"Y","N") -> Y | HE4: =IF(EI4=EJ4,"Y","N") -> Y | HF4: =IF(EK4=EL4,"Y","N") -> Y | HG4: =IF(EM4=EN4,"Y","N") -> Y | HH4: =IF(EO4=EP4,"Y","N") -> Y | HI4: =IF(EQ4=ER4,"Y","N") -> Y | HJ4: =IF(ES4=ET4,"Y","N") -> Y
A5: Correa-Oliveira | B5: 2022 | C5: 152 | D5: 152 | E5: 85 | F5: 85 | G5: NS | H5: NS | I5: NS | J5: NS | K5: 23.5 | L5: 23.5 | M5: NS | N5: NS | O5: 153 | P5: 153 | Q5: NS | R5: NS | S5: 64 | T5: 64 | U5: 0 | V5: 0 | W5: 0 | X5: 0 | Y5: 237 | Z5: 237 | AA5: 0 | AB5: 0 | AC5: outpat_psych | AD5: Brazil | AE5: Brazil | AF5: s_am | AG5: yes | AH5: yes | AI5: no | AJ5: no | AK5: yes | AL5: yes | AM5: 237 | AN5: 237 | AO5: 0 | AP5: 0 | AQ5: 0 | AR5: 0 | AS5: NS | AT5: NS | AU5: NS | AV5: NS | AW5: NS | AX5: NS | AY5: 237 | AZ5: 237 | BA5: 84 | BB5: 84 | BC5: multiple | BD5: multiple | BE5: =SUM(BI5,BK5,BQ5,BS5,BU5,BW5,BY5,CA5,CC5,CE5,CG5,CI5,CK5,CM5,CO5) -> 23 | BF5: =SUM(BJ5,BL5,BR5,BT5,BV5,BX5,BZ5,CB5,CD5,CF5,CH5,CJ5,CL5,CN5,CP5) -> 23 | BG5: =SUM(BM5,BO5) -> 61 | BH5: =SUM(BN5,BP5) -> 61 | BI5: NA | BJ5: NA | BK5: NA | BL5: NA | BM5: 61 | BN5: 61 | BO5: NA | BP5: NA | BQ5: NA | BR5: NA | BS5: NA | BT5: NA | BU5: NA | BV5: NA | BW5: NA | BX5: NA | BY5: NA | BZ5: NA | CA5: NA | CB5: NA | CC5: NA | CD5: NA | CE5: NA | CF5: NA | CG5: NA | CH5: NA | CI5: NA | CJ5: NA | CK5: NA | CL5: NA | CM5: NA | CN5: NA | CO5: 23 | CP5: 23 | CQ5: NS | CR5: NS | CS5: all | CT5: all | CU5: all | CV5: all | CW5: NS | CX5: NS | CY5: NS | CZ5: NS | DA5: all | DB5: all | DC5: all | DD5: all | DE5: all | DF5: all | DG5: yes | DH5: yes | DI5: all | DJ5: all | DK5: NS | DL5: NS | DM5: NS | DN5: NS | DO5: NS | DP5: NS | DQ5: NS | DR5: NS | DS5: disorder | DT5: disorder | DU5: SCID | DV5: SCID | DW5: DSM-5 | DX5: DSM-IV | DY5: 1 | DZ5: 1 | EA5: 1 | EB5: 1 | EC5: 1 | ED5: 1 | EE5: 1 | EF5: 1 | EG5: 1 | EH5: 1 | EI5: 1 | EJ5: 1 | EK5: 1 | EL5: 1 | EM5: 1 | EN5: 1 | EO5: 1 | EP5: 1 | EQ5: 1 | ER5: 1 | ES5: =SUM(DY5,EA5,EC5,EE5,EG5,EI5,EK5,EM5,EO5,EQ5) -> 10 | ET5: =SUM(DZ5,EB5,ED5,EF5,EH5,EJ5,EL5,EN5,EP5,ER5) -> 10 | EU5: Correa-Oliveira | EV5: 2022 | EW5: =IF(C5=D5,"Y","N") -> Y | EX5: =IF(E5=F5,"Y","N") -> Y | EY5: =IF(G5=H5,"Y","N") -> Y | EZ5: =IF(I5=J5,"Y","N") -> Y | FA5: =IF(K5=L5,"Y","N") -> Y | FB5: =IF(M5=N5,"Y","N") -> Y | FC5: =IF(O5=P5,"Y","N") -> Y | FD5: =IF(Q5=R5,"Y","N") -> Y | FE5: =IF(S5=T5,"Y","N") -> Y | FF5: =IF(U5=V5,"Y","N") -> Y | FG5: =IF(W5=X5,"Y","N") -> Y | FH5: =IF(Y5=Z5,"Y","N") -> Y | FI5: =IF(AA5=AB5,"Y","N") -> Y | FJ5: =IF(AD5=AE5,"Y","N") -> Y | FK5: =IF(AG5=AH5,"Y","N") -> Y | FL5: =IF(AI5=AJ5,"Y","N") -> Y | FM5: =IF(AM5=AN5,"Y","N") -> Y | FN5: =IF(AO5=AP5,"Y","N") -> Y | FO5: =IF(AQ5=AR5,"Y","N") -> Y | FP5: =IF(AY5=AZ5,"Y","N") -> Y | FQ5: =IF(BA5=BB5,"Y","N") -> Y | FR5: =IF(BC5=BD5,"Y","N") -> Y | FS5: =IF(BE5=BF5,"Y","N") -> Y | FT5: =IF(BG5=BH5,"Y","N") -> Y | FU5: =IF(BI5=BJ5,"Y","N") -> Y | FV5: =IF(BK5=BL5,"Y","N") -> Y | FW5: =IF(BM5=BN5,"Y","N") -> Y | FX5: =IF(BO5=BP5,"Y","N") -> Y | FY5: =IF(BQ5=BR5,"Y","N") -> Y | FZ5: =IF(BS5=BT5,"Y","N") -> Y | GA5: =IF(BU5=BV5,"Y","N") -> Y | GB5: =IF(BW5=BX5,"Y","N") -> Y | GC5: =IF(BY5=BZ5,"Y","N") -> Y | GD5: =IF(CA5=CB5,"Y","N") -> Y | GE5: =IF(CC5=CD5,"Y","N") -> Y | GF5: =IF(CE5=CF5,"Y","N") -> Y | GG5: =IF(CG5=CH5, "Y", "N") -> Y | GH5: =IF(CI5=CJ5, "Y", "N") -> Y | GI5: =IF(CK5=CL5,"Y","N") -> Y | GJ5: =IF(CM5=CN5,"Y","N") -> Y | GK5: =IF(CO5=CP5,"Y","N") -> Y | GL5: =IF(CQ5=CR5,"Y","N") -> Y | GM5: =IF(CS5=CT5,"Y","N") -> Y | GN5: =IF(CU5=CV5,"Y","N") -> Y | GO5: =IF(CW5=CX5,"Y","N") -> Y | GP5: =IF(CY5=CZ5,"Y","N") -> Y | GQ5: =IF(DA5=DB5,"Y","N") -> Y | GR5: =IF(DC5=DD5,"Y","N") -> Y | GS5: =IF(DE5=DF5,"Y","N") -> Y | GT5: =IF(DG5=DH5,"Y","N") -> Y | GU5: =IF(DI5=DJ5,"Y","N") -> Y | GV5: =IF(DK5=DL5,"Y","N") -> Y | GW5: =IF(DM5=DN5,"Y","N") -> Y | GX5: =IF(DO5=DP5,"Y","N") -> Y | GY5: =IF(DQ5=DR5,"Y","N") -> Y | GZ5: =IF(DY5=DZ5,"Y","N") -> Y | HA5: =IF(EA5=EB5,"Y","N") -> Y | HB5: =IF(EC5=ED5,"Y","N") -> Y | HC5: =IF(EE5=EF5,"Y","N") -> Y | HD5: =IF(EG5=EH5,"Y","N") -> Y | HE5: =IF(EI5=EJ5,"Y","N") -> Y | HF5: =IF(EK5=EL5,"Y","N") -> Y | HG5: =IF(EM5=EN5,"Y","N") -> Y | HH5: =IF(EO5=EP5,"Y","N") -> Y | HI5: =IF(EQ5=ER5,"Y","N") -> Y | HJ5: =IF(ES5=ET5,"Y","N") -> Y | HK5: 1 | HL5: 1
A6: Drake | B6: 2011 | C6: 152 | D6: 152 | E6: 99 | F6: 99 | G6: 27.2 | H6: 27.2 | I6: 30.4 | J6: 30.4 | K6: NS | L6: NS | M6: 156 | N6: 156 | O6: 52 | P6: 52 | Q6: 0 | R6: 0 | S6: 147 | T6: 147 | U6: 351 | V6: 351 | W6: 0 | X6: 0 | Y6: 0 | Z6: 0 | AA6: 0 | AB6: 0 | AC6: gen_hospital | AD6: USA | AE6: USA | AF6: n_am | AG6: no | AH6: no | AI6: yes | AJ6: yes | AK6: yes | AL6: yes | AM6: 351 | AN6: 351 | AO6: 0 | AP6: 0 | AQ6: 0 | AR6: 0 | AS6: NS | AT6: NS | AU6: NS | AV6: NS | AW6: NS | AX6: NS | AY6: 351 | AZ6: 351 | BA6: 134 | BB6: 134 | BC6: single | BD6: single | BE6: =SUM(BI6,BK6,BQ6,BS6,BU6,BW6,BY6,CA6,CC6,CE6,CG6,CI6,CK6,CM6,CO6) -> 0 | BF6: =SUM(BJ6,BL6,BR6,BT6,BV6,BX6,BZ6,CB6,CD6,CF6,CH6,CJ6,CL6,CN6,CP6) -> 0 | BG6: =SUM(BM6,BO6) -> 134 | BH6: =SUM(BN6,BP6) -> 134 | BI6: NA | BJ6: NA | BK6: NA | BL6: NA | BM6: 134 | BN6: 134 | BO6: NA | BP6: NA | BQ6: NA | BR6: NA | BS6: NA | BT6: NA | BU6: NA | BV6: NA | BW6: NA | BX6: NA | BY6: NA | BZ6: NA | CA6: NA | CB6: NA | CC6: NA | CD6: NA | CE6: NA | CF6: NA | CG6: NA | CH6: NA | CI6: NA | CJ6: NA | CK6: NA | CL6: NA | CM6: NA | CN6: NA | CO6: NA | CP6: NA | CQ6: NS | CR6: NS | CS6: NS | CT6: NS | CU6: NS | CV6: NS | CW6: NS | CX6: NS | CY6: NS | CZ6: NS | DA6: NS | DB6: NS | DC6: all | DD6: all | DE6: all | DF6: all | DG6: yes | DH6: yes | DI6: NS | DJ6: NS | DK6: NS | DL6: NS | DM6: NS | DN6: NS | DO6: NS | DP6: NS | DQ6: NS | DR6: NS | DS6: disorder | DT6: disorder | DU6: PRISM | DV6: PRISM | DW6: DSM-IV | DX6: DSM-IV | DY6: 1 | DZ6: 1 | EA6: 0 | EB6: 0 | EC6: 1 | ED6: 1 | EE6: 1 | EF6: 1 | EG6: 1 | EH6: 1 | EI6: 1 | EJ6: 1 | EK6: 1 | EL6: 1 | EM6: 1 | EN6: 1 | EO6: 1 | EP6: 1 | EQ6: 1 | ER6: 1 | ES6: =SUM(DY6,EA6,EC6,EE6,EG6,EI6,EK6,EM6,EO6,EQ6) -> 9 | ET6: =SUM(DZ6,EB6,ED6,EF6,EH6,EJ6,EL6,EN6,EP6,ER6) -> 9 | EU6: Drake | EV6: 2011 | EW6: =IF(C6=D6,"Y","N") -> Y | EX6: =IF(E6=F6,"Y","N") -> Y | EY6: =IF(G6=H6,"Y","N") -> Y | EZ6: =IF(I6=J6,"Y","N") -> Y | FA6: =IF(K6=L6,"Y","N") -> Y | FB6: =IF(M6=N6,"Y","N") -> Y | FC6: =IF(O6=P6,"Y","N") -> Y | FD6: =IF(Q6=R6,"Y","N") -> Y | FE6: =IF(S6=T6,"Y","N") -> Y | FF6: =IF(U6=V6,"Y","N") -> Y | FG6: =IF(W6=X6,"Y","N") -> Y | FH6: =IF(Y6=Z6,"Y","N") -> Y | FI6: =IF(AA6=AB6,"Y","N") -> Y | FJ6: =IF(AD6=AE6,"Y","N") -> Y | FK6: =IF(AG6=AH6,"Y","N") -> Y | FL6: =IF(AI6=AJ6,"Y","N") -> Y | FM6: =IF(AM6=AN6,"Y","N") -> Y | FN6: =IF(AO6=AP6,"Y","N") -> Y | FO6: =IF(AQ6=AR6,"Y","N") -> Y | FP6: =IF(AY6=AZ6,"Y","N") -> Y | FQ6: =IF(BA6=BB6,"Y","N") -> Y | FR6: =IF(BC6=BD6,"Y","N") -> Y | FS6: =IF(BE6=BF6,"Y","N") -> Y | FT6: =IF(BG6=BH6,"Y","N") -> Y | FU6: =IF(BI6=BJ6,"Y","N") -> Y | FV6: =IF(BK6=BL6,"Y","N") -> Y | FW6: =IF(BM6=BN6,"Y","N") -> Y | FX6: =IF(BO6=BP6,"Y","N") -> Y | FY6: =IF(BQ6=BR6,"Y","N") -> Y | FZ6: =IF(BS6=BT6,"Y","N") -> Y | GA6: =IF(BU6=BV6,"Y","N") -> Y | GB6: =IF(BW6=BX6,"Y","N") -> Y | GC6: =IF(BY6=BZ6,"Y","N") -> Y | GD6: =IF(CA6=CB6,"Y","N") -> Y | GE6: =IF(CC6=CD6,"Y","N") -> Y | GF6: =IF(CE6=CF6,"Y","N") -> Y | GG6: =IF(CG6=CH6, "Y", "N") -> Y | GH6: =IF(CI6=CJ6, "Y", "N") -> Y | GI6: =IF(CK6=CL6,"Y","N") -> Y | GJ6: =IF(CM6=CN6,"Y","N") -> Y | GK6: =IF(CO6=CP6,"Y","N") -> Y | GL6: =IF(CQ6=CR6,"Y","N") -> Y | GM6: =IF(CS6=CT6,"Y","N") -> Y | GN6: =IF(CU6=CV6,"Y","N") -> Y | GO6: =IF(CW6=CX6,"Y","N") -> Y | GP6: =IF(CY6=CZ6,"Y","N") -> Y | GQ6: =IF(DA6=DB6,"Y","N") -> Y | GR6: =IF(DC6=DD6,"Y","N") -> Y | GS6: =IF(DE6=DF6,"Y","N") -> Y | GT6: =IF(DG6=DH6,"Y","N") -> Y | GU6: =IF(DI6=DJ6,"Y","N") -> Y | GV6: =IF(DK6=DL6,"Y","N") -> Y | GW6: =IF(DM6=DN6,"Y","N") -> Y | GX6: =IF(DO6=DP6,"Y","N") -> Y | GY6: =IF(DQ6=DR6,"Y","N") -> Y | GZ6: =IF(DY6=DZ6,"Y","N") -> Y | HA6: =IF(EA6=EB6,"Y","N") -> Y | HB6: =IF(EC6=ED6,"Y","N") -> Y | HC6: =IF(EE6=EF6,"Y","N") -> Y | HD6: =IF(EG6=EH6,"Y","N") -> Y | HE6: =IF(EI6=EJ6,"Y","N") -> Y | HF6: =IF(EK6=EL6,"Y","N") -> Y | HG6: =IF(EM6=EN6,"Y","N") -> Y | HH6: =IF(EO6=EP6,"Y","N") -> Y | HI6: =IF(EQ6=ER6,"Y","N") -> Y | HJ6: =IF(ES6=ET6,"Y","N") -> Y
A7: Endres | B7: 2020 | C7: 32 | D7: 32 | E7: 44 | F7: 44 | G7: NS | H7: NS | I7: NS | J7: NS | K7: 37.22 | L7: 37.22 | M7: NS | N7: NS | O7: NS | P7: NS | Q7: NS | R7: NS | S7: NS | T7: NS | U7: 0 | V7: 0 | W7: 76 | X7: 76 | Y7: 0 | Z7: 0 | AA7: 0 | AB7: 0 | AC7: inpat_psych | AD7: Germany | AE7: Germany | AF7: euro | AG7: yes | AH7: yes | AI7: no | AJ7: no | AK7: no | AL7: no | AM7: 15 | AN7: 15 | AO7: 61 | AP7: 61 | AQ7: 0 | AR7: 0 | AS7: NS | AT7: NS | AU7: NS | AV7: NS | AW7: NS | AX7: NS | AY7: 76 | AZ7: 76 | BA7: 4 | BB7: 4 | BC7: multiple | BD7: multiple | BE7: =SUM(BI7,BK7,BQ7,BS7,BU7,BW7,BY7,CA7,CC7,CE7,CG7,CI7,CK7,CM7,CO7) -> 3 | BF7: =SUM(BJ7,BL7,BR7,BT7,BV7,BX7,BZ7,CB7,CD7,CF7,CH7,CJ7,CL7,CN7,CP7) -> 3 | BG7: =SUM(BM7,BO7) -> 1 | BH7: =SUM(BN7,BP7) -> 1 | BI7: 3 | BJ7: 3 | BK7: 0 | BL7: 0 | BM7: 1 | BN7: 1 | BO7: 0 | BP7: 0 | BQ7: 0 | BR7: 0 | BS7: 0 | BT7: 0 | BU7: 0 | BV7: 0 | BW7: 0 | BX7: 0 | BY7: 0 | BZ7: 0 | CA7: 0 | CB7: 0 | CC7: 0 | CD7: 0 | CE7: 0 | CF7: 0 | CG7: 0 | CH7: 0 | CI7: 0 | CJ7: 0 | CK7: 0 | CL7: 0 | CM7: 0 | CN7: 0 | CO7: 0 | CP7: 0 | CQ7: all | CR7: all | CS7: NS | CT7: NS | CU7: NS | CV7: NS | CW7: all | CX7: all | CY7: all | CZ7: all | DA7: all | DB7: all | DC7: all | DD7: all | DE7: all | DF7: all | DG7: NS | DH7: NS | DI7: NS | DJ7: NS | DK7: NS | DL7: NS | DM7: NS | DN7: NS | DO7: NS | DP7: NS | DQ7: NS | DR7: NS | DS7: disorder | DT7: disorder | DU7: NS | DV7: NS | DW7: ICD-10 | DX7: ICD-10 | DY7: 1 | DZ7: 1 | EA7: 1 | EB7: 1 | EC7: 1 | ED7: 1 | EE7: 1 | EF7: 1 | EG7: 1 | EH7: 1 | EI7: 1 | EJ7: 1 | EK7: 1 | EL7: 1 | EM7: 1 | EN7: 1 | EO7: 1 | EP7: 1 | EQ7: 1 | ER7: 1 | ES7: =SUM(DY7,EA7,EC7,EE7,EG7,EI7,EK7,EM7,EO7,EQ7) -> 10 | ET7: =SUM(DZ7,EB7,ED7,EF7,EH7,EJ7,EL7,EN7,EP7,ER7) -> 10 | EU7: Endres | EV7: 2020 | EW7: =IF(C7=D7,"Y","N") -> Y | EX7: =IF(E7=F7,"Y","N") -> Y | EY7: =IF(G7=H7,"Y","N") -> Y | EZ7: =IF(I7=J7,"Y","N") -> Y | FA7: =IF(K7=L7,"Y","N") -> Y | FB7: =IF(M7=N7,"Y","N") -> Y | FC7: =IF(O7=P7,"Y","N") -> Y | FD7: =IF(Q7=R7,"Y","N") -> Y | FE7: =IF(S7=T7,"Y","N") -> Y | FF7: =IF(U7=V7,"Y","N") -> Y | FG7: =IF(W7=X7,"Y","N") -> Y | FH7: =IF(Y7=Z7,"Y","N") -> Y | FI7: =IF(AA7=AB7,"Y","N") -> Y | FJ7: =IF(AD7=AE7,"Y","N") -> Y | FK7: =IF(AG7=AH7,"Y","N") -> Y | FL7: =IF(AI7=AJ7,"Y","N") -> Y | FM7: =IF(AM7=AN7,"Y","N") -> Y | FN7: =IF(AO7=AP7,"Y","N") -> Y | FO7: =IF(AQ7=AR7,"Y","N") -> Y | FP7: =IF(AY7=AZ7,"Y","N") -> Y | FQ7: =IF(BA7=BB7,"Y","N") -> Y | FR7: =IF(BC7=BD7,"Y","N") -> Y | FS7: =IF(BE7=BF7,"Y","N") -> Y | FT7: =IF(BG7=BH7,"Y","N") -> Y | FU7: =IF(BI7=BJ7,"Y","N") -> Y | FV7: =IF(BK7=BL7,"Y","N") -> Y | FW7: =IF(BM7=BN7,"Y","N") -> Y | FX7: =IF(BO7=BP7,"Y","N") -> Y | FY7: =IF(BQ7=BR7,"Y","N") -> Y | FZ7: =IF(BS7=BT7,"Y","N") -> Y | GA7: =IF(BU7=BV7,"Y","N") -> Y | GB7: =IF(BW7=BX7,"Y","N") -> Y | GC7: =IF(BY7=BZ7,"Y","N") -> Y | GD7: =IF(CA7=CB7,"Y","N") -> Y | GE7: =IF(CC7=CD7,"Y","N") -> Y | GF7: =IF(CE7=CF7,"Y","N") -> Y | GG7: =IF(CG7=CH7, "Y", "N") -> Y | GH7: =IF(CI7=CJ7, "Y", "N") -> Y | GI7: =IF(CK7=CL7,"Y","N") -> Y | GJ7: =IF(CM7=CN7,"Y","N") -> Y | GK7: =IF(CO7=CP7,"Y","N") -> Y | GL7: =IF(CQ7=CR7,"Y","N") -> Y | GM7: =IF(CS7=CT7,"Y","N") -> Y | GN7: =IF(CU7=CV7,"Y","N") -> Y | GO7: =IF(CW7=CX7,"Y","N") -> Y | GP7: =IF(CY7=CZ7,"Y","N") -> Y | GQ7: =IF(DA7=DB7,"Y","N") -> Y | GR7: =IF(DC7=DD7,"Y","N") -> Y | GS7: =IF(DE7=DF7,"Y","N") -> Y | GT7: =IF(DG7=DH7,"Y","N") -> Y | GU7: =IF(DI7=DJ7,"Y","N") -> Y | GV7: =IF(DK7=DL7,"Y","N") -> Y | GW7: =IF(DM7=DN7,"Y","N") -> Y | GX7: =IF(DO7=DP7,"Y","N") -> Y | GY7: =IF(DQ7=DR7,"Y","N") -> Y | GZ7: =IF(DY7=DZ7,"Y","N") -> Y | HA7: =IF(EA7=EB7,"Y","N") -> Y | HB7: =IF(EC7=ED7,"Y","N") -> Y | HC7: =IF(EE7=EF7,"Y","N") -> Y | HD7: =IF(EG7=EH7,"Y","N") -> Y | HE7: =IF(EI7=EJ7,"Y","N") -> Y | HF7: =IF(EK7=EL7,"Y","N") -> Y | HG7: =IF(EM7=EN7,"Y","N") -> Y | HH7: =IF(EO7=EP7,"Y","N") -> Y | HI7: =IF(EQ7=ER7,"Y","N") -> Y | HJ7: =IF(ES7=ET7,"Y","N") -> Y
A8: Etlouba | B8: 2018 | C8: 95 | D8: 95 | E8: 64 | F8: 64 | G8: 28.7 | H8: 28.7 | I8: 36.7 | J8: 36.7 | K8: 34.3 | L8: 34.3 | M8: 142 | N8: 142 | O8: 5 | P8: 5 | Q8: 7 | R8: 7 | S8: 5 | T8: 5 | U8: 159 | V8: 159 | W8: 0 | X8: 0 | Y8: 0 | Z8: 0 | AA8: 0 | AB8: 0 | AC8: gen_hospital | AD8: South Africa | AE8: South Africa | AF8: afri | AG8: yes | AH8: yes | AI8: no | AJ8: no | AK8: yes | AL8: yes | AM8: 159 | AN8: 159 | AO8: 0 | AP8: 0 | AQ8: 0 | AR8: 0 | AS8: 16.6 | AT8: 16.6 | AU8: 37.8 | AV8: NS | AX8: NS | AY8: 159 | AZ8: 159 | BA8: 124 | BB8: 124 | BC8: multiple | BD8: multiple | BE8: =SUM(BI8,BK8,BQ8,BS8,BU8,BW8,BY8,CA8,CC8,CE8,CG8,CI8,CK8,CM8,CO8) -> 87 | BF8: =SUM(BJ8,BL8,BR8,BT8,BV8,BX8,BZ8,CB8,CD8,CF8,CH8,CJ8,CL8,CN8,CP8) -> 87 | BG8: =SUM(BM8,BO8) -> 37 | BH8: =SUM(BN8,BP8) -> 37 | BI8: 0 | BJ8: 0 | BK8: 0 | BL8: 0 | BM8: 37 | BN8: 37 | BO8: 0 | BP8: 0 | BQ8: 2 | BR8: 2 | BS8: 0 | BT8: 0 | BU8: 4 | BV8: 4 | BW8: 0 | BX8: 0 | BY8: 75 | BZ8: 75 | CA8: 0 | CB8: 0 | CC8: 0 | CD8: 0 | CE8: 3 | CF8: 3 | CG8: 0 | CH8: 0 | CI8: 0 | CJ8: 0 | CK8: 2 | CL8: 2 | CM8: 1 | CN8: 1 | CO8: 0 | CP8: 0 | CQ8: NS | CR8: NS | CS8: yes - NS | CT8: yes - NS | CU8: yes - NS | CV8: yes - NS | CW8: NS | CX8: NS | CY8: yes - NS | CZ8: yes - NS | DA8: yes - NS | DB8: yes - NS | DC8: yes - NS | DD8: yes - NS | DE8: all | DF8: all | DG8: NS | DH8: NS | DI8: all | DJ8: all | DK8: NS | DL8: NS | DM8: NS | DN8: NS | DO8: X-ray (yes-NS) | DP8: X-ray (yes-NS) | DQ8: NS | DR8: NS | DS8: symptoms | DT8: symptoms | DU8: NS | DV8: NS | DW8: NS | DX8: NS | DY8: 1 | DZ8: 1 | EA8: 1 | EB8: 1 | EC8: 1 | ED8: 1 | EE8: 1 | EF8: 1 | EG8: 1 | EH8: 1 | EI8: 1 | EJ8: 1 | EK8: 1 | EL8: 1 | EM8: 1 | EN8: 1 | EO8: 1 | EP8: 1 | EQ8: 1 | ER8: 1 | ES8: =SUM(DY8,EA8,EC8,EE8,EG8,EI8,EK8,EM8,EO8,EQ8) -> 10 | ET8: =SUM(DZ8,EB8,ED8,EF8,EH8,EJ8,EL8,EN8,EP8,ER8) -> 10 | EU8: Etlouba | EV8: 2018 | EW8: =IF(C8=D8,"Y","N") -> Y | EX8: =IF(E8=F8,"Y","N") -> Y | EY8: =IF(G8=H8,"Y","N") -> Y | EZ8: =IF(I8=J8,"Y","N") -> Y | FA8: =IF(K8=L8,"Y","N") -> Y | FB8: =IF(M8=N8,"Y","N") -> Y | FC8: =IF(O8=P8,"Y","N") -> Y | FD8: =IF(Q8=R8,"Y","N") -> Y | FE8: =IF(S8=T8,"Y","N") -> Y | FF8: =IF(U8=V8,"Y","N") -> Y | FG8: =IF(W8=X8,"Y","N") -> Y | FH8: =IF(Y8=Z8,"Y","N") -> Y | FI8: =IF(AA8=AB8,"Y","N") -> Y | FJ8: =IF(AD8=AE8,"Y","N") -> Y | FK8: =IF(AG8=AH8,"Y","N") -> Y | FL8: =IF(AI8=AJ8,"Y","N") -> Y | FM8: =IF(AM8=AN8,"Y","N") -> Y | FN8: =IF(AO8=AP8,"Y","N") -> Y | FO8: =IF(AQ8=AR8,"Y","N") -> Y | FP8: =IF(AY8=AZ8,"Y","N") -> Y | FQ8: =IF(BA8=BB8,"Y","N") -> Y | FR8: =IF(BC8=BD8,"Y","N") -> Y | FS8: =IF(BE8=BF8,"Y","N") -> Y | FT8: =IF(BG8=BH8,"Y","N") -> Y | FU8: =IF(BI8=BJ8,"Y","N") -> Y | FV8: =IF(BK8=BL8,"Y","N") -> Y | FW8: =IF(BM8=BN8,"Y","N") -> Y | FX8: =IF(BO8=BP8,"Y","N") -> Y | FY8: =IF(BQ8=BR8,"Y","N") -> Y | FZ8: =IF(BS8=BT8,"Y","N") -> Y | GA8: =IF(BU8=BV8,"Y","N") -> Y | GB8: =IF(BW8=BX8,"Y","N") -> Y | GC8: =IF(BY8=BZ8,"Y","N") -> Y | GD8: =IF(CA8=CB8,"Y","N") -> Y | GE8: =IF(CC8=CD8,"Y","N") -> Y | GF8: =IF(CE8=CF8,"Y","N") -> Y | GG8: =IF(CG8=CH8, "Y", "N") -> Y | GH8: =IF(CI8=CJ8, "Y", "N") -> Y | GI8: =IF(CK8=CL8,"Y","N") -> Y | GJ8: =IF(CM8=CN8,"Y","N") -> Y | GK8: =IF(CO8=CP8,"Y","N") -> Y | GL8: =IF(CQ8=CR8,"Y","N") -> Y | GM8: =IF(CS8=CT8,"Y","N") -> Y | GN8: =IF(CU8=CV8,"Y","N") -> Y | GO8: =IF(CW8=CX8,"Y","N") -> Y | GP8: =IF(CY8=CZ8,"Y","N") -> Y | GQ8: =IF(DA8=DB8,"Y","N") -> Y | GR8: =IF(DC8=DD8,"Y","N") -> Y | GS8: =IF(DE8=DF8,"Y","N") -> Y | GT8: =IF(DG8=DH8,"Y","N") -> Y | GU8: =IF(DI8=DJ8,"Y","N") -> Y | GV8: =IF(DK8=DL8,"Y","N") -> Y | GW8: =IF(DM8=DN8,"Y","N") -> Y | GX8: =IF(DO8=DP8,"Y","N") -> Y | GY8: =IF(DQ8=DR8,"Y","N") -> Y | GZ8: =IF(DY8=DZ8,"Y","N") -> Y | HA8: =IF(EA8=EB8,"Y","N") -> Y | HB8: =IF(EC8=ED8,"Y","N") -> Y | HC8: =IF(EE8=EF8,"Y","N") -> Y | HD8: =IF(EG8=EH8,"Y","N") -> Y | HE8: =IF(EI8=EJ8,"Y","N") -> Y | HF8: =IF(EK8=EL8,"Y","N") -> Y | HG8: =IF(EM8=EN8,"Y","N") -> Y | HH8: =IF(EO8=EP8,"Y","N") -> Y | HI8: =IF(EQ8=ER8,"Y","N") -> Y | HJ8: =IF(ES8=ET8,"Y","N") -> Y
A9: Fraser | B9: 2020 | C9: 47 | D9: 47 | E9: 14 | F9: 14 | G9: 21.3 | H9: 21.3 | I9: 20.1 | J9: 20.1 | K9: 20.6 | L9: 20.6 | M9: NS | N9: NS | O9: NS | P9: NS | Q9: NS | R9: NS | S9: NS | T9: NS | U9: 0 | V9: 0 | W9: 61 | X9: 61 | Y9: 0 | Z9: 0 | AA9: 0 | AB9: 0 | AC9: inpat_psych | AD9: Australia | AE9: Australia | AF9: aus | AG9: no | AH9: no | AI9: yes | AJ9: yes | AK9: yes | AL9: yes | AM9: 61 | AN9: 61 | AO9: 0 | AP9: 0 | AQ9: 0 | AR9: 0 | AS9: 2.9 | AT9: NS | AU9: 3.4 | AV9: NS | AW9: 2.4 | AX9: 2.4 | AY9: 61 | AZ9: 61 | BA9: 34 | BB9: 34 | BC9: single | BD9: single | BE9: =SUM(BI9,BK9,BQ9,BS9,BU9,BW9,BY9,CA9,CC9,CE9,CG9,CI9,CK9,CM9,CO9) -> 0 | BF9: =SUM(BJ9,BL9,BR9,BT9,BV9,BX9,BZ9,CB9,CD9,CF9,CH9,CJ9,CL9,CN9,CP9) -> 0 | BG9: =SUM(BM9,BO9) -> 34 | BH9: =SUM(BN9,BP9) -> 34 | BI9: NA | BJ9: NA | BK9: NA | BL9: NA | BM9: 34 | BN9: 34 | BO9: NA | BP9: NA | BQ9: NA | BR9: NA | BS9: NA | BT9: NA | BU9: NA | BV9: NA | BW9: NA | BX9: NA | BY9: NA | BZ9: NA | CA9: NA | CB9: NA | CC9: NA | CD9: NA | CE9: NA | CF9: NA | CG9: NA | CH9: NA | CI9: NA | CJ9: NA | CK9: NA | CL9: NA | CM9: NA | CN9: NA | CO9: NA | CP9: NA | CQ9: NS | CR9: NS | CS9: NS | CT9: NS | CU9: NS | CV9: NS | CW9: NS | CX9: NS | CY9: NS | CZ9: NS | DA9: NS | DB9: NS | DC9: yes - NS | DD9: yes - NS | DE9: all | DF9: all | DG9: yes | DH9: yes | DI9: NS | DJ9: NS | DK9: NS | DL9: NS | DM9: NS | DN9: NS | DO9: NS | DP9: NS | DQ9: NS | DR9: NS | DS9: disorder | DT9: disorder | DU9: PRISM | DV9: PRISM | DW9: DSM-IV | DX9: DSM-IV | DY9: 1 | DZ9: 1 | EA9: 0 | EB9: 0 | EC9: 1 | ED9: 1 | EE9: 1 | EF9: 1 | EG9: 1 | EH9: 1 | EI9: 1 | EJ9: 1 | EK9: 1 | EL9: 1 | EM9: 1 | EN9: 1 | EO9: 1 | EP9: 1 | EQ9: 1 | ER9: 1 | ES9: =SUM(DY9,EA9,EC9,EE9,EG9,EI9,EK9,EM9,EO9,EQ9) -> 9 | ET9: =SUM(DZ9,EB9,ED9,EF9,EH9,EJ9,EL9,EN9,EP9,ER9) -> 9 | EW9: =IF(C9=D9,"Y","N") -> Y | EX9: =IF(E9=F9,"Y","N") -> Y | EY9: =IF(G9=H9,"Y","N") -> Y | EZ9: =IF(I9=J9,"Y","N") -> Y | FA9: =IF(K9=L9,"Y","N") -> Y | FC9: =IF(O9=P9,"Y","N") -> Y | FD9: =IF(Q9=R9,"Y","N") -> Y | FE9: =IF(S9=T9,"Y","N") -> Y | FF9: =IF(U9=V9,"Y","N") -> Y | FG9: =IF(W9=X9,"Y","N") -> Y | FH9: =IF(Y9=Z9,"Y","N") -> Y | FI9: =IF(AA9=AB9,"Y","N") -> Y | FJ9: =IF(AD9=AE9,"Y","N") -> Y | FK9: =IF(AG9=AH9,"Y","N") -> Y | FL9: =IF(AI9=AJ9,"Y","N") -> Y | FM9: =IF(AM9=AN9,"Y","N") -> Y | FN9: =IF(AO9=AP9,"Y","N") -> Y | FO9: =IF(AQ9=AR9,"Y","N") -> Y | FP9: =IF(AY9=AZ9,"Y","N") -> Y | FQ9: =IF(BA9=BB9,"Y","N") -> Y | FR9: =IF(BC9=BD9,"Y","N") -> Y | FS9: =IF(BE9=BF9,"Y","N") -> Y | FT9: =IF(BG9=BH9,"Y","N") -> Y | FU9: =IF(BI9=BJ9,"Y","N") -> Y | FV9: =IF(BK9=BL9,"Y","N") -> Y | FW9: =IF(BM9=BN9,"Y","N") -> Y | FX9: =IF(BO9=BP9,"Y","N") -> Y | FY9: =IF(BQ9=BR9,"Y","N") -> Y | FZ9: =IF(BS9=BT9,"Y","N") -> Y | GA9: =IF(BU9=BV9,"Y","N") -> Y | GB9: =IF(BW9=BX9,"Y","N") -> Y | GC9: =IF(BY9=BZ9,"Y","N") -> Y | GD9: =IF(CA9=CB9,"Y","N") -> Y | GE9: =IF(CC9=CD9,"Y","N") -> Y | GF9: =IF(CE9=CF9,"Y","N") -> Y | GG9: =IF(CG9=CH9, "Y", "N") -> Y | GH9: =IF(CI9=CJ9, "Y", "N") -> Y | GI9: =IF(CK9=CL9,"Y","N") -> Y | GJ9: =IF(CM9=CN9,"Y","N") -> Y | GK9: =IF(CO9=CP9,"Y","N") -> Y | GL9: =IF(CQ9=CR9,"Y","N") -> Y | GM9: =IF(CS9=CT9,"Y","N") -> Y | GN9: =IF(CU9=CV9,"Y","N") -> Y | GO9: =IF(CW9=CX9,"Y","N") -> Y | GP9: =IF(CY9=CZ9,"Y","N") -> Y | GQ9: =IF(DA9=DB9,"Y","N") -> Y | GR9: =IF(DC9=DD9,"Y","N") -> Y | GS9: =IF(DE9=DF9,"Y","N") -> Y | GT9: =IF(DG9=DH9,"Y","N") -> Y | GU9: =IF(DI9=DJ9,"Y","N") -> Y | GV9: =IF(DK9=DL9,"Y","N") -> Y | GW9: =IF(DM9=DN9,"Y","N") -> Y | GX9: =IF(DO9=DP9,"Y","N") -> Y | GY9: =IF(DQ9=DR9,"Y","N") -> Y | GZ9: =IF(DY9=DZ9,"Y","N") -> Y | HA9: =IF(EA9=EB9,"Y","N") -> Y | HB9: =IF(EC9=ED9,"Y","N") -> Y | HC9: =IF(EE9=EF9,"Y","N") -> Y | HD9: =IF(EG9=EH9,"Y","N") -> Y | HE9: =IF(EI9=EJ9,"Y","N") -> Y | HF9: =IF(EK9=EL9,"Y","N") -> Y | HG9: =IF(EM9=EN9,"Y","N") -> Y | HH9: =IF(EO9=EP9,"Y","N") -> Y | HI9: =IF(EQ9=ER9,"Y","N") -> Y | HJ9: =IF(ES9=ET9,"Y","N") -> Y
A10: Funayama | B10: 2022 | C10: 68 | D10: 68 | E10: 119 | F10: 119 | G10: 36.7 | H10: 36.7 | I10: 32.3 | J10: 32.3 | K10: NS | L10: NS | M10: NS | N10: NS | O10: NS | P10: NS | Q10: NS | R10: NS | S10: NS | T10: NS | U10: 0 | V10: 0 | W10: 187 | X10: 187 | Y10: 0 | Z10: 0 | AA10: 0 | AB10: 0 | AC10: inpat_psych | AD10: Japan | AE10: Japan | AF10: asia | AG10: yes | AH10: yes | AI10: no | AJ10: no | AK10: yes | AL10: yes | AM10: 187 | AN10: 187 | AO10: 0 | AP10: 0 | AQ10: 0 | AR10: 0 | AS10: NS | AT10: NS | AU10: NS | AV10: NS | AW10: NS | AX10: NS | AY10: 187 | AZ10: 187 | BA10: 10 | BB10: 10 | BC10: single | BD10: single | BE10: =SUM(BI10,BK10,BQ10,BS10,BU10,BW10,BY10,CA10,CC10,CE10,CG10,CI10,CK10,CM10,CO10) -> 10 | BF10: =SUM(BJ10,BL10,BR10,BT10,BV10,BX10,BZ10,CB10,CD10,CF10,CH10,CJ10,CL10,CN10,CP10) -> 10 | BG10: =SUM(BM10,BO10) -> 0 | BH10: =SUM(BN10,BP10) -> 0 | BI10: 10 | BJ10: 10 | BK10: NA | BL10: NA | BM10: NA | BN10: NA | BO10: NA | BP10: NA | BQ10: NA | BR10: NA | BS10: NA | BT10: NA | BU10: NA | BV10: NA | BW10: NA | BX10: NA | BY10: NA | BZ10: NA | CA10: NA | CB10: NA | CC10: NA | CD10: NA | CE10: NA | CF10: NA | CG10: NA | CH10: NA | CI10: NA | CJ10: NA | CK10: NA | CL10: NA | CM10: NA | CN10: NA | CO10: NA | CP10: NA | CQ10: yes - NS | CR10: yes - NS | CS10: NS | CT10: NS | CU10: NS | CV10: NS | CW10: yes - NS | CX10: yes - NS | CY10: yes - NS | CZ10: yes - NS | DA10: all | DB10: all | DC10: NS | DD10: NS | DE10: all | DF10: all | DG10: NS | DH10: NS | DI10: all | DJ10: all | DK10: all | DL10: all | DM10: no | DN10: no | DO10: NS | DP10: NS | DQ10: NS | DR10: NS | DS10: symptoms | DT10: symptoms | DU10: NS | DV10: NS | DW10: ICD-10 | DX10: ICD-10 | DY10: 1 | DZ10: 1 | EA10: 1 | EB10: 1 | EC10: 1 | ED10: 1 | EE10: 1 | EF10: 1 | EG10: 1 | EH10: 1 | EI10: 1 | EJ10: 1 | EK10: 1 | EL10: 1 | EM10: 1 | EN10: 1 | EO10: 1 | EP10: 1 | EQ10: 1 | ER10: 1 | ES10: =SUM(DY10,EA10,EC10,EE10,EG10,EI10,EK10,EM10,EO10,EQ10) -> 10 | ET10: =SUM(DZ10,EB10,ED10,EF10,EH10,EJ10,EL10,EN10,EP10,ER10) -> 10 | EU10: Funayama | EV10: 2022 | EW10: =IF(C10=D10,"Y","N") -> Y | EX10: =IF(E10=F10,"Y","N") -> Y | EY10: =IF(G10=H10,"Y","N") -> Y | EZ10: =IF(I10=J10,"Y","N") -> Y | FA10: =IF(K10=L10,"Y","N") -> Y | FB10: =IF(M10=N10,"Y","N") -> Y | FC10: =IF(O10=P10,"Y","N") -> Y | FD10: =IF(Q10=R10,"Y","N") -> Y | FE10: =IF(S10=T10,"Y","N") -> Y | FF10: =IF(U10=V10,"Y","N") -> Y | FG10: =IF(W10=X10,"Y","N") -> Y | FH10: =IF(Y10=Z10,"Y","N") -> Y | FI10: =IF(AA10=AB10,"Y","N") -> Y | FJ10: =IF(AD10=AE10,"Y","N") -> Y | FK10: =IF(AG10=AH10,"Y","N") -> Y | FL10: =IF(AI10=AJ10,"Y","N") -> Y | FM10: =IF(AM10=AN10,"Y","N") -> Y | FN10: =IF(AO10=AP10,"Y","N") -> Y | FO10: =IF(AQ10=AR10,"Y","N") -> Y | FP10: =IF(AY10=AZ10,"Y","N") -> Y | FQ10: =IF(BA10=BB10,"Y","N") -> Y | FR10: =IF(BC10=BD10,"Y","N") -> Y | FS10: =IF(BE10=BF10,"Y","N") -> Y | FT10: =IF(BG10=BH10,"Y","N") -> Y | FU10: =IF(BI10=BJ10,"Y","N") -> Y | FV10: =IF(BK10=BL10,"Y","N") -> Y | FW10: =IF(BM10=BN10,"Y","N") -> Y | FX10: =IF(BO10=BP10,"Y","N") -> Y | FY10: =IF(BQ10=BR10,"Y","N") -> Y | FZ10: =IF(BS10=BT10,"Y","N") -> Y | GA10: =IF(BU10=BV10,"Y","N") -> Y | GB10: =IF(BW10=BX10,"Y","N") -> Y | GC10: =IF(BY10=BZ10,"Y","N") -> Y | GD10: =IF(CA10=CB10,"Y","N") -> Y | GE10: =IF(CC10=CD10,"Y","N") -> Y | GF10: =IF(CE10=CF10,"Y","N") -> Y | GG10: =IF(CG10=CH10, "Y", "N") -> Y | GH10: =IF(CI10=CJ10, "Y", "N") -> Y | GI10: =IF(CK10=CL10,"Y","N") -> Y | GJ10: =IF(CM10=CN10,"Y","N") -> Y | GK10: =IF(CO10=CP10,"Y","N") -> Y | GL10: =IF(CQ10=CR10,"Y","N") -> Y | GM10: =IF(CS10=CT10,"Y","N") -> Y | GN10: =IF(CU10=CV10,"Y","N") -> Y | GO10: =IF(CW10=CX10,"Y","N") -> Y | GP10: =IF(CY10=CZ10,"Y","N") -> Y | GQ10: =IF(DA10=DB10,"Y","N") -> Y | GR10: =IF(DC10=DD10,"Y","N") -> Y | GS10: =IF(DE10=DF10,"Y","N") -> Y | GT10: =IF(DG10=DH10,"Y","N") -> Y | GU10: =IF(DI10=DJ10,"Y","N") -> Y | GV10: =IF(DK10=DL10,"Y","N") -> Y | GW10: =IF(DM10=DN10,"Y","N") -> Y | GX10: =IF(DO10=DP10,"Y","N") -> Y | GY10: =IF(DQ10=DR10,"Y","N") -> Y | GZ10: =IF(DY10=DZ10,"Y","N") -> Y | HA10: =IF(EA10=EB10,"Y","N") -> Y | HB10: =IF(EC10=ED10,"Y","N") -> Y | HC10: =IF(EE10=EF10,"Y","N") -> Y | HD10: =IF(EG10=EH10,"Y","N") -> Y | HE10: =IF(EI10=EJ10,"Y","N") -> Y | HF10: =IF(EK10=EL10,"Y","N") -> Y | HG10: =IF(EM10=EN10,"Y","N") -> Y | HH10: =IF(EO10=EP10,"Y","N") -> Y | HI10: =IF(EQ10=ER10,"Y","N") -> Y | HJ10: =IF(ES10=ET10,"Y","N") -> Y
A11: Giannitelli | B11: 2018 | C11: NS | D11: NS | E11: NS | F11: NS | G11: NS | H11: NS | I11: NS | J11: NS | K11: NS | L11: NS | M11: NS | N11: NS | O11: NS | P11: NS | Q11: NS | R11: NS | S11: NS | T11: NS | U11: 160 | V11: 160 | W11: NS | X11: NS | Y11: NS | Z11: NS | AA11: NS | AB11: NS | AC11: gen_hospital | AD11: France | AE11: France | AF11: euro | AG11: yes | AH11: yes | AI11: no | AJ11: no | AK11: NS | AL11: NS | AM11: NS | AN11: NS | AO11: NS | AP11: NS | AQ11: NS | AR11: NS | AS11: NS | AT11: NS | AU11: NS | AV11: NS | AW11: NS | AX11: NS | AY11: 160 | AZ11: 160 | BA11: 20 | BB11: 20 | BC11: multiple | BD11: multiple | BE11: =SUM(BI11,BK11,BQ11,BS11,BU11,BW11,BY11,CA11,CC11,CE11,CG11,CI11,CK11,CM11,CO11) -> 20 | BF11: =SUM(BJ11,BL11,BR11,BT11,BV11,BX11,BZ11,CB11,CD11,CF11,CH11,CJ11,CL11,CN11,CP11) -> 20 | BG11: =SUM(BM11,BO11) -> 0 | BH11: =SUM(BN11,BP11) -> 0 | BI11: 3 | BJ11: 3 | BK11: 15 | BL11: 15 | BM11: 0 | BN11: 0 | BO11: 0 | BP11: 0 | BQ11: 0 | BR11: 0 | BS11: 2 | BT11: 2 | BU11: 0 | BV11: 0 | BW11: 0 | BX11: 0 | BY11: 0 | BZ11: 0 | CA11: 0 | CB11: 0 | CC11: 0 | CD11: 0 | CE11: 0 | CF11: 0 | CG11: 0 | CH11: 0 | CI11: 0 | CJ11: 0 | CK11: 0 | CL11: 0 | CM11: 0 | CN11: 0 | CO11: 0 | CP11: 0 | CQ11: NS | CR11: NS | CS11: NS | CT11: NS | CU11: NS | CV11: NS | CW11: yes - NS | CX11: yes - NS | CY11: NS | CZ11: NS | DA11: yes - NS | DB11: yes - NS | DC11: NS | DD11: NS | DE11: NS | DF11: NS | DG11: NS | DH11: NS | DI11: NS | DJ11: NS | DK11: NS | DL11: NS | DM11: NS | DN11: NS | DO11: NS | DP11: NS | DQ11: NS | DR11: NS | DS11: disorder | DT11: disorder | DU11: NS | DV11: NS | DW11: NS | DX11: NS | DY11: 1 | DZ11: 1 | EA11: 1 | EB11: 1 | EC11: 1 | ED11: 1 | EE11: 1 | EF11: 1 | EG11: 1 | EH11: 1 | EI11: 1 | EJ11: 1 | EK11: 1 | EL11: 1 | EM11: 1 | EN11: 1 | EO11: 1 | EP11: 1 | EQ11: 1 | ER11: 1 | ES11: =SUM(DY11,EA11,EC11,EE11,EG11,EI11,EK11,EM11,EO11,EQ11) -> 10 | ET11: =SUM(DZ11,EB11,ED11,EF11,EH11,EJ11,EL11,EN11,EP11,ER11) -> 10 | EU11: Giannitelli | EV11: 2018 | EW11: =IF(C11=D11,"Y","N") -> Y | EX11: =IF(E11=F11,"Y","N") -> Y | EY11: =IF(G11=H11,"Y","N") -> Y | EZ11: =IF(I11=J11,"Y","N") -> Y | FA11: =IF(K11=L11,"Y","N") -> Y | FB11: =IF(M11=N11,"Y","N") -> Y | FC11: =IF(O11=P11,"Y","N") -> Y | FD11: =IF(Q11=R11,"Y","N") -> Y | FE11: =IF(S11=T11,"Y","N") -> Y | FF11: =IF(U11=V11,"Y","N") -> Y | FG11: =IF(W11=X11,"Y","N") -> Y | FH11: =IF(Y11=Z11,"Y","N") -> Y | FI11: =IF(AA11=AB11,"Y","N") -> Y | FJ11: =IF(AD11=AE11,"Y","N") -> Y | FK11: =IF(AG11=AH11,"Y","N") -> Y | FL11: =IF(AI11=AJ11,"Y","N") -> Y | FM11: =IF(AM11=AN11,"Y","N") -> Y | FN11: =IF(AO11=AP11,"Y","N") -> Y | FO11: =IF(AQ11=AR11,"Y","N") -> Y | FP11: =IF(AY11=AZ11,"Y","N") -> Y | FQ11: =IF(BA11=BB11,"Y","N") -> Y | FR11: =IF(BC11=BD11,"Y","N") -> Y | FS11: =IF(BE11=BF11,"Y","N") -> Y | FT11: =IF(BG11=BH11,"Y","N") -> Y | FU11: =IF(BI11=BJ11,"Y","N") -> Y | FV11: =IF(BK11=BL11,"Y","N") -> Y | FW11: =IF(BM11=BN11,"Y","N") -> Y | FX11: =IF(BO11=BP11,"Y","N") -> Y | FY11: =IF(BQ11=BR11,"Y","N") -> Y | FZ11: =IF(BS11=BT11,"Y","N") -> Y | GA11: =IF(BU11=BV11,"Y","N") -> Y | GB11: =IF(BW11=BX11,"Y","N") -> Y | GC11: =IF(BY11=BZ11,"Y","N") -> Y | GD11: =IF(CA11=CB11,"Y","N") -> Y | GE11: =IF(CC11=CD11,"Y","N") -> Y | GF11: =IF(CE11=CF11,"Y","N") -> Y | GG11: =IF(CG11=CH11, "Y", "N") -> Y | GH11: =IF(CI11=CJ11, "Y", "N") -> Y | GI11: =IF(CK11=CL11,"Y","N") -> Y | GJ11: =IF(CM11=CN11,"Y","N") -> Y | GK11: =IF(CO11=CP11,"Y","N") -> Y | GL11: =IF(CQ11=CR11,"Y","N") -> Y | GM11: =IF(CS11=CT11,"Y","N") -> Y | GN11: =IF(CU11=CV11,"Y","N") -> Y | GO11: =IF(CW11=CX11,"Y","N") -> Y | GP11: =IF(CY11=CZ11,"Y","N") -> Y | GQ11: =IF(DA11=DB11,"Y","N") -> Y | GR11: =IF(DC11=DD11,"Y","N") -> Y | GS11: =IF(DE11=DF11,"Y","N") -> Y | GT11: =IF(DG11=DH11,"Y","N") -> Y | GU11: =IF(DI11=DJ11,"Y","N") -> Y | GV11: =IF(DK11=DL11,"Y","N") -> Y | GW11: =IF(DM11=DN11,"Y","N") -> Y | GX11: =IF(DO11=DP11,"Y","N") -> Y | GY11: =IF(DQ11=DR11,"Y","N") -> Y | GZ11: =IF(DY11=DZ11,"Y","N") -> Y | HA11: =IF(EA11=EB11,"Y","N") -> Y | HB11: =IF(EC11=ED11,"Y","N") -> Y | HC11: =IF(EE11=EF11,"Y","N") -> Y | HD11: =IF(EG11=EH11,"Y","N") -> Y | HE11: =IF(EI11=EJ11,"Y","N") -> Y | HF11: =IF(EK11=EL11,"Y","N") -> Y | HG11: =IF(EM11=EN11,"Y","N") -> Y | HH11: =IF(EO11=EP11,"Y","N") -> Y | HI11: =IF(EQ11=ER11,"Y","N") -> Y | HJ11: =IF(ES11=ET11,"Y","N") -> Y
A12: Guasp | B12: 2021 | C12: 61 | D12: 61 | E12: 44 | F12: 44 | G12: NS | H12: NS | I12: NS | J12: NS | K12: NS | L12: NS | M12: NS | N12: NS | O12: NS | P12: NS | Q12: NS | R12: NS | S12: NS | T12: NS | U12: 0 | V12: 0 | W12: 105 | X12: 105 | Y12: 0 | Z12: 0 | AA12: 0 | AB12: 0 | AC12: inpat_psych | AD12: Spain | AE12: Spain | AF12: euro | AG12: no | AH12: no | AI12: yes | AJ12: yes | AK12: yes | AL12: yes | AM12: 105 | AN12: 105 | AO12: 0 | AP12: 0 | AQ12: 0 | AR12: 0 | AS12: 79 | AT12: 79 | AU12: NS | AV12: NS | AW12: NS | AX12: NS | AY12: 105 | AZ12: 105 | BA12: 4 | BB12: 4 | BC12: multiple | BD12: multiple | BE12: =SUM(BI12,BK12,BQ12,BS12,BU12,BW12,BY12,CA12,CC12,CE12,CG12,CI12,CK12,CM12,CO12) -> 4 | BF12: =SUM(BJ12,BL12,BR12,BT12,BV12,BX12,BZ12,CB12,CD12,CF12,CH12,CJ12,CL12,CN12,CP12) -> 4 | BG12: =SUM(BM12,BO12) -> 0 | BH12: =SUM(BN12,BP12) -> 0 | BI12: 0 | BJ12: 0 | BK12: 0 | BL12: 0 | BM12: 0 | BN12: 0 | BO12: 0 | BP12: 0 | BQ12: 0 | BR12: 0 | BS12: 0 | BT12: 0 | BU12: 1 | BV12: 1 | BW12: 0 | BX12: 0 | BY12: 1 | BZ12: 1 | CA12: 1 | CB12: 1 | CC12: 0 | CD12: 0 | CE12: 0 | CF12: 0 | CG12: 0 | CH12: 0 | CI12: 0 | CJ12: 0 | CK12: 1 | CL12: 1 | CM12: 0 | CN12: 0 | CO12: 0 | CP12: 0 | CQ12: all | CR12: all | CS12: NS | CT12: NS | CU12: NS | CV12: NS | CW12: some | CX12: some | CY12: all | CZ12: all | DA12: all | DB12: all | DC12: all | DD12: all | DE12: all | DF12: all | DG12: NS | DH12: NS | DI12: all | DJ12: all | DK12: NS | DL12: NS | DM12: NS | DN12: NS | DO12: NS | DP12: NS | DQ12: NS | DR12: NS | DS12: disorder | DT12: disorder | DU12: SCID | DV12: SCID and PANSS | DW12: DSM-IV | DX12: DSM-IV | DY12: 1 | DZ12: 1 | EA12: 1 | EB12: 1 | EC12: 1 | ED12: 1 | EE12: 1 | EF12: 1 | EG12: 1 | EH12: 1 | EI12: 1 | EJ12: 1 | EK12: 1 | EL12: 1 | EM12: 1 | EN12: 1 | EO12: 1 | EP12: 1 | EQ12: 1 | ER12: 1 | ES12: =SUM(DY12,EA12,EC12,EE12,EG12,EI12,EK12,EM12,EO12,EQ12) -> 10 | ET12: =SUM(DZ12,EB12,ED12,EF12,EH12,EJ12,EL12,EN12,EP12,ER12) -> 10 | EU12: Guasp | EV12: 2021 | EW12: =IF(C12=D12,"Y","N") -> Y | EX12: =IF(E12=F12,"Y","N") -> Y | EY12: =IF(G12=H12,"Y","N") -> Y | EZ12: =IF(I12=J12,"Y","N") -> Y | FA12: =IF(K12=L12,"Y","N") -> Y | FB12: =IF(M12=N12,"Y","N") -> Y | FC12: =IF(O12=P12,"Y","N") -> Y | FD12: =IF(Q12=R12,"Y","N") -> Y | FE12: =IF(S12=T12,"Y","N") -> Y | FF12: =IF(U12=V12,"Y","N") -> Y | FG12: =IF(W12=X12,"Y","N") -> Y | FH12: =IF(Y12=Z12,"Y","N") -> Y | FI12: =IF(AA12=AB12,"Y","N") -> Y | FJ12: =IF(AD12=AE12,"Y","N") -> Y | FK12: =IF(AG12=AH12,"Y","N") -> Y | FL12: =IF(AI12=AJ12,"Y","N") -> Y | FM12: =IF(AM12=AN12,"Y","N") -> Y | FN12: =IF(AO12=AP12,"Y","N") -> Y | FO12: =IF(AQ12=AR12,"Y","N") -> Y | FP12: =IF(AY12=AZ12,"Y","N") -> Y | FQ12: =IF(BA12=BB12,"Y","N") -> Y | FR12: =IF(BC12=BD12,"Y","N") -> Y | FS12: =IF(BE12=BF12,"Y","N") -> Y | FT12: =IF(BG12=BH12,"Y","N") -> Y | FU12: =IF(BI12=BJ12,"Y","N") -> Y | FV12: =IF(BK12=BL12,"Y","N") -> Y | FW12: =IF(BM12=BN12,"Y","N") -> Y | FX12: =IF(BO12=BP12,"Y","N") -> Y | FY12: =IF(BQ12=BR12,"Y","N") -> Y | FZ12: =IF(BS12=BT12,"Y","N") -> Y | GA12: =IF(BU12=BV12,"Y","N") -> Y | GB12: =IF(BW12=BX12,"Y","N") -> Y | GC12: =IF(BY12=BZ12,"Y","N") -> Y | GD12: =IF(CA12=CB12,"Y","N") -> Y | GE12: =IF(CC12=CD12,"Y","N") -> Y | GF12: =IF(CE12=CF12,"Y","N") -> Y | GG12: =IF(CG12=CH12, "Y", "N") -> Y | GH12: =IF(CI12=CJ12, "Y", "N") -> Y | GI12: =IF(CK12=CL12,"Y","N") -> Y | GJ12: =IF(CM12=CN12,"Y","N") -> Y | GK12: =IF(CO12=CP12,"Y","N") -> Y | GL12: =IF(CQ12=CR12,"Y","N") -> Y | GM12: =IF(CS12=CT12,"Y","N") -> Y | GN12: =IF(CU12=CV12,"Y","N") -> Y | GO12: =IF(CW12=CX12,"Y","N") -> Y | GP12: =IF(CY12=CZ12,"Y","N") -> Y | GQ12: =IF(DA12=DB12,"Y","N") -> Y | GR12: =IF(DC12=DD12,"Y","N") -> Y | GS12: =IF(DE12=DF12,"Y","N") -> Y | GT12: =IF(DG12=DH12,"Y","N") -> Y | GU12: =IF(DI12=DJ12,"Y","N") -> Y | GV12: =IF(DK12=DL12,"Y","N") -> Y | GW12: =IF(DM12=DN12,"Y","N") -> Y | GX12: =IF(DO12=DP12,"Y","N") -> Y | GY12: =IF(DQ12=DR12,"Y","N") -> Y | GZ12: =IF(DY12=DZ12,"Y","N") -> Y | HA12: =IF(EA12=EB12,"Y","N") -> Y | HB12: =IF(EC12=ED12,"Y","N") -> Y | HC12: =IF(EE12=EF12,"Y","N") -> Y | HD12: =IF(EG12=EH12,"Y","N") -> Y | HE12: =IF(EI12=EJ12,"Y","N") -> Y | HF12: =IF(EK12=EL12,"Y","N") -> Y | HG12: =IF(EM12=EN12,"Y","N") -> Y | HH12: =IF(EO12=EP12,"Y","N") -> Y | HI12: =IF(EQ12=ER12,"Y","N") -> Y | HJ12: =IF(ES12=ET12,"Y","N") -> Y
A13: Harris | B13: 2019 | C13: 480 | D13: 480 | E13: 325 | F13: 325 | G13: NS | H13: NS | I13: NS | J13: NS | K13: 32 | L13: 32 | M13: NS | N13: NS | O13: NS | P13: NS | Q13: NS | R13: NS | S13: NS | T13: NS | U13: NS | V13: NS | W13: NS | X13: NS | Y13: 0 | Z13: 0 | AA13: 0 | AB13: 0 | AC13: NS | AD13: Australia | AE13: Australia | AF13: aus | AG13: yes | AH13: yes | AI13: no | AJ13: no | AK13: no | AL13: no | AM13: NS | AN13: NS | AO13: NS | AP13: NS | AQ13: NS | AR13: NS | AS13: NS | AT13: NS | AU13: NS | AV13: NS | AW13: NS | AX13: NS | AY13: 805 | AZ13: 805 | BA13: 3 | BB13: 3 | BC13: multiple | BD13: multiple | BE13: =SUM(BI13,BK13,BQ13,BS13,BU13,BW13,BY13,CA13,CC13,CE13,CG13,CI13,CK13,CM13,CO13) -> 3 | BF13: =SUM(BJ13,BL13,BR13,BT13,BV13,BX13,BZ13,CB13,CD13,CF13,CH13,CJ13,CL13,CN13,CP13) -> 3 | BG13: =SUM(BM13,BO13) -> 0 | BH13: =SUM(BN13,BP13) -> 0 | BI13: NA | BJ13: NA | BK13: NA | BL13: NA | BM13: NA | BN13: NA | BO13: NA | BP13: NA | BQ13: NA | BR13: NA | BS13: NA | BT13: NA | BU13: NA | BV13: NA | BW13: NA | BX13: NA | BY13: NA | BZ13: NA | CA13: NA | CB13: NA | CC13: NA | CD13: NA | CE13: NA | CF13: NA | CG13: NA | CH13: NA | CI13: NA | CJ13: NA | CK13: NA | CL13: NA | CM13: NA | CN13: NA | CO13: 3 | CP13: 3 | CQ13: some | CR13: some | CS13: all | CT13: all | CU13: some | CV13: some | CW13: some | CX13: some | CY13: some | CZ13: some | DA13: some | DB13: some | DC13: NS | DD13: NS | DE13: NS | DF13: NS | DG13: NS | DH13: NS | DI13: some | DJ13: some | DK13: NS | DL13: NS | DM13: NS | DN13: NS | DO13: NS | DP13: NS | DQ13: NS | DR13: NS | DS13: NS | DT13: NS | DU13: NS | DV13: NS | DW13: NS | DX13: NS | DY13: 1 | DZ13: 1 | EA13: 1 | EB13: 1 | EC13: 1 | ED13: 1 | EE13: 1 | EF13: 1 | EG13: 1 | EH13: 1 | EI13: 1 | EJ13: 1 | EK13: 1 | EL13: 1 | EM13: 1 | EN13: 1 | EO13: 1 | EP13: 1 | EQ13: 1 | ER13: 1 | ES13: =SUM(DY13,EA13,EC13,EE13,EG13,EI13,EK13,EM13,EO13,EQ13) -> 10 | ET13: =SUM(DZ13,EB13,ED13,EF13,EH13,EJ13,EL13,EN13,EP13,ER13) -> 10 | EU13: Harris | EV13: 2019 | EW13: =IF(C13=D13,"Y","N") -> Y | EX13: =IF(E13=F13,"Y","N") -> Y | EY13: =IF(G13=H13,"Y","N") -> Y | EZ13: =IF(I13=J13,"Y","N") -> Y | FA13: =IF(K13=L13,"Y","N") -> Y | FB13: =IF(M13=N13,"Y","N") -> Y | FC13: =IF(O13=P13,"Y","N") -> Y | FD13: =IF(Q13=R13,"Y","N") -> Y | FE13: =IF(S13=T13,"Y","N") -> Y | FF13: =IF(U13=V13,"Y","N") -> Y | FG13: =IF(W13=X13,"Y","N") -> Y | FH13: =IF(Y13=Z13,"Y","N") -> Y | FI13: =IF(AA13=AB13,"Y","N") -> Y | FJ13: =IF(AD13=AE13,"Y","N") -> Y | FK13: =IF(AG13=AH13,"Y","N") -> Y | FL13: =IF(AI13=AJ13,"Y","N") -> Y | FM13: =IF(AM13=AN13,"Y","N") -> Y | FN13: =IF(AO13=AP13,"Y","N") -> Y | FO13: =IF(AQ13=AR13,"Y","N") -> Y | FP13: =IF(AY13=AZ13,"Y","N") -> Y | FQ13: =IF(BA13=BB13,"Y","N") -> Y | FR13: =IF(BC13=BD13,"Y","N") -> Y | FS13: =IF(BE13=BF13,"Y","N") -> Y | FT13: =IF(BG13=BH13,"Y","N") -> Y | FU13: =IF(BI13=BJ13,"Y","N") -> Y | FV13: =IF(BK13=BL13,"Y","N") -> Y | FW13: =IF(BM13=BN13,"Y","N") -> Y | FX13: =IF(BO13=BP13,"Y","N") -> Y | FY13: =IF(BQ13=BR13,"Y","N") -> Y | FZ13: =IF(BS13=BT13,"Y","N") -> Y | GA13: =IF(BU13=BV13,"Y","N") -> Y | GB13: =IF(BW13=BX13,"Y","N") -> Y | GC13: =IF(BY13=BZ13,"Y","N") -> Y | GD13: =IF(CA13=CB13,"Y","N") -> Y | GE13: =IF(CC13=CD13,"Y","N") -> Y | GF13: =IF(CE13=CF13,"Y","N") -> Y | GG13: =IF(CG13=CH13, "Y", "N") -> Y | GH13: =IF(CI13=CJ13, "Y", "N") -> Y | GI13: =IF(CK13=CL13,"Y","N") -> Y | GJ13: =IF(CM13=CN13,"Y","N") -> Y | GK13: =IF(CO13=CP13,"Y","N") -> Y | GL13: =IF(CQ13=CR13,"Y","N") -> Y | GM13: =IF(CS13=CT13,"Y","N") -> Y | GN13: =IF(CU13=CV13,"Y","N") -> Y | GO13: =IF(CW13=CX13,"Y","N") -> Y | GP13: =IF(CY13=CZ13,"Y","N") -> Y | GQ13: =IF(DA13=DB13,"Y","N") -> Y | GR13: =IF(DC13=DD13,"Y","N") -> Y | GS13: =IF(DE13=DF13,"Y","N") -> Y | GT13: =IF(DG13=DH13,"Y","N") -> Y | GU13: =IF(DI13=DJ13,"Y","N") -> Y | GV13: =IF(DK13=DL13,"Y","N") -> Y | GW13: =IF(DM13=DN13,"Y","N") -> Y | GX13: =IF(DO13=DP13,"Y","N") -> Y | GY13: =IF(DQ13=DR13,"Y","N") -> Y | GZ13: =IF(DY13=DZ13,"Y","N") -> Y | HA13: =IF(EA13=EB13,"Y","N") -> Y | HB13: =IF(EC13=ED13,"Y","N") -> Y | HC13: =IF(EE13=EF13,"Y","N") -> Y | HD13: =IF(EG13=EH13,"Y","N") -> Y | HE13: =IF(EI13=EJ13,"Y","N") -> Y | HF13: =IF(EK13=EL13,"Y","N") -> Y | HG13: =IF(EM13=EN13,"Y","N") -> Y | HH13: =IF(EO13=EP13,"Y","N") -> Y | HI13: =IF(EQ13=ER13,"Y","N") -> Y | HJ13: =IF(ES13=ET13,"Y","N") -> Y
A14: Johnstone | B14: 1987 | C14: NS | D14: NS | E14: NS | F14: NS | G14: NS | H14: NS | I14: NS | J14: NS | K14: NS | L14: NS | M14: NS | N14: NS | O14: NS | P14: NS | Q14: NS | R14: NS | S14: NS | T14: NS | U14: 0 | V14: 0 | W14: 268 | X14: 268 | Y14: 0 | Z14: 0 | AA14: 0 | AB14: 0 | AC14: inpat_psych | AD14: UK | AE14: UK | AF14: euro | AG14: no | AH14: no | AI14: yes | AJ14: yes | AK14: yes | AL14: yes | AM14: 268 | AN14: 268 | AO14: 0 | AP14: 0 | AQ14: 0 | AR14: 0 | AS14: NS | AT14: NS | AU14: NS | AV14: NS | AW14: NS | AX14: NS | AY14: 268 | AZ14: 268 | BA14: 15 | BB14: 15 | BC14: multiple | BD14: multiple | BE14: =SUM(BI14,BK14,BQ14,BS14,BU14,BW14,BY14,CA14,CC14,CE14,CG14,CI14,CK14,CM14,CO14) -> 10 | BF14: =SUM(BJ14,BL14,BR14,BT14,BV14,BX14,BZ14,CB14,CD14,CF14,CH14,CJ14,CL14,CN14,CP14) -> 10 | BG14: =SUM(BM14,BO14) -> 5 | BH14: =SUM(BN14,BP14) -> 5 | BI14: 0 | BJ14: 0 | BK14: 0 | BL14: 0 | BM14: 5 | BN14: 5 | BO14: 0 | BP14: 0 | BQ14: 0 | BR14: 0 | BS14: 0 | BT14: 0 | BU14: 0 | BV14: 0 | BW14: 0 | BX14: 0 | BY14: 4 | BZ14: 4 | CA14: 0 | CB14: 0 | CC14: 0 | CD14: 0 | CE14: 0 | CF14: 0 | CG14: 0 | CH14: 0 | CI14: 0 | CJ14: 0 | CK14: 1 | CL14: 1 | CM14: 5 | CN14: 5 | CO14: 0 | CP14: 0 | CQ14: NS | CR14: NS | CS14: some | CT14: some | CU14: 0 | CV14: 0 | CW14: some | CX14: some | CY14: some | CZ14: some | DA14: some | DB14: some | DC14: 0 | DD14: 0 | DE14: all | DF14: all | DG14: NS | DH14: NS | DI14: some | DJ14: some | DK14: some | DL14: some | DM14: NS | DN14: NS | DO14: X-ray (Unspecified freq) | DP14: X-ray (Unspecified freq) | DQ14: NS | DR14: NS | DS14: disorder | DT14: disorder | DU14: NS | DV14: NS | DW14: NS | DX14: NS | DY14: 1 | DZ14: 1 | EA14: 1 | EB14: 1 | EC14: 1 | ED14: 1 | EE14: 1 | EF14: 1 | EG14: 1 | EH14: 1 | EI14: 1 | EJ14: 1 | EK14: 1 | EL14: 1 | EM14: 0 | EN14: 0 | EO14: 1 | EP14: 1 | EQ14: 1 | ER14: 1 | ES14: =SUM(DY14,EA14,EC14,EE14,EG14,EI14,EK14,EM14,EO14,EQ14) -> 9 | ET14: =SUM(DZ14,EB14,ED14,EF14,EH14,EJ14,EL14,EN14,EP14,ER14) -> 9 | EU14: Johnstone | EV14: 1987 | EW14: =IF(C14=D14,"Y","N") -> Y | EX14: =IF(E14=F14,"Y","N") -> Y | EY14: =IF(G14=H14,"Y","N") -> Y | EZ14: =IF(I14=J14,"Y","N") -> Y | FA14: =IF(K14=L14,"Y","N") -> Y | FB14: =IF(M14=N14,"Y","N") -> Y | FC14: =IF(O14=P14,"Y","N") -> Y | FD14: =IF(Q14=R14,"Y","N") -> Y | FE14: =IF(S14=T14,"Y","N") -> Y | FF14: =IF(U14=V14,"Y","N") -> Y | FG14: =IF(W14=X14,"Y","N") -> Y | FH14: =IF(Y14=Z14,"Y","N") -> Y | FI14: =IF(AA14=AB14,"Y","N") -> Y | FJ14: =IF(AD14=AE14,"Y","N") -> Y | FK14: =IF(AG14=AH14,"Y","N") -> Y | FL14: =IF(AI14=AJ14,"Y","N") -> Y | FM14: =IF(AM14=AN14,"Y","N") -> Y | FN14: =IF(AO14=AP14,"Y","N") -> Y | FO14: =IF(AQ14=AR14,"Y","N") -> Y | FP14: =IF(AY14=AZ14,"Y","N") -> Y | FQ14: =IF(BA14=BB14,"Y","N") -> Y | FR14: =IF(BC14=BD14,"Y","N") -> Y | FS14: =IF(BE14=BF14,"Y","N") -> Y | FT14: =IF(BG14=BH14,"Y","N") -> Y | FU14: =IF(BI14=BJ14,"Y","N") -> Y | FV14: =IF(BK14=BL14,"Y","N") -> Y | FW14: =IF(BM14=BN14,"Y","N") -> Y | FX14: =IF(BO14=BP14,"Y","N") -> Y | FY14: =IF(BQ14=BR14,"Y","N") -> Y | FZ14: =IF(BS14=BT14,"Y","N") -> Y | GA14: =IF(BU14=BV14,"Y","N") -> Y | GB14: =IF(BW14=BX14,"Y","N") -> Y | GC14: =IF(BY14=BZ14,"Y","N") -> Y | GD14: =IF(CA14=CB14,"Y","N") -> Y | GE14: =IF(CC14=CD14,"Y","N") -> Y | GF14: =IF(CE14=CF14,"Y","N") -> Y | GG14: =IF(CG14=CH14, "Y", "N") -> Y | GH14: =IF(CI14=CJ14, "Y", "N") -> Y | GI14: =IF(CK14=CL14,"Y","N") -> Y | GJ14: =IF(CM14=CN14,"Y","N") -> Y | GK14: =IF(CO14=CP14,"Y","N") -> Y | GL14: =IF(CQ14=CR14,"Y","N") -> Y | GM14: =IF(CS14=CT14,"Y","N") -> Y | GN14: =IF(CU14=CV14,"Y","N") -> Y | GO14: =IF(CW14=CX14,"Y","N") -> Y | GP14: =IF(CY14=CZ14,"Y","N") -> Y | GQ14: =IF(DA14=DB14,"Y","N") -> Y | GR14: =IF(DC14=DD14,"Y","N") -> Y | GS14: =IF(DE14=DF14,"Y","N") -> Y | GT14: =IF(DG14=DH14,"Y","N") -> Y | GU14: =IF(DI14=DJ14,"Y","N") -> Y | GV14: =IF(DK14=DL14,"Y","N") -> Y | GW14: =IF(DM14=DN14,"Y","N") -> Y | GX14: =IF(DO14=DP14,"Y","N") -> Y | GY14: =IF(DQ14=DR14,"Y","N") -> Y | GZ14: =IF(DY14=DZ14,"Y","N") -> Y | HA14: =IF(EA14=EB14,"Y","N") -> Y | HB14: =IF(EC14=ED14,"Y","N") -> Y | HC14: =IF(EE14=EF14,"Y","N") -> Y | HD14: =IF(EG14=EH14,"Y","N") -> Y | HE14: =IF(EI14=EJ14,"Y","N") -> Y | HF14: =IF(EK14=EL14,"Y","N") -> Y | HG14: =IF(EM14=EN14,"Y","N") -> Y | HH14: =IF(EO14=EP14,"Y","N") -> Y | HI14: =IF(EQ14=ER14,"Y","N") -> Y | HJ14: =IF(ES14=ET14,"Y","N") -> Y
A15: Kanbayashi | B15: 2012 | C15: NS | D15: NS | E15: NS | F15: NS | G15: NS | H15: NS | I15: 30.6 | J15: 30.6 | K15: NS | L15: NS | M15: NS | N15: NS | O15: NS | P15: NS | Q15: NS | R15: NS | S15: NS | T15: NS | U15: 0 | V15: 0 | W15: 51 | X15: 51 | Y15: 0 | Z15: 0 | AA15: 0 | AB15: 0 | AC15: inpat_psych | AD15: Japan | AE15: Japan | AF15: asia | AG15: no | AH15: no | AI15: yes | AJ15: yes | AK15: no | AL15: no | AM15: NS | AN15: NS | AO15: NS | AP15: NS | AQ15: NS | AR15: NS | AS15: NS | AT15: NS | AU15: NS | AV15: NS | AW15: NS | AX15: NS | AY15: 51 | AZ15: 51 | BA15: 4 | BB15: 4 | BC15: single | BD15: single | BE15: =SUM(BI15,BK15,BQ15,BS15,BU15,BW15,BY15,CA15,CC15,CE15,CG15,CI15,CK15,CM15,CO15) -> 4 | BF15: =SUM(BJ15,BL15,BR15,BT15,BV15,BX15,BZ15,CB15,CD15,CF15,CH15,CJ15,CL15,CN15,CP15) -> 4 | BG15: =SUM(BM15,BO15) -> 0 | BH15: =SUM(BN15,BP15) -> 0 | BI15: 4 | BJ15: 4 | BK15: NA | BL15: NA | BM15: NA | BN15: NA | BO15: NA | BP15: NA | BQ15: NA | BR15: NA | BS15: NA | BT15: NA | BU15: NA | BV15: NA | BW15: NA | BX15: NA | BY15: NA | BZ15: NA | CA15: NA | CB15: NA | CC15: NA | CD15: NA | CE15: NA | CF15: NA | CG15: NA | CH15: NA | CI15: NA | CJ15: NA | CK15: NA | CL15: NA | CM15: NA | CN15: NA | CO15: NA | CP15: NA | CQ15: yes - NS | CR15: yes - NS | CS15: NS | CT15: NS | CU15: NS | CV15: NS | CW15: yes - NS | CX15: yes - NS | CY15: some | CZ15: some | DA15: yes - NS | DB15: yes - NS | DC15: NS | DD15: NS | DE15: NS | DF15: NS | DG15: NS | DH15: NS | DI15: NS | DJ15: NS | DK15: NS | DL15: NS | DM15: NS | DN15: NS | DO15: NS | DP15: NS | DQ15: NS | DR15: NS | DS15: disorder | DT15: disorder | DU15: NS | DV15: NS | DW15: DSM-IV | DX15: DSM-IV | DY15: 1 | DZ15: 1 | EA15: 1 | EB15: 1 | EC15: 1 | ED15: 1 | EE15: 1 | EF15: 1 | EG15: 1 | EH15: 1 | EI15: 1 | EJ15: 1 | EK15: 1 | EL15: 1 | EM15: 1 | EN15: 1 | EO15: 1 | EP15: 1 | EQ15: 1 | ER15: 1 | ES15: =SUM(DY15,EA15,EC15,EE15,EG15,EI15,EK15,EM15,EO15,EQ15) -> 10 | ET15: =SUM(DZ15,EB15,ED15,EF15,EH15,EJ15,EL15,EN15,EP15,ER15) -> 10 | EU15: Kanbayashi | EV15: 2012 | EW15: =IF(C15=D15,"Y","N") -> Y | EX15: =IF(E15=F15,"Y","N") -> Y | EY15: =IF(G15=H15,"Y","N") -> Y | EZ15: =IF(I15=J15,"Y","N") -> Y | FA15: =IF(K15=L15,"Y","N") -> Y | FB15: =IF(M15=N15,"Y","N") -> Y | FC15: =IF(O15=P15,"Y","N") -> Y | FD15: =IF(Q15=R15,"Y","N") -> Y | FE15: =IF(S15=T15,"Y","N") -> Y | FF15: =IF(U15=V15,"Y","N") -> Y | FG15: =IF(W15=X15,"Y","N") -> Y | FH15: =IF(Y15=Z15,"Y","N") -> Y | FI15: =IF(AA15=AB15,"Y","N") -> Y | FJ15: =IF(AD15=AE15,"Y","N") -> Y | FK15: =IF(AG15=AH15,"Y","N") -> Y | FL15: =IF(AI15=AJ15,"Y","N") -> Y | FM15: =IF(AM15=AN15,"Y","N") -> Y | FN15: =IF(AO15=AP15,"Y","N") -> Y | FO15: =IF(AQ15=AR15,"Y","N") -> Y | FP15: =IF(AY15=AZ15,"Y","N") -> Y | FQ15: =IF(BA15=BB15,"Y","N") -> Y | FR15: =IF(BC15=BD15,"Y","N") -> Y | FS15: =IF(BE15=BF15,"Y","N") -> Y | FT15: =IF(BG15=BH15,"Y","N") -> Y | FU15: =IF(BI15=BJ15,"Y","N") -> Y | FV15: =IF(BK15=BL15,"Y","N") -> Y | FW15: =IF(BM15=BN15,"Y","N") -> Y | FX15: =IF(BO15=BP15,"Y","N") -> Y | FY15: =IF(BQ15=BR15,"Y","N") -> Y | FZ15: =IF(BS15=BT15,"Y","N") -> Y | GA15: =IF(BU15=BV15,"Y","N") -> Y | GB15: =IF(BW15=BX15,"Y","N") -> Y | GC15: =IF(BY15=BZ15,"Y","N") -> Y | GD15: =IF(CA15=CB15,"Y","N") -> Y | GE15: =IF(CC15=CD15,"Y","N") -> Y | GF15: =IF(CE15=CF15,"Y","N") -> Y | GG15: =IF(CG15=CH15, "Y", "N") -> Y | GH15: =IF(CI15=CJ15, "Y", "N") -> Y | GI15: =IF(CK15=CL15,"Y","N") -> Y | GJ15: =IF(CM15=CN15,"Y","N") -> Y | GK15: =IF(CO15=CP15,"Y","N") -> Y | GL15: =IF(CQ15=CR15,"Y","N") -> Y | GM15: =IF(CS15=CT15,"Y","N") -> Y | GN15: =IF(CU15=CV15,"Y","N") -> Y | GO15: =IF(CW15=CX15,"Y","N") -> Y | GP15: =IF(CY15=CZ15,"Y","N") -> Y | GQ15: =IF(DA15=DB15,"Y","N") -> Y | GR15: =IF(DC15=DD15,"Y","N") -> Y | GS15: =IF(DE15=DF15,"Y","N") -> Y | GT15: =IF(DG15=DH15,"Y","N") -> Y | GU15: =IF(DI15=DJ15,"Y","N") -> Y | GV15: =IF(DK15=DL15,"Y","N") -> Y | GW15: =IF(DM15=DN15,"Y","N") -> Y | GX15: =IF(DO15=DP15,"Y","N") -> Y | GY15: =IF(DQ15=DR15,"Y","N") -> Y | GZ15: =IF(DY15=DZ15,"Y","N") -> Y | HA15: =IF(EA15=EB15,"Y","N") -> Y | HB15: =IF(EC15=ED15,"Y","N") -> Y | HC15: =IF(EE15=EF15,"Y","N") -> Y | HD15: =IF(EG15=EH15,"Y","N") -> Y | HE15: =IF(EI15=EJ15,"Y","N") -> Y | HF15: =IF(EK15=EL15,"Y","N") -> Y | HG15: =IF(EM15=EN15,"Y","N") -> Y | HH15: =IF(EO15=EP15,"Y","N") -> Y | HI15: =IF(EQ15=ER15,"Y","N") -> Y | HJ15: =IF(ES15=ET15,"Y","N") -> Y
