Workbook

Sheet Sheet1
A1: First Author | B1: Date | C1: Gender (Male) | E1: Gender (Female) | G1: Mean Age (Primary) | I1: Mean Age (Secondary) | K1: Mean Age (Total) | M1: Ethnicity (Black) | O1: Ethnicity (White) | Q1: Ethnicity (Asian) | S1: Ethnicity (Other) | U1: Accident and Emergency / Urgent Care | W1: Inpatient Psychiatric Service | Y1: Outpatient Psychiatric Service | AA1: GP /non-Urgent Physical Care | AC1: setting | AD1: Country | AF1: Continant | AG1: Retrospective | AI1: Prospective | AK1: FEP Only | AM1: First Episode Cohort | AO1: Chronic Psychosis Cohort | AQ1: Mixed Cohort | AS1: DUP (all psychosis) | AU1: DUP (primary) | AW1: DUP (secondary) | AY1: Total Sample Size | BA1: Total Secondary Causes | BC1: Probable or Definite Secondary cause | BD1: Definite Secondary cause | BE1: Probable Secondary cause | BF1: Possible Secondary cause | BG1: Was the study looking at multiple causes? | BI1: Endogenous | BK1: Exogenous | BM1: Autoimmune Disorders | BO1: Cytogenic / Congenital | BQ1: Toxic / Substance-Induced | BS1: Iatrogenic | BU1: Cerebrovascular | BW1: Space-Occupying | BY1: Metabolic | CA1: Dietary | CC1: Sepsis / Infectious | CE1: Degenerative | CG1: Demyelinating | CI1: Seizure | CK1: Sleep Disorders | CM1: Head Injury | CO1: Endocrine | CQ1: Other | CS1: Unknown | CU1: MRI (freq) | CW1: CT (freq) | CY1: SPECT/PET (freq) | DA1: EEG (freq) | DC1: CSF (freq) | DE1: Blood (freq) | DG1: Urine (freq) | DI1: Psychiatric Assessment (freq) | DK1: Psychiatric Assessment Standardised Tool (y/n) | DM1: Physical Exam (including neurological, vital signs) (freq) | DO1: Cognitive Assessment (freq) | DQ1: Cognitive Assessment-standardised tool | DS1: Other (add detail) | DU1: NS | DW1: Diagnosis | DY1: Diagnostic Tool | EA1: Classification System | EC1: Item 1 | EE1: Item 2 | EG1: Item 3 | EI1: Item 4 | EK1: Item 5 | EM1: Item 6 | EO1: Item 7 | EQ1: Item 8 | ES1: Item 9 | EU1: Item 10 | EW1: Overall Score | EY1: First Author | EZ1: Date | FA1: Gender (Male) | FB1: Gender (Female) | FC1: Mean Age (Primary) | FD1: Mean Age (Secondary) | FE1: Mean Age (Total) | FF1: Ethnicity (Black) | FG1: Ethnicity (White) | FH1: Ethnicity (Asian) | FI1: Ethnicity (Other) | FJ1: Accident and Emergency / Urgent Care | FK1: Inpatient Psychiatric Service | FL1: Outpatient Psychiatric Service | FM1: GP /non-Urgent Physical Care | FN1: Geographic Location | FO1: Retrospective | FP1: Prospective | FQ1: First Episode Cohort | FR1: Chronic Psychosis Cohort | FS1: Mixed Cohort | FT1: Total Sample Size | FU1: Total Secondary Causes | FV1: Was the study looking at multiple causes? | FW1: Endogenous | FX1: Exogenous | FY1: Autoimmune Disorders | FZ1: Cytogenic / Congenital | GA1: Toxic / Substance-Induced | GB1: Iatrogenic | GC1: Cerebrovascular | GD1: Space-Occupying | GE1: Metabolic | GF1: Dietary | GG1: Sepsis / Infectious | GH1: Degenerative | GI1: Demyelinating | GJ1: Seizure | GK1: Sleep Disorder | GL1: Head Injury | GM1: Endocrine | GN1: Other | GO1: Unknown | GP1: MRI (freq) | GQ1: CT (freq) | GR1: SPECT/PET (freq) | GS1: EEG (freq) | GT1: CSF (freq) | GU1: Blood (freq) | GV1: Urine (freq) | GW1: Psychiatric Assessment (freq) | GX1: Psychiatric Assessment Standardised Tool (y/n) | GY1: Physical Exam (including neurological, vital signs) (freq) | GZ1: Cognitive Assessment (freq) | HA1: Cognitive Assessment-standardised tool | HB1: Other (add detail) | HC1: NS | HD1: Item 1 | HE1: Item 2 | HF1: Item 3 | HG1: Item 4 | HH1: Item 5 | HI1: Item 6 | HJ1: Item 7 | HK1: Item 8 | HL1: Item 9 | HM1: Item 10 | HN1: Overall Score | HO1: Comments - endogenous causesnot reported at most granual level | HP1: includes endogenous noS as "other"/"unknown"
C2: Rater 1 | D2: Rater 2 | E2: Rater 1 | F2: Rater 2 | G2: Rater 1 | H2: Rater 2 | I2: Rater 1 | J2: Rater 2 | K2: Rater 1 | L2: Rater 2 | M2: Rater 1 | N2: Rater 2 | O2: Rater 1 | P2: Rater 2 | Q2: Rater 1 | R2: Rater 2 | S2: Rater 1 | T2: Rater 2 | U2: Rater 1 | V2: Rater 2 | W2: Rater 1 | X2: Rater 2 | Y2: Rater 1 | Z2: Rater 2 | AA2: Rater 1 | AB2: Rater 2 | AD2: Rater 1 | AE2: Rater 2 | AG2: Rater 1 | AH2: Rater 2 | AI2: Rater 1 | AJ2: Rater 2 | AK2: Rater 1 | AL2: Rater 2 | AM2: Rater 1 | AN2: Rater 2 | AO2: Rater 1 | AP2: Rater 2 | AQ2: Rater 1 | AR2: Rater 2 | AS2: Rater 1 | AT2: Rater 2 | AU2: Rater 1 | AV2: Rater 2 | AW2: Rater 1 | AX2: Rater 2 | AY2: Rater 1 | AZ2: Rater 2 | BA2: Rater 1 | BB2: Rater 2 | BG2: Rater 1 | BH2: Rater 2 | BI2: Rater 1 | BJ2: Rater 2 | BK2: Rater 1 | BL2: Rater 2 | BM2: Rater 1 | BN2: Rater 2 | BO2: Rater 1 | BP2: Rater 2 | BQ2: Rater 1 | BR2: Rater 2 | BS2: Rater 1 | BT2: Rater 2 | BU2: Rater 1 | BV2: Rater 2 | BW2: Rater 1 | BX2: Rater 2 | BY2: Rater 1 | BZ2: Rater 2 | CA2: Rater 1 | CB2: Rater 2 | CC2: Rater 1 | CD2: Rater 2 | CE2: Rater 1 | CF2: Rater 2 | CG2: Rater 1 | CH2: Rater 2 | CI2: Rater 1 | CJ2: Rater 2 | CK2: Rater 1 | CL2: Rater 2 | CM2: Rater 1 | CN2: Rater 2 | CO2: Rater 1 | CP2: Rater 2 | CQ2: Rater 1 | CR2: Rater 2 | CS2: Rater 1 | CT2: Rater 2 | CU2: Rater 1 | CV2: Rater 2 | CW2: Rater 1 | CX2: Rater 2 | CY2: Rater 1 | CZ2: Rater 2 | DA2: Rater 1 | DB2: Rater 2 | DC2: Rater 1 | DD2: Rater 2 | DE2: Rater 1 | DF2: Rater 2 | DG2: Rater 1 | DH2: Rater 2 | DI2: Rater 1 | DJ2: Rater 2 | DK2: Rater 1 | DL2: Rater 2 | DM2: Rater 1 | DN2: Rater 2 | DO2: Rater 1 | DP2: Rater 2 | DQ2: Rater 1 | DR2: Rater 2 | DS2: Rater 1 | DT2: Rater 2 | DU2: Rater 1 | DV2: Rater 2 | DW2: Rater 1 | DX2: Rater 2 | DY2: Rater 1 | DZ2: Rater 2 | EA2: Rater 1 | EB2: Rater 2 | EC2: Rater 1 | ED2: Rater 2 | EE2: Rater 1 | EF2: Rater 2 | EG2: Rater 1 | EH2: Rater 2 | EI2: Rater 1 | EJ2: Rater 2 | EK2: Rater 1 | EL2: Rater 2 | EM2: Rater 1 | EN2: Rater 2 | EO2: Rater 1 | EP2: Rater 2 | EQ2: Rater 1 | ER2: Rater 2 | ES2: Rater 1 | ET2: Rater 2 | EU2: Rater 1 | EV2: Rater 2 | EW2: Rater 1 | EX2: Rater 2
A3: Adams | B3: 1996 | C3: 68 | D3: 68 | E3: 43 | F3: 43 | G3: NS | H3: NS | I3: NS | J3: NS | K3: NS | L3: NS | M3: NS | N3: NS | O3: NS | P3: NS | Q3: NS | R3: NS | S3: NS | T3: NS | U3: 0 | V3: 0 | W3: 111 | X3: 111 | Y3: 0 | Z3: 0 | AA3: 0 | AB3: 0 | AC3: inpat_psych | AD3: Canada | AE3: Canada | AF3: n_am | AG3: no | AH3: no | AI3: yes | AJ3: yes | AK3: yes | AL3: yes | AM3: 111 | AN3: 111 | AO3: 0 | AP3: 0 | AQ3: 0 | AR3: 0 | AS3: NS | AT3: NS | AU3: NS | AV3: NS | AW3: NS | AX3: NS | AY3: 111 | AZ3: 111 | BA3: 0 | BB3: 0 | BC3: =BD3+BE3 -> 0 | BD3: 0 | BE3: 0 | BF3: 0 | BG3: multiple | BH3: multiple | BI3: 0 | BJ3: 0 | BK3: 0 | BL3: 0 | BM3: NA | BN3: NA | BO3: NA | BP3: NA | BQ3: NA | BR3: NA | BS3: NA | BT3: NA | BU3: 0 | BV3: 0 | BW3: 0 | BX3: 0 | BY3: 0 | BZ3: 0 | CA3: 0 | CB3: 0 | CC3: NA | CD3: NA | CE3: 0 | CF3: 0 | CG3: 0 | CH3: 0 | CI3: NA | CJ3: NA | CK3: NA | CL3: NA | CM3: 0 | CN3: 0 | CO3: 0 | CP3: 0 | CQ3: NA | CR3: NA | CS3: NA | CT3: NA | CU3: NS | CV3: NS | CW3: some | CX3: some | CY3: some | CZ3: some | DA3: some | DB3: some | DC3: NS | DD3: NS | DE3: all | DF3: all | DG3: NS | DH3: NS | DI3: all | DJ3: all | DK3: NS | DL3: NS | DM3: NS | DN3: NS | DO3: NS | DP3: NS | DQ3: NS | DR3: NS | DS3: NS | DT3: NS | DU3: NS | DV3: NS | DW3: Psychotic Disorder | DX3: Psychotic Disorder | DY3: NS | DZ3: NS | EA3: NS | EB3: NS | EC3: 1 | ED3: 1 | EE3: 1 | EF3: 1 | EG3: 1 | EH3: 1 | EI3: 1 | EJ3: 1 | EK3: 1 | EL3: 1 | EM3: 1 | EN3: 1 | EO3: 1 | EP3: 1 | EQ3: 1 | ER3: 1 | ES3: 1 | ET3: 1 | EU3: 1 | EV3: 1 | EW3: =SUM(EC3,EE3,EG3,EI3,EK3,EM3,EO3,EQ3,ES3,EU3) -> 10 | EX3: =SUM(ED3,EF3,EH3,EJ3,EL3,EN3,EP3,ER3,ET3,EV3) -> 10 | EY3: =A3 -> Adams | EZ3: =B3 -> 1996 | FA3: =IF(C3=D3,"Y","N") -> Y | FB3: =IF(E3=F3,"Y","N") -> Y | FC3: =IF(G3=H3,"Y","N") -> Y | FD3: =IF(I3=J3,"Y","N") -> Y | FE3: =IF(K3=L3,"Y","N") -> Y | FF3: =IF(M3=N3,"Y","N") -> Y | FG3: =IF(O3=P3,"Y","N") -> Y | FH3: =IF(Q3=R3,"Y","N") -> Y | FI3: =IF(S3=T3,"Y","N") -> Y | FJ3: =IF(U3=V3,"Y","N") -> Y | FK3: =IF(W3=X3,"Y","N") -> Y | FL3: =IF(Y3=Z3,"Y","N") -> Y | FM3: =IF(AA3=AB3,"Y","N") -> Y | FN3: =IF(AD3=AE3,"Y","N") -> Y | FO3: =IF(AG3=AH3,"Y","N") -> Y | FP3: =IF(AI3=AJ3,"Y","N") -> Y | FQ3: =IF(AM3=AN3,"Y","N") -> Y | FR3: =IF(AO3=AP3,"Y","N") -> Y | FS3: =IF(AQ3=AR3,"Y","N") -> Y | FT3: =IF(AY3=AZ3,"Y","N") -> Y | FU3: =IF(BA3=BB3,"Y","N") -> Y | FV3: =IF(BG3=BH3,"Y","N") -> Y | FW3: =IF(BI3=BJ3,"Y","N") -> Y | FX3: =IF(BK3=BL3,"Y","N") -> Y | FY3: =IF(BM3=BN3,"Y","N") -> Y | FZ3: =IF(BO3=BP3,"Y","N") -> Y | GA3: =IF(BQ3=BR3,"Y","N") -> Y | GB3: =IF(BS3=BT3,"Y","N") -> Y | GC3: =IF(BU3=BV3,"Y","N") -> Y | GD3: =IF(BW3=BX3,"Y","N") -> Y | GE3: =IF(BY3=BZ3,"Y","N") -> Y | GF3: =IF(CA3=CB3,"Y","N") -> Y | GG3: =IF(CC3=CD3,"Y","N") -> Y | GH3: =IF(CE3=CF3,"Y","N") -> Y | GI3: =IF(CG3=CH3,"Y","N") -> Y | GJ3: =IF(CI3=CJ3,"Y","N") -> Y | GK3: =IF(CK3=CL3, "Y", "N") -> Y | GL3: =IF(CM3=CN3, "Y", "N") -> Y | GM3: =IF(CO3=CP3,"Y","N") -> Y | GN3: =IF(CQ3=CR3,"Y","N") -> Y | GO3: =IF(CS3=CT3,"Y","N") -> Y | GP3: =IF(CU3=CV3,"Y","N") -> Y | GQ3: =IF(CW3=CX3,"Y","N") -> Y | GR3: =IF(CY3=CZ3,"Y","N") -> Y | GS3: =IF(DA3=DB3,"Y","N") -> Y | GT3: =IF(DC3=DD3,"Y","N") -> Y | GU3: =IF(DE3=DF3,"Y","N") -> Y | GV3: =IF(DG3=DH3,"Y","N") -> Y | GW3: =IF(DI3=DJ3,"Y","N") -> Y | GX3: =IF(DK3=DL3,"Y","N") -> Y | GY3: =IF(DM3=DN3,"Y","N") -> Y | GZ3: =IF(DO3=DP3,"Y","N") -> Y | HA3: =IF(DQ3=DR3,"Y","N") -> Y | HB3: =IF(DS3=DT3,"Y","N") -> Y | HC3: =IF(DU3=DV3,"Y","N") -> Y | HD3: =IF(EC3=ED3,"Y","N") -> Y | HE3: =IF(EE3=EF3,"Y","N") -> Y | HF3: =IF(EG3=EH3,"Y","N") -> Y | HG3: =IF(EI3=EJ3,"Y","N") -> Y | HH3: =IF(EK3=EL3,"Y","N") -> Y | HI3: =IF(EM3=EN3,"Y","N") -> Y | HJ3: =IF(EO3=EP3,"Y","N") -> Y | HK3: =IF(EQ3=ER3,"Y","N") -> Y | HL3: =IF(ES3=ET3,"Y","N") -> Y | HM3: =IF(EU3=EV3,"Y","N") -> Y | HN3: =IF(EW3=EX3,"Y","N") -> Y
A4: Bechter | B4: 2010 | C4: 21 | D4: 21 | E4: 18 | F4: 18 | G4: NS | H4: NS | I4: NS | J4: NS | K4: 33.2 | L4: 33.2 | M4: NS | N4: NS | O4: NS | P4: NS | Q4: NS | R4: NS | S4: NS | T4: NS | U4: 0 | V4: 0 | W4: 39 | X4: 39 | Y4: 0 | Z4: 0 | AA4: 0 | AB4: 0 | AC4: inpat_psych | AD4: Germany | AE4: Germany | AF4: euro | AG4: no | AH4: no | AI4: yes | AJ4: yes | AK4: no | AL4: no | AM4: NS | AN4: NS | AO4: 39 | AP4: 39 | AQ4: NS | AR4: NS | AS4: NS | AT4: NS | AU4: NS | AV4: NS | AW4: NS | AX4: NS | AY4: 39 | AZ4: 39 | BA4: 2 | BB4: 2 | BC4: =BD4+BE4 -> 1 | BD4: 1 | BE4: 0 | BF4: 1 | BG4: multiple | BH4: multiple | BI4: 1 | BJ4: 1 | BK4: NA | BL4: NA | BM4: 1 | BN4: 1 | BO4: NA | BP4: NA | BQ4: NA | BR4: NA | BS4: NA | BT4: NA | BU4: 0 | BV4: 0 | BW4: 0 | BX4: 0 | BY4: NA | BZ4: NA | CA4: NA | CB4: NA | CC4: NA | CD4: NA | CE4: 0 | CF4: 0 | CG4: 0 | CH4: 0 | CI4: NA | CJ4: NA | CK4: NA | CL4: NA | CM4: 0 | CN4: 0 | CO4: NA | CP4: NA | CQ4: NA | CR4: NA | CS4: NA | CT4: NA | CU4: some | CV4: some | CW4: some | CX4: some | CY4: NS | CZ4: NS | DA4: some | DB4: some | DC4: all | DD4: all | DE4: all | DF4: all | DG4: NS | DH4: NS | DI4: all | DJ4: all | DK4: yes | DL4: yes | DM4: some | DN4: some | DO4: NS | DP4: NS | DQ4: NS | DR4: NS | DS4: NS | DT4: NS | DU4: NS | DV4: NS | DW4: Psychotic Disorder | DX4: Psychitoic Disorder | DY4: NS | DZ4: NS | EA4: ICD-10 | EB4: ICD-10 | EC4: 0 | ED4: 0 | EE4: 1 | EF4: 1 | EG4: 1 | EH4: 1 | EI4: 1 | EJ4: 1 | EK4: 1 | EL4: 1 | EM4: 1 | EN4: 1 | EO4: 1 | EP4: 1 | EQ4: 1 | ER4: 1 | ES4: 1 | ET4: 1 | EU4: 1 | EV4: 1 | EW4: =SUM(EC4,EE4,EG4,EI4,EK4,EM4,EO4,EQ4,ES4,EU4) -> 9 | EX4: =SUM(ED4,EF4,EH4,EJ4,EL4,EN4,EP4,ER4,ET4,EV4) -> 9 | EY4: =A4 -> Bechter | EZ4: =B4 -> 2010 | FA4: =IF(C4=D4,"Y","N") -> Y | FB4: =IF(E4=F4,"Y","N") -> Y | FC4: =IF(G4=H4,"Y","N") -> Y | FD4: =IF(I4=J4,"Y","N") -> Y | FE4: =IF(K4=L4,"Y","N") -> Y | FF4: =IF(M4=N4,"Y","N") -> Y | FG4: =IF(O4=P4,"Y","N") -> Y | FH4: =IF(Q4=R4,"Y","N") -> Y | FI4: =IF(S4=T4,"Y","N") -> Y | FJ4: =IF(U4=V4,"Y","N") -> Y | FK4: =IF(W4=X4,"Y","N") -> Y | FL4: =IF(Y4=Z4,"Y","N") -> Y | FM4: =IF(AA4=AB4,"Y","N") -> Y | FN4: =IF(AD4=AE4,"Y","N") -> Y | FO4: =IF(AG4=AH4,"Y","N") -> Y | FP4: =IF(AI4=AJ4,"Y","N") -> Y | FQ4: =IF(AM4=AN4,"Y","N") -> Y | FR4: =IF(AO4=AP4,"Y","N") -> Y | FS4: =IF(AQ4=AR4,"Y","N") -> Y | FT4: =IF(AY4=AZ4,"Y","N") -> Y | FU4: =IF(BA4=BB4,"Y","N") -> Y | FV4: =IF(BG4=BH4,"Y","N") -> Y | FW4: =IF(BI4=BJ4,"Y","N") -> Y | FX4: =IF(BK4=BL4,"Y","N") -> Y | FY4: =IF(BM4=BN4,"Y","N") -> Y | FZ4: =IF(BO4=BP4,"Y","N") -> Y | GA4: =IF(BQ4=BR4,"Y","N") -> Y | GB4: =IF(BS4=BT4,"Y","N") -> Y | GC4: =IF(BU4=BV4,"Y","N") -> Y | GD4: =IF(BW4=BX4,"Y","N") -> Y | GE4: =IF(BY4=BZ4,"Y","N") -> Y | GF4: =IF(CA4=CB4,"Y","N") -> Y | GG4: =IF(CC4=CD4,"Y","N") -> Y | GH4: =IF(CE4=CF4,"Y","N") -> Y | GI4: =IF(CG4=CH4,"Y","N") -> Y | GJ4: =IF(CI4=CJ4,"Y","N") -> Y | GK4: =IF(CK4=CL4, "Y", "N") -> Y | GL4: =IF(CM4=CN4, "Y", "N") -> Y | GM4: =IF(CO4=CP4,"Y","N") -> Y | GN4: =IF(CQ4=CR4,"Y","N") -> Y | GO4: =IF(CS4=CT4,"Y","N") -> Y | GP4: =IF(CU4=CV4,"Y","N") -> Y | GQ4: =IF(CW4=CX4,"Y","N") -> Y | GR4: =IF(CY4=CZ4,"Y","N") -> Y | GS4: =IF(DA4=DB4,"Y","N") -> Y | GT4: =IF(DC4=DD4,"Y","N") -> Y | GU4: =IF(DE4=DF4,"Y","N") -> Y | GV4: =IF(DG4=DH4,"Y","N") -> Y | GW4: =IF(DI4=DJ4,"Y","N") -> Y | GX4: =IF(DK4=DL4,"Y","N") -> Y | GY4: =IF(DM4=DN4,"Y","N") -> Y | GZ4: =IF(DO4=DP4,"Y","N") -> Y | HA4: =IF(DQ4=DR4,"Y","N") -> Y | HB4: =IF(DS4=DT4,"Y","N") -> Y | HC4: =IF(DU4=DV4,"Y","N") -> Y | HD4: =IF(EC4=ED4,"Y","N") -> Y | HE4: =IF(EE4=EF4,"Y","N") -> Y | HF4: =IF(EG4=EH4,"Y","N") -> Y | HG4: =IF(EI4=EJ4,"Y","N") -> Y | HH4: =IF(EK4=EL4,"Y","N") -> Y | HI4: =IF(EM4=EN4,"Y","N") -> Y | HJ4: =IF(EO4=EP4,"Y","N") -> Y | HK4: =IF(EQ4=ER4,"Y","N") -> Y | HL4: =IF(ES4=ET4,"Y","N") -> Y | HM4: =IF(EU4=EV4,"Y","N") -> Y | HN4: =IF(EW4=EX4,"Y","N") -> Y
A5: Caton | B5: 2005 | C5: 278 | D5: 278 | E5: 108 | F5: 108 | G5: 27.1 | H5: 27.1 | I5: 30.1 | J5: 30.1 | K5: 28.5 | L5: 28.5 | M5: 168 | N5: 168 | O5: 56 | P5: 56 | Q5: 0 | R5: 0 | S5: 0 | T5: 0 | U5: 386 | V5: 386 | W5: 0 | X5: 0 | Y5: 0 | Z5: 0 | AA5: 0 | AB5: 0 | AC5: gen_hospital | AD5: USA | AE5: USA | AF5: n_am | AG5: no | AH5: no | AI5: yes | AJ5: yes | AK5: yes | AL5: yes | AM5: NS | AN5: NS | AO5: NS | AP5: NS | AQ5: NS | AR5: NS | AS5: NS | AT5: NS | AU5: NS | AV5: NS | AW5: NS | AX5: NS | AY5: 386 | AZ5: 386 | BA5: 169 | BB5: 169 | BC5: =BD5+BE5 -> 169 | BD5: 169 | BE5: 0 | BF5: 0 | BG5: single | BH5: single | BI5: NA | BJ5: NA | BK5: 169 | BL5: =SUM(BR5,BT5) -> 169 | BM5: NA | BN5: NA | BO5: NA | BP5: NA | BQ5: 169 | BR5: 169 | BS5: NA | BT5: NA | BU5: NA | BV5: NA | BW5: NA | BX5: NA | BY5: NA | BZ5: NA | CA5: NA | CB5: NA | CC5: NA | CD5: NA | CE5: NA | CF5: NA | CG5: NA | CH5: NA | CI5: NA | CJ5: NA | CK5: NA | CL5: NA | CM5: NA | CN5: NA | CO5: NA | CP5: NA | CQ5: NA | CR5: NA | CS5: NA | CT5: NA | CU5: NS | CV5: NS | CW5: NS | CX5: NS | CY5: NS | CZ5: NS | DA5: NS | DB5: NS | DC5: NS | DD5: NS | DE5: NS | DF5: NS | DG5: all | DH5: all | DI5: all | DJ5: all | DK5: yes | DL5: yes | DM5: NS | DN5: NS | DO5: NS | DP5: NS | DQ5: NS | DR5: NS | DS5: NS | DT5: NS | DU5: NS | DV5: NS | DW5: Psychotic Disorder | DX5: Psychotic Disorder | DY5: PRISM | DZ5: PRISM | EA5: DSM-IV | EB5: DSM-IV | EC5: 1 | ED5: 1 | EE5: 0 | EF5: 0 | EG5: 1 | EH5: 1 | EI5: 1 | EJ5: 1 | EK5: 1 | EL5: 1 | EM5: 1 | EN5: 1 | EO5: 1 | EP5: 1 | EQ5: 1 | ER5: 1 | ES5: 1 | ET5: 1 | EU5: 1 | EV5: 1 | EW5: =SUM(EC5,EE5,EG5,EI5,EK5,EM5,EO5,EQ5,ES5,EU5) -> 9 | EX5: =SUM(ED5,EF5,EH5,EJ5,EL5,EN5,EP5,ER5,ET5,EV5) -> 9 | EY5: =A5 -> Caton | EZ5: =B5 -> 2005 | FA5: =IF(C5=D5,"Y","N") -> Y | FB5: =IF(E5=F5,"Y","N") -> Y | FC5: =IF(G5=H5,"Y","N") -> Y | FD5: =IF(I5=J5,"Y","N") -> Y | FE5: =IF(K5=L5,"Y","N") -> Y | FF5: =IF(M5=N5,"Y","N") -> Y | FG5: =IF(O5=P5,"Y","N") -> Y | FH5: =IF(Q5=R5,"Y","N") -> Y | FI5: =IF(S5=T5,"Y","N") -> Y | FJ5: =IF(U5=V5,"Y","N") -> Y | FK5: =IF(W5=X5,"Y","N") -> Y | FL5: =IF(Y5=Z5,"Y","N") -> Y | FM5: =IF(AA5=AB5,"Y","N") -> Y | FN5: =IF(AD5=AE5,"Y","N") -> Y | FO5: =IF(AG5=AH5,"Y","N") -> Y | FP5: =IF(AI5=AJ5,"Y","N") -> Y | FQ5: =IF(AM5=AN5,"Y","N") -> Y | FR5: =IF(AO5=AP5,"Y","N") -> Y | FS5: =IF(AQ5=AR5,"Y","N") -> Y | FT5: =IF(AY5=AZ5,"Y","N") -> Y | FU5: =IF(BA5=BB5,"Y","N") -> Y | FV5: =IF(BG5=BH5,"Y","N") -> Y | FW5: =IF(BI5=BJ5,"Y","N") -> Y | FX5: =IF(BK5=BL5,"Y","N") -> Y | FY5: =IF(BM5=BN5,"Y","N") -> Y | FZ5: =IF(BO5=BP5,"Y","N") -> Y | GA5: =IF(BQ5=BR5,"Y","N") -> Y | GB5: =IF(BS5=BT5,"Y","N") -> Y | GC5: =IF(BU5=BV5,"Y","N") -> Y | GD5: =IF(BW5=BX5,"Y","N") -> Y | GE5: =IF(BY5=BZ5,"Y","N") -> Y | GF5: =IF(CA5=CB5,"Y","N") -> Y | GG5: =IF(CC5=CD5,"Y","N") -> Y | GH5: =IF(CE5=CF5,"Y","N") -> Y | GI5: =IF(CG5=CH5,"Y","N") -> Y | GJ5: =IF(CI5=CJ5,"Y","N") -> Y | GK5: =IF(CK5=CL5, "Y", "N") -> Y | GL5: =IF(CM5=CN5, "Y", "N") -> Y | GM5: =IF(CO5=CP5,"Y","N") -> Y | GN5: =IF(CQ5=CR5,"Y","N") -> Y | GO5: =IF(CS5=CT5,"Y","N") -> Y | GP5: =IF(CU5=CV5,"Y","N") -> Y | GQ5: =IF(CW5=CX5,"Y","N") -> Y | GR5: =IF(CY5=CZ5,"Y","N") -> Y | GS5: =IF(DA5=DB5,"Y","N") -> Y | GT5: =IF(DC5=DD5,"Y","N") -> Y | GU5: =IF(DE5=DF5,"Y","N") -> Y | GV5: =IF(DG5=DH5,"Y","N") -> Y | GW5: =IF(DI5=DJ5,"Y","N") -> Y | GX5: =IF(DK5=DL5,"Y","N") -> Y | GY5: =IF(DM5=DN5,"Y","N") -> Y | GZ5: =IF(DO5=DP5,"Y","N") -> Y | HA5: =IF(DQ5=DR5,"Y","N") -> Y | HB5: =IF(DS5=DT5,"Y","N") -> Y | HC5: =IF(DU5=DV5,"Y","N") -> Y | HD5: =IF(EC5=ED5,"Y","N") -> Y | HE5: =IF(EE5=EF5,"Y","N") -> Y | HF5: =IF(EG5=EH5,"Y","N") -> Y | HG5: =IF(EI5=EJ5,"Y","N") -> Y | HH5: =IF(EK5=EL5,"Y","N") -> Y | HI5: =IF(EM5=EN5,"Y","N") -> Y | HJ5: =IF(EO5=EP5,"Y","N") -> Y | HK5: =IF(EQ5=ER5,"Y","N") -> Y | HL5: =IF(ES5=ET5,"Y","N") -> Y | HM5: =IF(EU5=EV5,"Y","N") -> Y | HN5: =IF(EW5=EX5,"Y","N") -> Y
A6: Correa-Oliveira | B6: 2022 | C6: 152 | D6: 152 | E6: 85 | F6: 85 | G6: NS | H6: NS | I6: NS | J6: NS | K6: 23.5 | L6: 23.5 | M6: NS | N6: NS | O6: 153 | P6: 153 | Q6: NS | R6: NS | S6: 64 | T6: 64 | U6: 0 | V6: 0 | W6: 0 | X6: 0 | Y6: 237 | Z6: 237 | AA6: 0 | AB6: 0 | AC6: outpat_psych | AD6: Brazil | AE6: Brazil | AF6: s_am | AG6: yes | AH6: yes | AI6: no | AJ6: no | AK6: yes | AL6: yes | AM6: 237 | AN6: 237 | AO6: 0 | AP6: 0 | AQ6: 0 | AR6: 0 | AS6: NS | AT6: NS | AU6: NS | AV6: NS | AW6: NS | AX6: NS | AY6: 237 | AZ6: 237 | BA6: 84 | BB6: 84 | BC6: =BD6+BE6 -> 84 | BD6: 84 | BE6: 0 | BF6: 0 | BG6: multiple | BH6: multiple | BI6: 23 | BJ6: 23 | BK6: 61 | BL6: =SUM(BR6,BT6) -> 61 | BM6: NA | BN6: NA | BO6: NA | BP6: NA | BQ6: 61 | BR6: 61 | BS6: NA | BT6: NA | BU6: NA | BV6: NA | BW6: NA | BX6: NA | BY6: NA | BZ6: NA | CA6: NA | CB6: NA | CC6: NA | CD6: NA | CE6: NA | CF6: NA | CG6: NA | CH6: NA | CI6: NA | CJ6: NA | CK6: NA | CL6: NA | CM6: NA | CN6: NA | CO6: NA | CP6: NA | CQ6: NA | CR6: NA | CS6: 23 | CT6: 23 | CU6: NS | CV6: NS | CW6: all | CX6: all | CY6: all | CZ6: all | DA6: NS | DB6: NS | DC6: NS | DD6: NS | DE6: all | DF6: all | DG6: all | DH6: all | DI6: all | DJ6: all | DK6: yes | DL6: yes | DM6: all | DN6: all | DO6: NS | DP6: NS | DQ6: NS | DR6: NS | DS6: NS | DT6: NS | DU6: NS | DV6: NS | DW6: Psychotic Disorder | DX6: Psychotic Disorder | DY6: SCID | DZ6: SCID | EA6: DSM-5 | EB6: DSM-IV | EC6: 1 | ED6: 1 | EE6: 1 | EF6: 1 | EG6: 1 | EH6: 1 | EI6: 1 | EJ6: 1 | EK6: 1 | EL6: 1 | EM6: 1 | EN6: 1 | EO6: 1 | EP6: 1 | EQ6: 1 | ER6: 1 | ES6: 1 | ET6: 1 | EU6: 1 | EV6: 1 | EW6: =SUM(EC6,EE6,EG6,EI6,EK6,EM6,EO6,EQ6,ES6,EU6) -> 10 | EX6: =SUM(ED6,EF6,EH6,EJ6,EL6,EN6,EP6,ER6,ET6,EV6) -> 10 | EY6: =A6 -> Correa-Oliveira | EZ6: =B6 -> 2022 | FA6: =IF(C6=D6,"Y","N") -> Y | FB6: =IF(E6=F6,"Y","N") -> Y | FC6: =IF(G6=H6,"Y","N") -> Y | FD6: =IF(I6=J6,"Y","N") -> Y | FE6: =IF(K6=L6,"Y","N") -> Y | FF6: =IF(M6=N6,"Y","N") -> Y | FG6: =IF(O6=P6,"Y","N") -> Y | FH6: =IF(Q6=R6,"Y","N") -> Y | FI6: =IF(S6=T6,"Y","N") -> Y | FJ6: =IF(U6=V6,"Y","N") -> Y | FK6: =IF(W6=X6,"Y","N") -> Y | FL6: =IF(Y6=Z6,"Y","N") -> Y | FM6: =IF(AA6=AB6,"Y","N") -> Y | FN6: =IF(AD6=AE6,"Y","N") -> Y | FO6: =IF(AG6=AH6,"Y","N") -> Y | FP6: =IF(AI6=AJ6,"Y","N") -> Y | FQ6: =IF(AM6=AN6,"Y","N") -> Y | FR6: =IF(AO6=AP6,"Y","N") -> Y | FS6: =IF(AQ6=AR6,"Y","N") -> Y | FT6: =IF(AY6=AZ6,"Y","N") -> Y | FU6: =IF(BA6=BB6,"Y","N") -> Y | FV6: =IF(BG6=BH6,"Y","N") -> Y | FW6: =IF(BI6=BJ6,"Y","N") -> Y | FX6: =IF(BK6=BL6,"Y","N") -> Y | FY6: =IF(BM6=BN6,"Y","N") -> Y | FZ6: =IF(BO6=BP6,"Y","N") -> Y | GA6: =IF(BQ6=BR6,"Y","N") -> Y | GB6: =IF(BS6=BT6,"Y","N") -> Y | GC6: =IF(BU6=BV6,"Y","N") -> Y | GD6: =IF(BW6=BX6,"Y","N") -> Y | GE6: =IF(BY6=BZ6,"Y","N") -> Y | GF6: =IF(CA6=CB6,"Y","N") -> Y | GG6: =IF(CC6=CD6,"Y","N") -> Y | GH6: =IF(CE6=CF6,"Y","N") -> Y | GI6: =IF(CG6=CH6,"Y","N") -> Y | GJ6: =IF(CI6=CJ6,"Y","N") -> Y | GK6: =IF(CK6=CL6, "Y", "N") -> Y | GL6: =IF(CM6=CN6, "Y", "N") -> Y | GM6: =IF(CO6=CP6,"Y","N") -> Y | GN6: =IF(CQ6=CR6,"Y","N") -> Y | GO6: =IF(CS6=CT6,"Y","N") -> Y | GP6: =IF(CU6=CV6,"Y","N") -> Y | GQ6: =IF(CW6=CX6,"Y","N") -> Y | GR6: =IF(CY6=CZ6,"Y","N") -> Y | GS6: =IF(DA6=DB6,"Y","N") -> Y | GT6: =IF(DC6=DD6,"Y","N") -> Y | GU6: =IF(DE6=DF6,"Y","N") -> Y | GV6: =IF(DG6=DH6,"Y","N") -> Y | GW6: =IF(DI6=DJ6,"Y","N") -> Y | GX6: =IF(DK6=DL6,"Y","N") -> Y | GY6: =IF(DM6=DN6,"Y","N") -> Y | GZ6: =IF(DO6=DP6,"Y","N") -> Y | HA6: =IF(DQ6=DR6,"Y","N") -> Y | HB6: =IF(DS6=DT6,"Y","N") -> Y | HC6: =IF(DU6=DV6,"Y","N") -> Y | HD6: =IF(EC6=ED6,"Y","N") -> Y | HE6: =IF(EE6=EF6,"Y","N") -> Y | HF6: =IF(EG6=EH6,"Y","N") -> Y | HG6: =IF(EI6=EJ6,"Y","N") -> Y | HH6: =IF(EK6=EL6,"Y","N") -> Y | HI6: =IF(EM6=EN6,"Y","N") -> Y | HJ6: =IF(EO6=EP6,"Y","N") -> Y | HK6: =IF(EQ6=ER6,"Y","N") -> Y | HL6: =IF(ES6=ET6,"Y","N") -> Y | HM6: =IF(EU6=EV6,"Y","N") -> Y | HN6: =IF(EW6=EX6,"Y","N") -> Y | HO6: 1 | HP6: 1
A7: Drake | B7: 2011 | C7: 152 | D7: 152 | E7: 99 | F7: 99 | G7: 27.2 | H7: 27.2 | I7: 30.4 | J7: 30.4 | K7: NS | L7: NS | M7: 156 | N7: 156 | O7: 52 | P7: 52 | Q7: 0 | R7: 0 | S7: 147 | T7: 147 | U7: 351 | V7: 351 | W7: 0 | X7: 0 | Y7: 0 | Z7: 0 | AA7: 0 | AB7: 0 | AC7: gen_hospital | AD7: USA | AE7: USA | AF7: n_am | AG7: no | AH7: no | AI7: yes | AJ7: yes | AK7: yes | AL7: yes | AM7: 351 | AN7: 351 | AO7: 0 | AP7: 0 | AQ7: 0 | AR7: 0 | AS7: NS | AT7: NS | AU7: NS | AV7: NS | AW7: NS | AX7: NS | AY7: 351 | AZ7: 351 | BA7: 134 | BB7: 134 | BC7: =BD7+BE7 -> 134 | BD7: 134 | BE7: 0 | BF7: 0 | BG7: single | BH7: single | BI7: NA | BJ7: NA | BK7: 134 | BL7: =SUM(BR7,BT7) -> 134 | BM7: NA | BN7: NA | BO7: NA | BP7: NA | BQ7: 134 | BR7: 134 | BS7: NA | BT7: NA | BU7: NA | BV7: NA | BW7: NA | BX7: NA | BY7: NA | BZ7: NA | CA7: NA | CB7: NA | CC7: NA | CD7: NA | CE7: NA | CF7: NA | CG7: NA | CH7: NA | CI7: NA | CJ7: NA | CK7: NA | CL7: NA | CM7: NA | CN7: NA | CO7: NA | CP7: NA | CQ7: NA | CR7: NA | CS7: NA | CT7: NA | CU7: NS | CV7: NS | CW7: NS | CX7: NS | CY7: NS | CZ7: NS | DA7: NS | DB7: NS | DC7: NS | DD7: NS | DE7: NS | DF7: NS | DG7: all | DH7: all | DI7: all | DJ7: all | DK7: yes | DL7: yes | DM7: NS | DN7: NS | DO7: NS | DP7: NS | DQ7: NS | DR7: NS | DS7: NS | DT7: NS | DU7: NS | DV7: NS | DW7: Psychotic Disorder | DX7: Psychotic Disorder | DY7: PRISM | DZ7: PRISM | EA7: DSM-IV | EB7: DSM-IV | EC7: 1 | ED7: 1 | EE7: 0 | EF7: 0 | EG7: 1 | EH7: 1 | EI7: 1 | EJ7: 1 | EK7: 1 | EL7: 1 | EM7: 1 | EN7: 1 | EO7: 1 | EP7: 1 | EQ7: 1 | ER7: 1 | ES7: 1 | ET7: 1 | EU7: 1 | EV7: 1 | EW7: =SUM(EC7,EE7,EG7,EI7,EK7,EM7,EO7,EQ7,ES7,EU7) -> 9 | EX7: =SUM(ED7,EF7,EH7,EJ7,EL7,EN7,EP7,ER7,ET7,EV7) -> 9 | EY7: =A7 -> Drake | EZ7: =B7 -> 2011 | FA7: =IF(C7=D7,"Y","N") -> Y | FB7: =IF(E7=F7,"Y","N") -> Y | FC7: =IF(G7=H7,"Y","N") -> Y | FD7: =IF(I7=J7,"Y","N") -> Y | FE7: =IF(K7=L7,"Y","N") -> Y | FF7: =IF(M7=N7,"Y","N") -> Y | FG7: =IF(O7=P7,"Y","N") -> Y | FH7: =IF(Q7=R7,"Y","N") -> Y | FI7: =IF(S7=T7,"Y","N") -> Y | FJ7: =IF(U7=V7,"Y","N") -> Y | FK7: =IF(W7=X7,"Y","N") -> Y | FL7: =IF(Y7=Z7,"Y","N") -> Y | FM7: =IF(AA7=AB7,"Y","N") -> Y | FN7: =IF(AD7=AE7,"Y","N") -> Y | FO7: =IF(AG7=AH7,"Y","N") -> Y | FP7: =IF(AI7=AJ7,"Y","N") -> Y | FQ7: =IF(AM7=AN7,"Y","N") -> Y | FR7: =IF(AO7=AP7,"Y","N") -> Y | FS7: =IF(AQ7=AR7,"Y","N") -> Y | FT7: =IF(AY7=AZ7,"Y","N") -> Y | FU7: =IF(BA7=BB7,"Y","N") -> Y | FV7: =IF(BG7=BH7,"Y","N") -> Y | FW7: =IF(BI7=BJ7,"Y","N") -> Y | FX7: =IF(BK7=BL7,"Y","N") -> Y | FY7: =IF(BM7=BN7,"Y","N") -> Y | FZ7: =IF(BO7=BP7,"Y","N") -> Y | GA7: =IF(BQ7=BR7,"Y","N") -> Y | GB7: =IF(BS7=BT7,"Y","N") -> Y | GC7: =IF(BU7=BV7,"Y","N") -> Y | GD7: =IF(BW7=BX7,"Y","N") -> Y | GE7: =IF(BY7=BZ7,"Y","N") -> Y | GF7: =IF(CA7=CB7,"Y","N") -> Y | GG7: =IF(CC7=CD7,"Y","N") -> Y | GH7: =IF(CE7=CF7,"Y","N") -> Y | GI7: =IF(CG7=CH7,"Y","N") -> Y | GJ7: =IF(CI7=CJ7,"Y","N") -> Y | GK7: =IF(CK7=CL7, "Y", "N") -> Y | GL7: =IF(CM7=CN7, "Y", "N") -> Y | GM7: =IF(CO7=CP7,"Y","N") -> Y | GN7: =IF(CQ7=CR7,"Y","N") -> Y | GO7: =IF(CS7=CT7,"Y","N") -> Y | GP7: =IF(CU7=CV7,"Y","N") -> Y | GQ7: =IF(CW7=CX7,"Y","N") -> Y | GR7: =IF(CY7=CZ7,"Y","N") -> Y | GS7: =IF(DA7=DB7,"Y","N") -> Y | GT7: =IF(DC7=DD7,"Y","N") -> Y | GU7: =IF(DE7=DF7,"Y","N") -> Y | GV7: =IF(DG7=DH7,"Y","N") -> Y | GW7: =IF(DI7=DJ7,"Y","N") -> Y | GX7: =IF(DK7=DL7,"Y","N") -> Y | GY7: =IF(DM7=DN7,"Y","N") -> Y | GZ7: =IF(DO7=DP7,"Y","N") -> Y | HA7: =IF(DQ7=DR7,"Y","N") -> Y | HB7: =IF(DS7=DT7,"Y","N") -> Y | HC7: =IF(DU7=DV7,"Y","N") -> Y | HD7: =IF(EC7=ED7,"Y","N") -> Y | HE7: =IF(EE7=EF7,"Y","N") -> Y | HF7: =IF(EG7=EH7,"Y","N") -> Y | HG7: =IF(EI7=EJ7,"Y","N") -> Y | HH7: =IF(EK7=EL7,"Y","N") -> Y | HI7: =IF(EM7=EN7,"Y","N") -> Y | HJ7: =IF(EO7=EP7,"Y","N") -> Y | HK7: =IF(EQ7=ER7,"Y","N") -> Y | HL7: =IF(ES7=ET7,"Y","N") -> Y | HM7: =IF(EU7=EV7,"Y","N") -> Y | HN7: =IF(EW7=EX7,"Y","N") -> Y
A8: Endres | B8: 2020 | C8: 32 | D8: 32 | E8: 44 | F8: 44 | G8: NS | H8: NS | I8: NS | J8: NS | K8: 37.22 | L8: 37.22 | M8: NS | N8: NS | O8: NS | P8: NS | Q8: NS | R8: NS | S8: NS | T8: NS | U8: 0 | V8: 0 | W8: 76 | X8: 76 | Y8: 0 | Z8: 0 | AA8: 0 | AB8: 0 | AC8: inpat_psych | AD8: Germany | AE8: Germany | AF8: euro | AG8: yes | AH8: yes | AI8: no | AJ8: no | AK8: no | AL8: no | AM8: 15 | AN8: 15 | AO8: 61 | AP8: 61 | AQ8: 0 | AR8: 0 | AS8: NS | AT8: NS | AU8: NS | AV8: NS | AW8: NS | AX8: NS | AY8: 76 | AZ8: 76 | BA8: 4 | BB8: 4 | BC8: 3 | BD8: 1 | BE8: 2 | BF8: 1 | BG8: multiple | BH8: multiple | BI8: 2 | BJ8: 2 | BK8: =BQ8+BS8 -> 1 | BL8: 1 | BM8: 2 | BN8: 2 | BO8: 0 | BP8: 0 | BQ8: 1 | BR8: 1 | BS8: 0 | BT8: 0 | BU8: 0 | BV8: 0 | BW8: 0 | BX8: 0 | BY8: 0 | BZ8: 0 | CA8: 0 | CB8: 0 | CC8: 0 | CD8: 0 | CE8: 0 | CF8: 0 | CG8: 0 | CH8: 0 | CI8: 0 | CJ8: 0 | CK8: 0 | CL8: 0 | CM8: 0 | CN8: 0 | CO8: 0 | CP8: 0 | CQ8: 0 | CR8: 0 | CS8: 0 | CT8: 0 | CU8: all | CV8: all | CW8: NS | CX8: NS | CY8: NS | CZ8: NS | DA8: all | DB8: all | DC8: all | DD8: all | DE8: all | DF8: all | DG8: all | DH8: all | DI8: all | DJ8: all | DK8: NS | DL8: NS | DM8: NS | DN8: NS | DO8: NS | DP8: NS | DQ8: NS | DR8: NS | DS8: NS | DT8: NS | DU8: NS | DV8: NS | DW8: Psychotic Disorder | DX8: Psychotic Disorder | DY8: NS | DZ8: NS | EA8: ICD-10 | EB8: ICD-10 | EC8: 1 | ED8: 1 | EE8: 1 | EF8: 1 | EG8: 1 | EH8: 1 | EI8: 1 | EJ8: 1 | EK8: 1 | EL8: 1 | EM8: 1 | EN8: 1 | EO8: 1 | EP8: 1 | EQ8: 1 | ER8: 1 | ES8: 1 | ET8: 1 | EU8: 1 | EV8: 1 | EW8: =SUM(EC8,EE8,EG8,EI8,EK8,EM8,EO8,EQ8,ES8,EU8) -> 10 | EX8: =SUM(ED8,EF8,EH8,EJ8,EL8,EN8,EP8,ER8,ET8,EV8) -> 10 | EY8: =A8 -> Endres | EZ8: =B8 -> 2020 | FA8: =IF(C8=D8,"Y","N") -> Y | FB8: =IF(E8=F8,"Y","N") -> Y | FC8: =IF(G8=H8,"Y","N") -> Y | FD8: =IF(I8=J8,"Y","N") -> Y | FE8: =IF(K8=L8,"Y","N") -> Y | FF8: =IF(M8=N8,"Y","N") -> Y | FG8: =IF(O8=P8,"Y","N") -> Y | FH8: =IF(Q8=R8,"Y","N") -> Y | FI8: =IF(S8=T8,"Y","N") -> Y | FJ8: =IF(U8=V8,"Y","N") -> Y | FK8: =IF(W8=X8,"Y","N") -> Y | FL8: =IF(Y8=Z8,"Y","N") -> Y | FM8: =IF(AA8=AB8,"Y","N") -> Y | FN8: =IF(AD8=AE8,"Y","N") -> Y | FO8: =IF(AG8=AH8,"Y","N") -> Y | FP8: =IF(AI8=AJ8,"Y","N") -> Y | FQ8: =IF(AM8=AN8,"Y","N") -> Y | FR8: =IF(AO8=AP8,"Y","N") -> Y | FS8: =IF(AQ8=AR8,"Y","N") -> Y | FT8: =IF(AY8=AZ8,"Y","N") -> Y | FU8: =IF(BA8=BB8,"Y","N") -> Y | FV8: =IF(BG8=BH8,"Y","N") -> Y | FW8: =IF(BI8=BJ8,"Y","N") -> Y | FX8: =IF(BK8=BL8,"Y","N") -> Y | FY8: =IF(BM8=BN8,"Y","N") -> Y | FZ8: =IF(BO8=BP8,"Y","N") -> Y | GA8: =IF(BQ8=BR8,"Y","N") -> Y | GB8: =IF(BS8=BT8,"Y","N") -> Y | GC8: =IF(BU8=BV8,"Y","N") -> Y | GD8: =IF(BW8=BX8,"Y","N") -> Y | GE8: =IF(BY8=BZ8,"Y","N") -> Y | GF8: =IF(CA8=CB8,"Y","N") -> Y | GG8: =IF(CC8=CD8,"Y","N") -> Y | GH8: =IF(CE8=CF8,"Y","N") -> Y | GI8: =IF(CG8=CH8,"Y","N") -> Y | GJ8: =IF(CI8=CJ8,"Y","N") -> Y | GK8: =IF(CK8=CL8, "Y", "N") -> Y | GL8: =IF(CM8=CN8, "Y", "N") -> Y | GM8: =IF(CO8=CP8,"Y","N") -> Y | GN8: =IF(CQ8=CR8,"Y","N") -> Y | GO8: =IF(CS8=CT8,"Y","N") -> Y | GP8: =IF(CU8=CV8,"Y","N") -> Y | GQ8: =IF(CW8=CX8,"Y","N") -> Y | GR8: =IF(CY8=CZ8,"Y","N") -> Y | GS8: =IF(DA8=DB8,"Y","N") -> Y | GT8: =IF(DC8=DD8,"Y","N") -> Y | GU8: =IF(DE8=DF8,"Y","N") -> Y | GV8: =IF(DG8=DH8,"Y","N") -> Y | GW8: =IF(DI8=DJ8,"Y","N") -> Y | GX8: =IF(DK8=DL8,"Y","N") -> Y | GY8: =IF(DM8=DN8,"Y","N") -> Y | GZ8: =IF(DO8=DP8,"Y","N") -> Y | HA8: =IF(DQ8=DR8,"Y","N") -> Y | HB8: =IF(DS8=DT8,"Y","N") -> Y | HC8: =IF(DU8=DV8,"Y","N") -> Y | HD8: =IF(EC8=ED8,"Y","N") -> Y | HE8: =IF(EE8=EF8,"Y","N") -> Y | HF8: =IF(EG8=EH8,"Y","N") -> Y | HG8: =IF(EI8=EJ8,"Y","N") -> Y | HH8: =IF(EK8=EL8,"Y","N") -> Y | HI8: =IF(EM8=EN8,"Y","N") -> Y | HJ8: =IF(EO8=EP8,"Y","N") -> Y | HK8: =IF(EQ8=ER8,"Y","N") -> Y | HL8: =IF(ES8=ET8,"Y","N") -> Y | HM8: =IF(EU8=EV8,"Y","N") -> Y | HN8: =IF(EW8=EX8,"Y","N") -> Y
A9: Etlouba | B9: 2018 | C9: 95 | D9: 95 | E9: 64 | F9: 64 | G9: 28.7 | H9: 28.7 | I9: 36.7 | J9: 36.7 | K9: 34.3 | L9: 34.3 | M9: 142 | N9: 142 | O9: 5 | P9: 5 | Q9: 7 | R9: 7 | S9: 5 | T9: 5 | U9: 159 | V9: 159 | W9: 0 | X9: 0 | Y9: 0 | Z9: 0 | AA9: 0 | AB9: 0 | AC9: gen_hospital | AD9: South Africa | AE9: South Africa | AF9: afri | AG9: yes | AH9: yes | AI9: no | AJ9: no | AK9: yes | AL9: yes | AM9: 159 | AN9: 159 | AO9: 0 | AP9: 0 | AQ9: 0 | AR9: 0 | AS9: 16.6 | AT9: 16.6 | AU9: 37.8 | AV9: NS | AX9: NS | AY9: 159 | AZ9: 159 | BA9: 124 | BB9: 124 | BC9: =BD9+BE9 -> 124 | BD9: 123 | BE9: 1 | BF9: 0 | BG9: multiple | BH9: multiple | BI9: 87 | BJ9: =SUM(BN9,BP9,BV9,BX9,BZ9,CB9,CD9,CF9,CH9,CJ9,CP9,CR9) -> 87 | BK9: =BQ9+BS9 -> 37 | BL9: =SUM(BR9,BT9) -> 37 | BM9: 0 | BN9: 0 | BO9: 0 | BP9: 0 | BQ9: 37 | BR9: 37 | BS9: 0 | BT9: 0 | BU9: 2 | BV9: 2 | BW9: 0 | BX9: 0 | BY9: 4 | BZ9: 4 | CA9: 0 | CB9: 0 | CC9: 75 | CD9: 75 | CE9: 0 | CF9: 0 | CG9: 0 | CH9: 0 | CI9: 3 | CJ9: 3 | CK9: 0 | CL9: 0 | CM9: 0 | CN9: 0 | CO9: 2 | CP9: 2 | CQ9: 1 | CR9: 1 | CS9: 0 | CT9: 0 | CU9: NS | CV9: NS | CW9: yes - NS | CX9: yes - NS | CY9: yes - NS | CZ9: yes - NS | DA9: NS | DB9: NS | DC9: yes - NS | DD9: yes - NS | DE9: yes - NS | DF9: yes - NS | DG9: yes - NS | DH9: yes - NS | DI9: all | DJ9: all | DK9: NS | DL9: NS | DM9: all | DN9: all | DO9: NS | DP9: NS | DQ9: NS | DR9: NS | DS9: yes - NS | DT9: yes - NS | DU9: NS | DV9: NS | DW9: Psychotic Symptoms | DX9: Psychotic symptoms | DY9: NS | DZ9: NS | EA9: NS | EB9: NS | EC9: 1 | ED9: 1 | EE9: 1 | EF9: 1 | EG9: 1 | EH9: 1 | EI9: 1 | EJ9: 1 | EK9: 1 | EL9: 1 | EM9: 1 | EN9: 1 | EO9: 1 | EP9: 1 | EQ9: 1 | ER9: 1 | ES9: 1 | ET9: 1 | EU9: 1 | EV9: 1 | EW9: =SUM(EC9,EE9,EG9,EI9,EK9,EM9,EO9,EQ9,ES9,EU9) -> 10 | EX9: =SUM(ED9,EF9,EH9,EJ9,EL9,EN9,EP9,ER9,ET9,EV9) -> 10 | EY9: =A9 -> Etlouba | EZ9: =B9 -> 2018 | FA9: =IF(C9=D9,"Y","N") -> Y | FB9: =IF(E9=F9,"Y","N") -> Y | FC9: =IF(G9=H9,"Y","N") -> Y | FD9: =IF(I9=J9,"Y","N") -> Y | FE9: =IF(K9=L9,"Y","N") -> Y | FF9: =IF(M9=N9,"Y","N") -> Y | FG9: =IF(O9=P9,"Y","N") -> Y | FH9: =IF(Q9=R9,"Y","N") -> Y | FI9: =IF(S9=T9,"Y","N") -> Y | FJ9: =IF(U9=V9,"Y","N") -> Y | FK9: =IF(W9=X9,"Y","N") -> Y | FL9: =IF(Y9=Z9,"Y","N") -> Y | FM9: =IF(AA9=AB9,"Y","N") -> Y | FN9: =IF(AD9=AE9,"Y","N") -> Y | FO9: =IF(AG9=AH9,"Y","N") -> Y | FP9: =IF(AI9=AJ9,"Y","N") -> Y | FQ9: =IF(AM9=AN9,"Y","N") -> Y | FR9: =IF(AO9=AP9,"Y","N") -> Y | FS9: =IF(AQ9=AR9,"Y","N") -> Y | FT9: =IF(AY9=AZ9,"Y","N") -> Y | FU9: =IF(BA9=BB9,"Y","N") -> Y | FV9: =IF(BG9=BH9,"Y","N") -> Y | FW9: =IF(BI9=BJ9,"Y","N") -> Y | FX9: =IF(BK9=BL9,"Y","N") -> Y | FY9: =IF(BM9=BN9,"Y","N") -> Y | FZ9: =IF(BO9=BP9,"Y","N") -> Y | GA9: =IF(BQ9=BR9,"Y","N") -> Y | GB9: =IF(BS9=BT9,"Y","N") -> Y | GC9: =IF(BU9=BV9,"Y","N") -> Y | GD9: =IF(BW9=BX9,"Y","N") -> Y | GE9: =IF(BY9=BZ9,"Y","N") -> Y | GF9: =IF(CA9=CB9,"Y","N") -> Y | GG9: =IF(CC9=CD9,"Y","N") -> Y | GH9: =IF(CE9=CF9,"Y","N") -> Y | GI9: =IF(CG9=CH9,"Y","N") -> Y | GJ9: =IF(CI9=CJ9,"Y","N") -> Y | GK9: =IF(CK9=CL9, "Y", "N") -> Y | GL9: =IF(CM9=CN9, "Y", "N") -> Y | GM9: =IF(CO9=CP9,"Y","N") -> Y | GN9: =IF(CQ9=CR9,"Y","N") -> Y | GO9: =IF(CS9=CT9,"Y","N") -> Y | GP9: =IF(CU9=CV9,"Y","N") -> Y | GQ9: =IF(CW9=CX9,"Y","N") -> Y | GR9: =IF(CY9=CZ9,"Y","N") -> Y | GS9: =IF(DA9=DB9,"Y","N") -> Y | GT9: =IF(DC9=DD9,"Y","N") -> Y | GU9: =IF(DE9=DF9,"Y","N") -> Y | GV9: =IF(DG9=DH9,"Y","N") -> Y | GW9: =IF(DI9=DJ9,"Y","N") -> Y | GX9: =IF(DK9=DL9,"Y","N") -> Y | GY9: =IF(DM9=DN9,"Y","N") -> Y | GZ9: =IF(DO9=DP9,"Y","N") -> Y | HA9: =IF(DQ9=DR9,"Y","N") -> Y | HB9: =IF(DS9=DT9,"Y","N") -> Y | HC9: =IF(DU9=DV9,"Y","N") -> Y | HD9: =IF(EC9=ED9,"Y","N") -> Y | HE9: =IF(EE9=EF9,"Y","N") -> Y | HF9: =IF(EG9=EH9,"Y","N") -> Y | HG9: =IF(EI9=EJ9,"Y","N") -> Y | HH9: =IF(EK9=EL9,"Y","N") -> Y | HI9: =IF(EM9=EN9,"Y","N") -> Y | HJ9: =IF(EO9=EP9,"Y","N") -> Y | HK9: =IF(EQ9=ER9,"Y","N") -> Y | HL9: =IF(ES9=ET9,"Y","N") -> Y | HM9: =IF(EU9=EV9,"Y","N") -> Y | HN9: =IF(EW9=EX9,"Y","N") -> Y
A10: Fraser | B10: 2020 | C10: 47 | D10: 47 | E10: 14 | F10: 14 | G10: 21.3 | H10: 21.3 | I10: 20.1 | J10: 20.1 | K10: 20.6 | L10: 20.6 | M10: NS | N10: NS | O10: NS | P10: NS | Q10: NS | R10: NS | S10: NS | T10: NS | U10: 0 | V10: 0 | W10: 61 | X10: 61 | Y10: 0 | Z10: 0 | AA10: 0 | AB10: 0 | AC10: inpat_psych | AD10: Australia | AE10: Australia | AF10: aus | AG10: no | AH10: no | AI10: yes | AJ10: yes | AK10: yes | AL10: yes | AM10: 61 | AN10: 61 | AO10: 0 | AP10: 0 | AQ10: 0 | AR10: 0 | AS10: 2.9 | AT10: NS | AU10: 3.4 | AV10: NS | AW10: 2.4 | AX10: 2.4 | AY10: 61 | AZ10: 61 | BA10: 34 | BB10: 34 | BC10: =BD10+BE10 -> 34 | BD10: 34 | BE10: 0 | BF10: 0 | BG10: single | BH10: single | BI10: NA | BJ10: NA | BK10: 34 | BL10: 34 | BM10: NA | BN10: NA | BO10: NA | BP10: NA | BQ10: 34 | BR10: 34 | BS10: NA | BT10: NA | BU10: NA | BV10: NA | BW10: NA | BX10: NA | BY10: NA | BZ10: NA | CA10: NA | CB10: NA | CC10: NA | CD10: NA | CE10: NA | CF10: NA | CG10: NA | CH10: NA | CI10: NA | CJ10: NA | CK10: NA | CL10: NA | CM10: NA | CN10: NA | CO10: NA | CP10: NA | CQ10: NA | CR10: NA | CS10: NA | CT10: NA | CU10: NS | CV10: NS | CW10: NS | CX10: NS | CY10: NS | CZ10: NS | DA10: NS | DB10: NS | DC10: NS | DD10: NS | DE10: NS | DF10: NS | DG10: yes - NS | DH10: yes - NS | DI10: all | DJ10: all | DK10: yes | DL10: yes | DM10: NS | DN10: NS | DO10: NS | DP10: NS | DQ10: NS | DR10: NS | DS10: NS | DT10: NS | DU10: NS | DV10: NS | DW10: Psychotic Disorder | DX10: Psychotic Disorder | DY10: PRISM | DZ10: PRISM | EA10: DSM-IV | EB10: DSM-IV | EC10: 1 | ED10: 1 | EE10: 0 | EF10: 0 | EG10: 1 | EH10: 1 | EI10: 1 | EJ10: 1 | EK10: 1 | EL10: 1 | EM10: 1 | EN10: 1 | EO10: 1 | EP10: 1 | EQ10: 1 | ER10: 1 | ES10: 1 | ET10: 1 | EU10: 1 | EV10: 1 | EW10: =SUM(EC10,EE10,EG10,EI10,EK10,EM10,EO10,EQ10,ES10,EU10) -> 9 | EX10: =SUM(ED10,EF10,EH10,EJ10,EL10,EN10,EP10,ER10,ET10,EV10) -> 9 | EY10: =A10 -> Fraser | EZ10: =B10 -> 2020 | FA10: =IF(C10=D10,"Y","N") -> Y | FB10: =IF(E10=F10,"Y","N") -> Y | FC10: =IF(G10=H10,"Y","N") -> Y | FD10: =IF(I10=J10,"Y","N") -> Y | FE10: =IF(K10=L10,"Y","N") -> Y | FG10: =IF(O10=P10,"Y","N") -> Y | FH10: =IF(Q10=R10,"Y","N") -> Y | FI10: =IF(S10=T10,"Y","N") -> Y | FJ10: =IF(U10=V10,"Y","N") -> Y | FK10: =IF(W10=X10,"Y","N") -> Y | FL10: =IF(Y10=Z10,"Y","N") -> Y | FM10: =IF(AA10=AB10,"Y","N") -> Y | FN10: =IF(AD10=AE10,"Y","N") -> Y | FO10: =IF(AG10=AH10,"Y","N") -> Y | FP10: =IF(AI10=AJ10,"Y","N") -> Y | FQ10: =IF(AM10=AN10,"Y","N") -> Y | FR10: =IF(AO10=AP10,"Y","N") -> Y | FS10: =IF(AQ10=AR10,"Y","N") -> Y | FT10: =IF(AY10=AZ10,"Y","N") -> Y | FU10: =IF(BA10=BB10,"Y","N") -> Y | FV10: =IF(BG10=BH10,"Y","N") -> Y | FW10: =IF(BI10=BJ10,"Y","N") -> Y | FX10: =IF(BK10=BL10,"Y","N") -> Y | FY10: =IF(BM10=BN10,"Y","N") -> Y | FZ10: =IF(BO10=BP10,"Y","N") -> Y | GA10: =IF(BQ10=BR10,"Y","N") -> Y | GB10: =IF(BS10=BT10,"Y","N") -> Y | GC10: =IF(BU10=BV10,"Y","N") -> Y | GD10: =IF(BW10=BX10,"Y","N") -> Y | GE10: =IF(BY10=BZ10,"Y","N") -> Y | GF10: =IF(CA10=CB10,"Y","N") -> Y | GG10: =IF(CC10=CD10,"Y","N") -> Y | GH10: =IF(CE10=CF10,"Y","N") -> Y | GI10: =IF(CG10=CH10,"Y","N") -> Y | GJ10: =IF(CI10=CJ10,"Y","N") -> Y | GK10: =IF(CK10=CL10, "Y", "N") -> Y | GL10: =IF(CM10=CN10, "Y", "N") -> Y | GM10: =IF(CO10=CP10,"Y","N") -> Y | GN10: =IF(CQ10=CR10,"Y","N") -> Y | GO10: =IF(CS10=CT10,"Y","N") -> Y | GP10: =IF(CU10=CV10,"Y","N") -> Y | GQ10: =IF(CW10=CX10,"Y","N") -> Y | GR10: =IF(CY10=CZ10,"Y","N") -> Y | GS10: =IF(DA10=DB10,"Y","N") -> Y | GT10: =IF(DC10=DD10,"Y","N") -> Y | GU10: =IF(DE10=DF10,"Y","N") -> Y | GV10: =IF(DG10=DH10,"Y","N") -> Y | GW10: =IF(DI10=DJ10,"Y","N") -> Y | GX10: =IF(DK10=DL10,"Y","N") -> Y | GY10: =IF(DM10=DN10,"Y","N") -> Y | GZ10: =IF(DO10=DP10,"Y","N") -> Y | HA10: =IF(DQ10=DR10,"Y","N") -> Y | HB10: =IF(DS10=DT10,"Y","N") -> Y | HC10: =IF(DU10=DV10,"Y","N") -> Y | HD10: =IF(EC10=ED10,"Y","N") -> Y | HE10: =IF(EE10=EF10,"Y","N") -> Y | HF10: =IF(EG10=EH10,"Y","N") -> Y | HG10: =IF(EI10=EJ10,"Y","N") -> Y | HH10: =IF(EK10=EL10,"Y","N") -> Y | HI10: =IF(EM10=EN10,"Y","N") -> Y | HJ10: =IF(EO10=EP10,"Y","N") -> Y | HK10: =IF(EQ10=ER10,"Y","N") -> Y | HL10: =IF(ES10=ET10,"Y","N") -> Y | HM10: =IF(EU10=EV10,"Y","N") -> Y | HN10: =IF(EW10=EX10,"Y","N") -> Y
A11: Funayama | B11: 2022 | C11: 68 | D11: 68 | E11: 119 | F11: 119 | G11: 36.7 | H11: 36.7 | I11: 32.3 | J11: 32.3 | K11: NS | L11: NS | M11: NS | N11: NS | O11: NS | P11: NS | Q11: NS | R11: NS | S11: NS | T11: NS | U11: 0 | V11: 0 | W11: 187 | X11: 187 | Y11: 0 | Z11: 0 | AA11: 0 | AB11: 0 | AC11: inpat_psych | AD11: Japan | AE11: Japan | AF11: asia | AG11: yes | AH11: yes | AI11: no | AJ11: no | AK11: yes | AL11: yes | AM11: 187 | AN11: 187 | AO11: 0 | AP11: 0 | AQ11: 0 | AR11: 0 | AS11: NS | AT11: NS | AU11: NS | AV11: NS | AW11: NS | AX11: NS | AY11: 187 | AZ11: 187 | BA11: 10 | BB11: 10 | BC11: =BD11+BE11 -> 4 | BD11: 4 | BE11: 0 | BF11: 6 | BG11: single | BH11: single | BI11: 4 | BJ11: 4 | BK11: NA | BL11: NA | BM11: 4 | BN11: 4 | BO11: NA | BP11: NA | BQ11: NA | BR11: NA | BS11: NA | BT11: NA | BU11: NA | BV11: NA | BW11: NA | BX11: NA | BY11: NA | BZ11: NA | CA11: NA | CB11: NA | CC11: NA | CD11: NA | CE11: NA | CF11: NA | CG11: NA | CH11: NA | CI11: NA | CJ11: NA | CK11: NA | CL11: NA | CM11: NA | CN11: NA | CO11: NA | CP11: NA | CQ11: NA | CR11: NA | CS11: NA | CT11: NA | CU11: yes - NS | CV11: yes - NS | CW11: NS | CX11: NS | CY11: NS | CZ11: NS | DA11: yes - NS | DB11: yes - NS | DC11: yes - NS | DD11: yes - NS | DE11: all | DF11: all | DG11: NS | DH11: NS | DI11: all | DJ11: all | DK11: NS | DL11: NS | DM11: all | DN11: all | DO11: all | DP11: all | DQ11: no | DR11: no | DS11: NS | DT11: NS | DU11: NS | DV11: NS | DW11: Psychotic Symptoms | DX11: Psychotic symptoms | DY11: NS | DZ11: NS | EA11: ICD-10 | EB11: ICD-10 | EC11: 1 | ED11: 1 | EE11: 1 | EF11: 1 | EG11: 1 | EH11: 1 | EI11: 1 | EJ11: 1 | EK11: 1 | EL11: 1 | EM11: 1 | EN11: 1 | EO11: 1 | EP11: 1 | EQ11: 1 | ER11: 1 | ES11: 1 | ET11: 1 | EU11: 1 | EV11: 1 | EW11: =SUM(EC11,EE11,EG11,EI11,EK11,EM11,EO11,EQ11,ES11,EU11) -> 10 | EX11: =SUM(ED11,EF11,EH11,EJ11,EL11,EN11,EP11,ER11,ET11,EV11) -> 10 | EY11: =A11 -> Funayama | EZ11: =B11 -> 2022 | FA11: =IF(C11=D11,"Y","N") -> Y | FB11: =IF(E11=F11,"Y","N") -> Y | FC11: =IF(G11=H11,"Y","N") -> Y | FD11: =IF(I11=J11,"Y","N") -> Y | FE11: =IF(K11=L11,"Y","N") -> Y | FF11: =IF(M11=N11,"Y","N") -> Y | FG11: =IF(O11=P11,"Y","N") -> Y | FH11: =IF(Q11=R11,"Y","N") -> Y | FI11: =IF(S11=T11,"Y","N") -> Y | FJ11: =IF(U11=V11,"Y","N") -> Y | FK11: =IF(W11=X11,"Y","N") -> Y | FL11: =IF(Y11=Z11,"Y","N") -> Y | FM11: =IF(AA11=AB11,"Y","N") -> Y | FN11: =IF(AD11=AE11,"Y","N") -> Y | FO11: =IF(AG11=AH11,"Y","N") -> Y | FP11: =IF(AI11=AJ11,"Y","N") -> Y | FQ11: =IF(AM11=AN11,"Y","N") -> Y | FR11: =IF(AO11=AP11,"Y","N") -> Y | FS11: =IF(AQ11=AR11,"Y","N") -> Y | FT11: =IF(AY11=AZ11,"Y","N") -> Y | FU11: =IF(BA11=BB11,"Y","N") -> Y | FV11: =IF(BG11=BH11,"Y","N") -> Y | FW11: =IF(BI11=BJ11,"Y","N") -> Y | FX11: =IF(BK11=BL11,"Y","N") -> Y | FY11: =IF(BM11=BN11,"Y","N") -> Y | FZ11: =IF(BO11=BP11,"Y","N") -> Y | GA11: =IF(BQ11=BR11,"Y","N") -> Y | GB11: =IF(BS11=BT11,"Y","N") -> Y | GC11: =IF(BU11=BV11,"Y","N") -> Y | GD11: =IF(BW11=BX11,"Y","N") -> Y | GE11: =IF(BY11=BZ11,"Y","N") -> Y | GF11: =IF(CA11=CB11,"Y","N") -> Y | GG11: =IF(CC11=CD11,"Y","N") -> Y | GH11: =IF(CE11=CF11,"Y","N") -> Y | GI11: =IF(CG11=CH11,"Y","N") -> Y | GJ11: =IF(CI11=CJ11,"Y","N") -> Y | GK11: =IF(CK11=CL11, "Y", "N") -> Y | GL11: =IF(CM11=CN11, "Y", "N") -> Y | GM11: =IF(CO11=CP11,"Y","N") -> Y | GN11: =IF(CQ11=CR11,"Y","N") -> Y | GO11: =IF(CS11=CT11,"Y","N") -> Y | GP11: =IF(CU11=CV11,"Y","N") -> Y | GQ11: =IF(CW11=CX11,"Y","N") -> Y | GR11: =IF(CY11=CZ11,"Y","N") -> Y | GS11: =IF(DA11=DB11,"Y","N") -> Y | GT11: =IF(DC11=DD11,"Y","N") -> Y | GU11: =IF(DE11=DF11,"Y","N") -> Y | GV11: =IF(DG11=DH11,"Y","N") -> Y | GW11: =IF(DI11=DJ11,"Y","N") -> Y | GX11: =IF(DK11=DL11,"Y","N") -> Y | GY11: =IF(DM11=DN11,"Y","N") -> Y | GZ11: =IF(DO11=DP11,"Y","N") -> Y | HA11: =IF(DQ11=DR11,"Y","N") -> Y | HB11: =IF(DS11=DT11,"Y","N") -> Y | HC11: =IF(DU11=DV11,"Y","N") -> Y | HD11: =IF(EC11=ED11,"Y","N") -> Y | HE11: =IF(EE11=EF11,"Y","N") -> Y | HF11: =IF(EG11=EH11,"Y","N") -> Y | HG11: =IF(EI11=EJ11,"Y","N") -> Y | HH11: =IF(EK11=EL11,"Y","N") -> Y | HI11: =IF(EM11=EN11,"Y","N") -> Y | HJ11: =IF(EO11=EP11,"Y","N") -> Y | HK11: =IF(EQ11=ER11,"Y","N") -> Y | HL11: =IF(ES11=ET11,"Y","N") -> Y | HM11: =IF(EU11=EV11,"Y","N") -> Y | HN11: =IF(EW11=EX11,"Y","N") -> Y
A12: Giannitelli | B12: 2018 | C12: NS | D12: NS | E12: NS | F12: NS | G12: NS | H12: NS | I12: NS | J12: NS | K12: NS | L12: NS | M12: NS | N12: NS | O12: NS | P12: NS | Q12: NS | R12: NS | S12: NS | T12: NS | U12: 160 | V12: 160 | W12: NS | X12: NS | Y12: NS | Z12: NS | AA12: NS | AB12: NS | AC12: gen_hospital | AD12: France | AE12: France | AF12: euro | AG12: yes | AH12: yes | AI12: no | AJ12: no | AK12: NS | AL12: NS | AM12: NS | AN12: NS | AO12: NS | AP12: NS | AQ12: NS | AR12: NS | AS12: NS | AT12: NS | AU12: NS | AV12: NS | AW12: NS | AX12: NS | AY12: 160 | AZ12: 160 | BA12: 20 | BB12: 20 | BC12: =BD12+BE12 -> 20 | BD12: 16 | BE12: 4 | BF12: 0 | BG12: multiple | BH12: multiple | BI12: 20 | BJ12: 20 | BK12: NA | BL12: NA | BM12: 3 | BN12: 3 | BO12: 15 | BP12: 15 | BQ12: 0 | BR12: 0 | BS12: 0 | BT12: 0 | BU12: 0 | BV12: 0 | BW12: 2 | BX12: 2 | BY12: 0 | BZ12: 0 | CA12: 0 | CB12: 0 | CC12: 0 | CD12: 0 | CE12: 0 | CF12: 0 | CG12: 0 | CH12: 0 | CI12: 0 | CJ12: 0 | CK12: 0 | CL12: 0 | CM12: 0 | CN12: 0 | CO12: 0 | CP12: 0 | CQ12: 0 | CR12: 0 | CS12: 0 | CT12: 0 | CU12: NS | CV12: NS | CW12: NS | CX12: NS | CY12: NS | CZ12: NS | DA12: yes - NS | DB12: yes - NS | DC12: NS | DD12: NS | DE12: yes - NS | DF12: yes - NS | DG12: NS | DH12: NS | DI12: NS | DJ12: NS | DK12: NS | DL12: NS | DM12: NS | DN12: NS | DO12: NS | DP12: NS | DQ12: NS | DR12: NS | DS12: NS | DT12: NS | DU12: NS | DV12: NS | DW12: Psychotic Disorder | DX12: Psychotic Disorder | DY12: NS | DZ12: NS | EA12: NS | EB12: NS | EC12: 1 | ED12: 1 | EE12: 1 | EF12: 1 | EG12: 1 | EH12: 1 | EI12: 1 | EJ12: 1 | EK12: 1 | EL12: 1 | EM12: 1 | EN12: 1 | EO12: 1 | EP12: 1 | EQ12: 1 | ER12: 1 | ES12: 1 | ET12: 1 | EU12: 1 | EV12: 1 | EW12: =SUM(EC12,EE12,EG12,EI12,EK12,EM12,EO12,EQ12,ES12,EU12) -> 10 | EX12: =SUM(ED12,EF12,EH12,EJ12,EL12,EN12,EP12,ER12,ET12,EV12) -> 10 | EY12: =A12 -> Giannitelli | EZ12: =B12 -> 2018 | FA12: =IF(C12=D12,"Y","N") -> Y | FB12: =IF(E12=F12,"Y","N") -> Y | FC12: =IF(G12=H12,"Y","N") -> Y | FD12: =IF(I12=J12,"Y","N") -> Y | FE12: =IF(K12=L12,"Y","N") -> Y | FF12: =IF(M12=N12,"Y","N") -> Y | FG12: =IF(O12=P12,"Y","N") -> Y | FH12: =IF(Q12=R12,"Y","N") -> Y | FI12: =IF(S12=T12,"Y","N") -> Y | FJ12: =IF(U12=V12,"Y","N") -> Y | FK12: =IF(W12=X12,"Y","N") -> Y | FL12: =IF(Y12=Z12,"Y","N") -> Y | FM12: =IF(AA12=AB12,"Y","N") -> Y | FN12: =IF(AD12=AE12,"Y","N") -> Y | FO12: =IF(AG12=AH12,"Y","N") -> Y | FP12: =IF(AI12=AJ12,"Y","N") -> Y | FQ12: =IF(AM12=AN12,"Y","N") -> Y | FR12: =IF(AO12=AP12,"Y","N") -> Y | FS12: =IF(AQ12=AR12,"Y","N") -> Y | FT12: =IF(AY12=AZ12,"Y","N") -> Y | FU12: =IF(BA12=BB12,"Y","N") -> Y | FV12: =IF(BG12=BH12,"Y","N") -> Y | FW12: =IF(BI12=BJ12,"Y","N") -> Y | FX12: =IF(BK12=BL12,"Y","N") -> Y | FY12: =IF(BM12=BN12,"Y","N") -> Y | FZ12: =IF(BO12=BP12,"Y","N") -> Y | GA12: =IF(BQ12=BR12,"Y","N") -> Y | GB12: =IF(BS12=BT12,"Y","N") -> Y | GC12: =IF(BU12=BV12,"Y","N") -> Y | GD12: =IF(BW12=BX12,"Y","N") -> Y | GE12: =IF(BY12=BZ12,"Y","N") -> Y | GF12: =IF(CA12=CB12,"Y","N") -> Y | GG12: =IF(CC12=CD12,"Y","N") -> Y | GH12: =IF(CE12=CF12,"Y","N") -> Y | GI12: =IF(CG12=CH12,"Y","N") -> Y | GJ12: =IF(CI12=CJ12,"Y","N") -> Y | GK12: =IF(CK12=CL12, "Y", "N") -> Y | GL12: =IF(CM12=CN12, "Y", "N") -> Y | GM12: =IF(CO12=CP12,"Y","N") -> Y | GN12: =IF(CQ12=CR12,"Y","N") -> Y | GO12: =IF(CS12=CT12,"Y","N") -> Y | GP12: =IF(CU12=CV12,"Y","N") -> Y | GQ12: =IF(CW12=CX12,"Y","N") -> Y | GR12: =IF(CY12=CZ12,"Y","N") -> Y | GS12: =IF(DA12=DB12,"Y","N") -> Y | GT12: =IF(DC12=DD12,"Y","N") -> Y | GU12: =IF(DE12=DF12,"Y","N") -> Y | GV12: =IF(DG12=DH12,"Y","N") -> Y | GW12: =IF(DI12=DJ12,"Y","N") -> Y | GX12: =IF(DK12=DL12,"Y","N") -> Y | GY12: =IF(DM12=DN12,"Y","N") -> Y | GZ12: =IF(DO12=DP12,"Y","N") -> Y | HA12: =IF(DQ12=DR12,"Y","N") -> Y | HB12: =IF(DS12=DT12,"Y","N") -> Y | HC12: =IF(DU12=DV12,"Y","N") -> Y | HD12: =IF(EC12=ED12,"Y","N") -> Y | HE12: =IF(EE12=EF12,"Y","N") -> Y | HF12: =IF(EG12=EH12,"Y","N") -> Y | HG12: =IF(EI12=EJ12,"Y","N") -> Y | HH12: =IF(EK12=EL12,"Y","N") -> Y | HI12: =IF(EM12=EN12,"Y","N") -> Y | HJ12: =IF(EO12=EP12,"Y","N") -> Y | HK12: =IF(EQ12=ER12,"Y","N") -> Y | HL12: =IF(ES12=ET12,"Y","N") -> Y | HM12: =IF(EU12=EV12,"Y","N") -> Y | HN12: =IF(EW12=EX12,"Y","N") -> Y
A13: Guasp | B13: 2021 | C13: 61 | D13: 61 | E13: 44 | F13: 44 | G13: NS | H13: NS | I13: NS | J13: NS | K13: NS | L13: NS | M13: NS | N13: NS | O13: NS | P13: NS | Q13: NS | R13: NS | S13: NS | T13: NS | U13: 0 | V13: 0 | W13: 105 | X13: 105 | Y13: 0 | Z13: 0 | AA13: 0 | AB13: 0 | AC13: inpat_psych | AD13: Spain | AE13: Spain | AF13: euro | AG13: no | AH13: no | AI13: yes | AJ13: yes | AK13: yes | AL13: yes | AM13: 105 | AN13: 105 | AO13: 0 | AP13: 0 | AQ13: 0 | AR13: 0 | AS13: 79 | AT13: 79 | AU13: NS | AV13: NS | AW13: NS | AX13: NS | AY13: 105 | AZ13: 105 | BA13: 4 | BB13: 4 | BC13: =BD13+BE13 -> 4 | BD13: 4 | BE13: 0 | BF13: 0 | BG13: multiple | BH13: multiple | BI13: 4 | BJ13: 4 | BK13: 0 | BL13: 0 | BM13: 0 | BN13: 0 | BO13: 0 | BP13: 0 | BQ13: 0 | BR13: 0 | BS13: 0 | BT13: 0 | BU13: 0 | BV13: 0 | BW13: 0 | BX13: 0 | BY13: 1 | BZ13: 1 | CA13: 0 | CB13: 0 | CC13: 1 | CD13: 1 | CE13: 1 | CF13: 1 | CG13: 0 | CH13: 0 | CI13: 0 | CJ13: 0 | CK13: 0 | CL13: 0 | CM13: 0 | CN13: 0 | CO13: 1 | CP13: 1 | CQ13: 0 | CR13: 0 | CS13: 0 | CT13: 0 | CU13: all | CV13: all | CW13: NS | CX13: NS | CY13: NS | CZ13: NS | DA13: some | DB13: some | DC13: all | DD13: all | DE13: all | DF13: all | DG13: all | DH13: all | DI13: all | DJ13: all | DK13: NS | DL13: NS | DM13: all | DN13: all | DO13: NS | DP13: NS | DQ13: NS | DR13: NS | DS13: NS | DT13: NS | DU13: NS | DV13: NS | DW13: Psychotic Disorder | DX13: Psychotics disorder | DY13: SCID | DZ13: SCID and PANSS | EA13: DSM-IV | EB13: DSM-IV | EC13: 1 | ED13: 1 | EE13: 1 | EF13: 1 | EG13: 1 | EH13: 1 | EI13: 1 | EJ13: 1 | EK13: 1 | EL13: 1 | EM13: 1 | EN13: 1 | EO13: 1 | EP13: 1 | EQ13: 1 | ER13: 1 | ES13: 1 | ET13: 1 | EU13: 1 | EV13: 1 | EW13: =SUM(EC13,EE13,EG13,EI13,EK13,EM13,EO13,EQ13,ES13,EU13) -> 10 | EX13: =SUM(ED13,EF13,EH13,EJ13,EL13,EN13,EP13,ER13,ET13,EV13) -> 10 | EY13: =A13 -> Guasp | EZ13: =B13 -> 2021 | FA13: =IF(C13=D13,"Y","N") -> Y | FB13: =IF(E13=F13,"Y","N") -> Y | FC13: =IF(G13=H13,"Y","N") -> Y | FD13: =IF(I13=J13,"Y","N") -> Y | FE13: =IF(K13=L13,"Y","N") -> Y | FF13: =IF(M13=N13,"Y","N") -> Y | FG13: =IF(O13=P13,"Y","N") -> Y | FH13: =IF(Q13=R13,"Y","N") -> Y | FI13: =IF(S13=T13,"Y","N") -> Y | FJ13: =IF(U13=V13,"Y","N") -> Y | FK13: =IF(W13=X13,"Y","N") -> Y | FL13: =IF(Y13=Z13,"Y","N") -> Y | FM13: =IF(AA13=AB13,"Y","N") -> Y | FN13: =IF(AD13=AE13,"Y","N") -> Y | FO13: =IF(AG13=AH13,"Y","N") -> Y | FP13: =IF(AI13=AJ13,"Y","N") -> Y | FQ13: =IF(AM13=AN13,"Y","N") -> Y | FR13: =IF(AO13=AP13,"Y","N") -> Y | FS13: =IF(AQ13=AR13,"Y","N") -> Y | FT13: =IF(AY13=AZ13,"Y","N") -> Y | FU13: =IF(BA13=BB13,"Y","N") -> Y | FV13: =IF(BG13=BH13,"Y","N") -> Y | FW13: =IF(BI13=BJ13,"Y","N") -> Y | FX13: =IF(BK13=BL13,"Y","N") -> Y | FY13: =IF(BM13=BN13,"Y","N") -> Y | FZ13: =IF(BO13=BP13,"Y","N") -> Y | GA13: =IF(BQ13=BR13,"Y","N") -> Y | GB13: =IF(BS13=BT13,"Y","N") -> Y | GC13: =IF(BU13=BV13,"Y","N") -> Y | GD13: =IF(BW13=BX13,"Y","N") -> Y | GE13: =IF(BY13=BZ13,"Y","N") -> Y | GF13: =IF(CA13=CB13,"Y","N") -> Y | GG13: =IF(CC13=CD13,"Y","N") -> Y | GH13: =IF(CE13=CF13,"Y","N") -> Y | GI13: =IF(CG13=CH13,"Y","N") -> Y | GJ13: =IF(CI13=CJ13,"Y","N") -> Y | GK13: =IF(CK13=CL13, "Y", "N") -> Y | GL13: =IF(CM13=CN13, "Y", "N") -> Y | GM13: =IF(CO13=CP13,"Y","N") -> Y | GN13: =IF(CQ13=CR13,"Y","N") -> Y | GO13: =IF(CS13=CT13,"Y","N") -> Y | GP13: =IF(CU13=CV13,"Y","N") -> Y | GQ13: =IF(CW13=CX13,"Y","N") -> Y | GR13: =IF(CY13=CZ13,"Y","N") -> Y | GS13: =IF(DA13=DB13,"Y","N") -> Y | GT13: =IF(DC13=DD13,"Y","N") -> Y | GU13: =IF(DE13=DF13,"Y","N") -> Y | GV13: =IF(DG13=DH13,"Y","N") -> Y | GW13: =IF(DI13=DJ13,"Y","N") -> Y | GX13: =IF(DK13=DL13,"Y","N") -> Y | GY13: =IF(DM13=DN13,"Y","N") -> Y | GZ13: =IF(DO13=DP13,"Y","N") -> Y | HA13: =IF(DQ13=DR13,"Y","N") -> Y | HB13: =IF(DS13=DT13,"Y","N") -> Y | HC13: =IF(DU13=DV13,"Y","N") -> Y | HD13: =IF(EC13=ED13,"Y","N") -> Y | HE13: =IF(EE13=EF13,"Y","N") -> Y | HF13: =IF(EG13=EH13,"Y","N") -> Y | HG13: =IF(EI13=EJ13,"Y","N") -> Y | HH13: =IF(EK13=EL13,"Y","N") -> Y | HI13: =IF(EM13=EN13,"Y","N") -> Y | HJ13: =IF(EO13=EP13,"Y","N") -> Y | HK13: =IF(EQ13=ER13,"Y","N") -> Y | HL13: =IF(ES13=ET13,"Y","N") -> Y | HM13: =IF(EU13=EV13,"Y","N") -> Y | HN13: =IF(EW13=EX13,"Y","N") -> Y
A14: Harris | B14: 2019 | C14: 480 | D14: 480 | E14: 325 | F14: 325 | G14: NS | H14: NS | I14: NS | J14: NS | K14: 32 | L14: 32 | M14: NS | N14: NS | O14: NS | P14: NS | Q14: NS | R14: NS | S14: NS | T14: NS | U14: NS | V14: NS | W14: NS | X14: NS | Y14: 0 | Z14: 0 | AA14: 0 | AB14: 0 | AC14: NS | AD14: Australia | AE14: Australia | AF14: aus | AG14: yes | AH14: yes | AI14: no | AJ14: no | AK14: no | AL14: no | AM14: NS | AN14: NS | AO14: NS | AP14: NS | AQ14: NS | AR14: NS | AS14: NS | AT14: NS | AU14: NS | AV14: NS | AW14: NS | AX14: NS | AY14: 805 | AZ14: 805 | BA14: 3 | BB14: 3 | BC14: =BD14+BE14 -> 1 | BD14: 1 | BE14: 0 | BF14: 2 | BG14: NS | BH14: NS | BI14: 1 | BJ14: 1 | BK14: NA | BL14: NA | BM14: NA | BN14: NA | BO14: NA | BP14: NA | BQ14: NA | BR14: NA | BS14: NA | BT14: NA | BU14: NA | BV14: NA | BW14: NA | BX14: NA | BY14: NA | BZ14: NA | CA14: NA | CB14: NA | CC14: NA | CD14: NA | CE14: NA | CF14: NA | CG14: NA | CH14: NA | CI14: NA | CJ14: NA | CK14: NA | CL14: NA | CM14: NA | CN14: NA | CO14: NA | CP14: NA | CQ14: NA | CR14: NA | CS14: 1 | CT14: 1 | CU14: some | CV14: some | CW14: all | CX14: all | CY14: some | CZ14: some | DA14: some | DB14: some | DC14: some | DD14: some | DE14: some | DF14: some | DG14: NS | DH14: NS | DI14: NS | DJ14: NS | DK14: NS | DL14: NS | DM14: some | DN14: some | DO14: NS | DP14: NS | DQ14: NS | DR14: NS | DS14: NS | DT14: NS | DU14: NS | DV14: NS | DW14: NS | DX14: NS | DY14: NS | DZ14: NS | EA14: NS | EB14: NS | EC14: 1 | ED14: 1 | EE14: 1 | EF14: 1 | EG14: 1 | EH14: 1 | EI14: 1 | EJ14: 1 | EK14: 1 | EL14: 1 | EM14: 1 | EN14: 1 | EO14: 1 | EP14: 1 | EQ14: 1 | ER14: 1 | ES14: 1 | ET14: 1 | EU14: 1 | EV14: 1 | EW14: =SUM(EC14,EE14,EG14,EI14,EK14,EM14,EO14,EQ14,ES14,EU14) -> 10 | EX14: =SUM(ED14,EF14,EH14,EJ14,EL14,EN14,EP14,ER14,ET14,EV14) -> 10 | EY14: =A14 -> Harris | EZ14: =B14 -> 2019 | FA14: =IF(C14=D14,"Y","N") -> Y | FB14: =IF(E14=F14,"Y","N") -> Y | FC14: =IF(G14=H14,"Y","N") -> Y | FD14: =IF(I14=J14,"Y","N") -> Y | FE14: =IF(K14=L14,"Y","N") -> Y | FF14: =IF(M14=N14,"Y","N") -> Y | FG14: =IF(O14=P14,"Y","N") -> Y | FH14: =IF(Q14=R14,"Y","N") -> Y | FI14: =IF(S14=T14,"Y","N") -> Y | FJ14: =IF(U14=V14,"Y","N") -> Y | FK14: =IF(W14=X14,"Y","N") -> Y | FL14: =IF(Y14=Z14,"Y","N") -> Y | FM14: =IF(AA14=AB14,"Y","N") -> Y | FN14: =IF(AD14=AE14,"Y","N") -> Y | FO14: =IF(AG14=AH14,"Y","N") -> Y | FP14: =IF(AI14=AJ14,"Y","N") -> Y | FQ14: =IF(AM14=AN14,"Y","N") -> Y | FR14: =IF(AO14=AP14,"Y","N") -> Y | FS14: =IF(AQ14=AR14,"Y","N") -> Y | FT14: =IF(AY14=AZ14,"Y","N") -> Y | FU14: =IF(BA14=BB14,"Y","N") -> Y | FV14: =IF(BG14=BH14,"Y","N") -> Y | FW14: =IF(BI14=BJ14,"Y","N") -> Y | FX14: =IF(BK14=BL14,"Y","N") -> Y | FY14: =IF(BM14=BN14,"Y","N") -> Y | FZ14: =IF(BO14=BP14,"Y","N") -> Y | GA14: =IF(BQ14=BR14,"Y","N") -> Y | GB14: =IF(BS14=BT14,"Y","N") -> Y | GC14: =IF(BU14=BV14,"Y","N") -> Y | GD14: =IF(BW14=BX14,"Y","N") -> Y | GE14: =IF(BY14=BZ14,"Y","N") -> Y | GF14: =IF(CA14=CB14,"Y","N") -> Y | GG14: =IF(CC14=CD14,"Y","N") -> Y | GH14: =IF(CE14=CF14,"Y","N") -> Y | GI14: =IF(CG14=CH14,"Y","N") -> Y | GJ14: =IF(CI14=CJ14,"Y","N") -> Y | GK14: =IF(CK14=CL14, "Y", "N") -> Y | GL14: =IF(CM14=CN14, "Y", "N") -> Y | GM14: =IF(CO14=CP14,"Y","N") -> Y | GN14: =IF(CQ14=CR14,"Y","N") -> Y | GO14: =IF(CS14=CT14,"Y","N") -> Y | GP14: =IF(CU14=CV14,"Y","N") -> Y | GQ14: =IF(CW14=CX14,"Y","N") -> Y | GR14: =IF(CY14=CZ14,"Y","N") -> Y | GS14: =IF(DA14=DB14,"Y","N") -> Y | GT14: =IF(DC14=DD14,"Y","N") -> Y | GU14: =IF(DE14=DF14,"Y","N") -> Y | GV14: =IF(DG14=DH14,"Y","N") -> Y | GW14: =IF(DI14=DJ14,"Y","N") -> Y | GX14: =IF(DK14=DL14,"Y","N") -> Y | GY14: =IF(DM14=DN14,"Y","N") -> Y | GZ14: =IF(DO14=DP14,"Y","N") -> Y | HA14: =IF(DQ14=DR14,"Y","N") -> Y | HB14: =IF(DS14=DT14,"Y","N") -> Y | HC14: =IF(DU14=DV14,"Y","N") -> Y | HD14: =IF(EC14=ED14,"Y","N") -> Y | HE14: =IF(EE14=EF14,"Y","N") -> Y | HF14: =IF(EG14=EH14,"Y","N") -> Y | HG14: =IF(EI14=EJ14,"Y","N") -> Y | HH14: =IF(EK14=EL14,"Y","N") -> Y | HI14: =IF(EM14=EN14,"Y","N") -> Y | HJ14: =IF(EO14=EP14,"Y","N") -> Y | HK14: =IF(EQ14=ER14,"Y","N") -> Y | HL14: =IF(ES14=ET14,"Y","N") -> Y | HM14: =IF(EU14=EV14,"Y","N") -> Y | HN14: =IF(EW14=EX14,"Y","N") -> Y
A15: Johnstone | B15: 1987 | C15: NS | D15: NS | E15: NS | F15: NS | G15: NS | H15: NS | I15: NS | J15: NS | K15: NS | L15: NS | M15: NS | N15: NS | O15: NS | P15: NS | Q15: NS | R15: NS | S15: NS | T15: NS | U15: 0 | V15: 0 | W15: 268 | X15: 268 | Y15: 0 | Z15: 0 | AA15: 0 | AB15: 0 | AC15: inpat_psych | AD15: UK | AE15: UK | AF15: euro | AG15: no | AH15: no | AI15: yes | AJ15: yes | AK15: yes | AL15: yes | AM15: 268 | AN15: 268 | AO15: 0 | AP15: 0 | AQ15: 0 | AR15: 0 | AS15: NS | AT15: NS | AU15: NS | AV15: NS | AW15: NS | AX15: NS | AY15: 268 | AZ15: 268 | BA15: 15 | BB15: 15 | BC15: =BD15+BE15 -> 15 | BD15: 15 | BE15: 0 | BF15: 0 | BG15: multiple | BH15: multiple | BI15: 10 | BJ15: 10 | BK15: =BQ15+BS15 -> 5 | BL15: =SUM(BR15,BT15) -> 5 | BM15: 3 | BN15: 3 | BO15: NA | BP15: NA | BQ15: 5 | BR15: 5 | BS15: 0 | BT15: 0 | BU15: 1 | BV15: 1 | BW15: NA | BX15: NA | BY15: 0 | BZ15: 0 | CA15: 0 | CB15: 0 | CC15: 4 | CD15: 4 | CE15: NA | CF15: NA | CG15: NA | CH15: NA | CI15: 0 | CJ15: 0 | CK15: 0 | CL15: 0 | CM15: 1 | CN15: 1 | CO15: 1 | CP15: 1 | CQ15: 0 | CR15: 0 | CS15: 0 | CT15: 0 | CU15: NS | CV15: NS | CW15: some | CX15: some | CY15: 0 | CZ15: 0 | DA15: some | DB15: some | DC15: some | DD15: some | DE15: some | DF15: some | DG15: 0 | DH15: 0 | DI15: all | DJ15: all | DK15: NS | DL15: NS | DM15: some | DN15: some | DO15: some | DP15: some | DQ15: NS | DR15: NS | DS15: X-ray (Unspecified freq) | DT15: X-ray (Unspecified freq) | DU15: NS | DV15: NS | DW15: Psychotic Disorder | DX15: Psychotic disorder | DY15: NS | DZ15: NS | EA15: NS | EB15: NS | EC15: 1 | ED15: 1 | EE15: 1 | EF15: 1 | EG15: 1 | EH15: 1 | EI15: 1 | EJ15: 1 | EK15: 1 | EL15: 1 | EM15: 1 | EN15: 1 | EO15: 1 | EP15: 1 | EQ15: 0 | ER15: 0 | ES15: 1 | ET15: 1 | EU15: 1 | EV15: 1 | EW15: =SUM(EC15,EE15,EG15,EI15,EK15,EM15,EO15,EQ15,ES15,EU15) -> 9 | EX15: =SUM(ED15,EF15,EH15,EJ15,EL15,EN15,EP15,ER15,ET15,EV15) -> 9 | EY15: =A15 -> Johnstone | EZ15: =B15 -> 1987 | FA15: =IF(C15=D15,"Y","N") -> Y | FB15: =IF(E15=F15,"Y","N") -> Y | FC15: =IF(G15=H15,"Y","N") -> Y | FD15: =IF(I15=J15,"Y","N") -> Y | FE15: =IF(K15=L15,"Y","N") -> Y | FF15: =IF(M15=N15,"Y","N") -> Y | FG15: =IF(O15=P15,"Y","N") -> Y | FH15: =IF(Q15=R15,"Y","N") -> Y | FI15: =IF(S15=T15,"Y","N") -> Y | FJ15: =IF(U15=V15,"Y","N") -> Y | FK15: =IF(W15=X15,"Y","N") -> Y | FL15: =IF(Y15=Z15,"Y","N") -> Y | FM15: =IF(AA15=AB15,"Y","N") -> Y | FN15: =IF(AD15=AE15,"Y","N") -> Y | FO15: =IF(AG15=AH15,"Y","N") -> Y | FP15: =IF(AI15=AJ15,"Y","N") -> Y | FQ15: =IF(AM15=AN15,"Y","N") -> Y | FR15: =IF(AO15=AP15,"Y","N") -> Y | FS15: =IF(AQ15=AR15,"Y","N") -> Y | FT15: =IF(AY15=AZ15,"Y","N") -> Y | FU15: =IF(BA15=BB15,"Y","N") -> Y | FV15: =IF(BG15=BH15,"Y","N") -> Y | FW15: =IF(BI15=BJ15,"Y","N") -> Y | FX15: =IF(BK15=BL15,"Y","N") -> Y | FY15: =IF(BM15=BN15,"Y","N") -> Y | FZ15: =IF(BO15=BP15,"Y","N") -> Y | GA15: =IF(BQ15=BR15,"Y","N") -> Y | GB15: =IF(BS15=BT15,"Y","N") -> Y | GC15: =IF(BU15=BV15,"Y","N") -> Y | GD15: =IF(BW15=BX15,"Y","N") -> Y | GE15: =IF(BY15=BZ15,"Y","N") -> Y | GF15: =IF(CA15=CB15,"Y","N") -> Y | GG15: =IF(CC15=CD15,"Y","N") -> Y | GH15: =IF(CE15=CF15,"Y","N") -> Y | GI15: =IF(CG15=CH15,"Y","N") -> Y | GJ15: =IF(CI15=CJ15,"Y","N") -> Y | GK15: =IF(CK15=CL15, "Y", "N") -> Y | GL15: =IF(CM15=CN15, "Y", "N") -> Y | GM15: =IF(CO15=CP15,"Y","N") -> Y | GN15: =IF(CQ15=CR15,"Y","N") -> Y | GO15: =IF(CS15=CT15,"Y","N") -> Y | GP15: =IF(CU15=CV15,"Y","N") -> Y | GQ15: =IF(CW15=CX15,"Y","N") -> Y | GR15: =IF(CY15=CZ15,"Y","N") -> Y | GS15: =IF(DA15=DB15,"Y","N") -> Y | GT15: =IF(DC15=DD15,"Y","N") -> Y | GU15: =IF(DE15=DF15,"Y","N") -> Y | GV15: =IF(DG15=DH15,"Y","N") -> Y | GW15: =IF(DI15=DJ15,"Y","N") -> Y | GX15: =IF(DK15=DL15,"Y","N") -> Y | GY15: =IF(DM15=DN15,"Y","N") -> Y | GZ15: =IF(DO15=DP15,"Y","N") -> Y | HA15: =IF(DQ15=DR15,"Y","N") -> Y | HB15: =IF(DS15=DT15,"Y","N") -> Y | HC15: =IF(DU15=DV15,"Y","N") -> Y | HD15: =IF(EC15=ED15,"Y","N") -> Y | HE15: =IF(EE15=EF15,"Y","N") -> Y | HF15: =IF(EG15=EH15,"Y","N") -> Y | HG15: =IF(EI15=EJ15,"Y","N") -> Y | HH15: =IF(EK15=EL15,"Y","N") -> Y | HI15: =IF(EM15=EN15,"Y","N") -> Y | HJ15: =IF(EO15=EP15,"Y","N") -> Y | HK15: =IF(EQ15=ER15,"Y","N") -> Y | HL15: =IF(ES15=ET15,"Y","N") -> Y | HM15: =IF(EU15=EV15,"Y","N") -> Y | HN15: =IF(EW15=EX15,"Y","N") -> Y
